<?xml version="1.0" ?>
<!-- =================================================================================== -->
<!-- |    This document was autogenerated by xacro from mecanum.urdf.xacro             | -->
<!-- |    EDITING THIS FILE BY HAND IS NOT RECOMMENDED                                 | -->
<!-- =================================================================================== -->
<robot name="linorobot2_mecanum">
  <link name="base_footprint"/>
  <link name="base_link">
    <visual>
      <origin rpy="0 0 0" xyz="0 0 0"/>
      <geometry>
        <box size="0.82067 0.3175 0.07772"/>
        <!-- <mesh filename="" scale="0.001 0.001 0.001"/> -->
      </geometry>
      <material name="gray_base">
        <color rgba="0.8 0.8 0.83 1.0"/>
      </material>
    </visual>
    <collision>
      <origin rpy="0 0 0" xyz="0 0 0"/>
      <geometry>
        <box size="0.82067 0.3175 0.07772"/>
      </geometry>
    </collision>
    <inertial>
      <origin rpy="0 0 0" xyz="0 0 0"/>
      <mass value="30"/>
    </inertial>
  </link>
  <gazebo reference="base_link">
    <visual>
      <material>
        <ambient>0.8392 0.6314 0.0 1.0</ambient>
        <diffuse>0.8392 0.6314 0.0 1.0</diffuse>
        <specular>0.99 0.99 0.99 1.0</specular>
        <emissive>0.0 0.0 0.0 0.0</emissive>
      </material>
    </visual>
  </gazebo>
  <joint name="base_to_footprint" type="fixed">
    <parent link="base_footprint"/>
    <child link="base_link"/>
    <origin rpy="0 0 0" xyz="0 0 0.06972"/>
  </joint>
  <link name="front_channel">
    <visual>
      <geometry>
        <box size="0.05398 0.4953 0.08458"/>
        <!-- Box dimensions (x, y, z) -->
      </geometry>
      <material name="gray">
        <color rgba="0.70 0.70 0.73 1.0"/>
        <!-- Blue color -->
      </material>
    </visual>
    <collision>
      <geometry>
        <box size="0.05398 0.4953 0.08458"/>
        <!-- Box dimensions (x, y, z) -->
      </geometry>
    </collision>
    <inertial>
      <mass value="5"/>
    </inertial>
  </link>
  <joint name="base_link_to_front_channel" type="fixed">
    <parent link="base_link"/>
    <child link="front_channel"/>
    <origin rpy="0 0 0" xyz="0.383345 0 0"/>
  </joint>
  <link name="back_channel">
    <visual>
      <geometry>
        <box size="0.05398 0.4953 0.08458"/>
        <!-- Box dimensions (x, y, z) -->
      </geometry>
      <material name="gray">
        <color rgba="0.70 0.70 0.73 1.0"/>
        <!-- Blue color -->
      </material>
    </visual>
    <collision>
      <geometry>
        <box size="0.05398 0.4953 0.08458"/>
        <!-- Box dimensions (x, y, z) -->
      </geometry>
    </collision>
    <inertial>
      <mass value="5"/>
    </inertial>
  </link>
  <joint name="base_link_to_back_channel" type="fixed">
    <parent link="base_link"/>
    <child link="back_channel"/>
    <origin rpy="0 0 0" xyz="-0.383345 0 0"/>
  </joint>
  <link name="left_channel">
    <visual>
      <geometry>
        <box size="0.82067 0.02224 0.07772"/>
      </geometry>
      <material name="gray">
        <color rgba="0.70 0.70 0.73 1.0"/>
      </material>
    </visual>
    <collision>
      <geometry>
        <box size="0.82067 0.02224 0.07772"/>
      </geometry>
    </collision>
    <inertial>
      <mass value="5"/>
    </inertial>
  </link>
  <joint name="base_link_to_left_channel" type="fixed">
    <parent link="base_link"/>
    <child link="left_channel"/>
    <origin rpy="0 0 0" xyz="0 0.23653 0"/>
  </joint>
  <link name="right_channel">
    <visual>
      <geometry>
        <box size="0.82067 0.02224 0.07772"/>
      </geometry>
      <material name="gray">
        <color rgba="0.70 0.70 0.73 1.0"/>
      </material>
    </visual>
    <collision>
      <geometry>
        <box size="0.82067 0.02224 0.07772"/>
      </geometry>
    </collision>
    <inertial>
      <mass value="5"/>
    </inertial>
  </link>
  <joint name="base_link_to_right_channel" type="fixed">
    <parent link="base_link"/>
    <child link="right_channel"/>
    <origin rpy="0 0 0" xyz="0 -0.23653 0"/>
  </joint>
  <link name="front_left_wheel">
    <inertial>
      <origin rpy="0 0 0" xyz="-3.9077136779291E-16 -0.0136205707454137 -1.44489682185117E-14"/>
      <mass value="0.25"/>
    </inertial>
    <visual>
      <origin rpy="0 0 0" xyz="0 0 0"/>
      <geometry>
        <mesh filename="package://linorobot2_description/mecanum_wheel_left/meshes/base_link.STL"/>
      </geometry>
      <material name="">
        <color rgba="0.898039215686275 0.917647058823529 0.929411764705882 1"/>
      </material>
    </visual>
    <collision>
      <origin rpy="0 0 0" xyz="0 0 0"/>
      <geometry>
        <mesh filename="package://linorobot2_description/mecanum_wheel_left/meshes/base_link.STL"/>
      </geometry>
    </collision>
  </link>
  <joint name="base_link_to_front_left_wheel" type="continuous">
    <origin rpy="0 0 0" xyz="0.25857 0.19355 0"/>
    <parent link="base_link"/>
    <child link="front_left_wheel"/>
    <axis xyz="0 1 0"/>
    <dynamics damping="0.1" friction="0.01"/>
  </joint>
  <link name="front_left_plate1">
    <inertial>
      <mass value="0.5"/>
    </inertial>
    <visual>
      <origin rpy="0 0 0" xyz="0 0 0"/>
      <geometry>
        <mesh filename="package://linorobot2_description/mecanum_wheel_left/meshes/plate1.STL"/>
      </geometry>
      <material name="">
        <color rgba="0.650980392156863 0.619607843137255 0.588235294117647 1"/>
      </material>
    </visual>
    <collision>
      <origin rpy="0 0 0" xyz="0 0 0"/>
      <geometry>
        <mesh filename="package://linorobot2_description/mecanum_wheel_left/meshes/plate1.STL"/>
      </geometry>
    </collision>
  </link>
  <joint name="front_left_wheel_to_front_left_plate1" type="fixed">
    <origin rpy="-1.5708 0.03287 0" xyz="0 0.023114 0"/>
    <parent link="front_left_wheel"/>
    <child link="front_left_plate1"/>
    <axis xyz="0 0 0"/>
  </joint>
  <link name="front_left_plate2">
    <inertial>
      <mass value="0.5"/>
    </inertial>
    <visual>
      <origin rpy="0 0 0" xyz="0 0 0"/>
      <geometry>
        <mesh filename="package://linorobot2_description/mecanum_wheel_left/meshes/plate2.STL"/>
      </geometry>
      <material name="">
        <color rgba="0.650980392156863 0.619607843137255 0.588235294117647 1"/>
      </material>
    </visual>
    <collision>
      <origin rpy="0 0 0" xyz="0 0 0"/>
      <geometry>
        <mesh filename="package://linorobot2_description/mecanum_wheel_left/meshes/plate2.STL"/>
      </geometry>
    </collision>
  </link>
  <joint name="front_left_wheel_to_front_left_plate2" type="fixed">
    <origin rpy="-1.5707963267949 0.0335546833724646 -3.14159265358979" xyz="0 -0.023114 0"/>
    <parent link="front_left_wheel"/>
    <child link="front_left_plate2"/>
    <axis xyz="0 0 0"/>
  </joint>
  <link name="front_left_roller1">
    <inertial>
      <origin rpy="0 0 0" xyz="5.96744875736022E-16 -1.24475083018716E-14 -0.0215899999999933"/>
      <mass value="0.025"/>
    </inertial>
    <visual>
      <origin rpy="0 0 0" xyz="0 0 0"/>
      <geometry>
        <mesh filename="package://linorobot2_description/mecanum_wheel_left/meshes/roller1.STL"/>
      </geometry>
      <material name="">
        <color rgba="0.752941176470588 0.752941176470588 0.752941176470588 1"/>
      </material>
    </visual>
    <collision>
      <origin rpy="0 0 0" xyz="0 0 0"/>
      <geometry>
        <mesh filename="package://linorobot2_description/mecanum_wheel_left/meshes/roller1.STL"/>
      </geometry>
    </collision>
  </link>
  <joint name="front_left_wheel_to_front_left_roller1" type="continuous">
    <origin rpy="2.3375 0.48899 -0.038445" xyz="-0.064997 -0.01515 0.019737"/>
    <parent link="front_left_wheel"/>
    <child link="front_left_roller1"/>
    <axis xyz="0 0 1"/>
    <dynamics damping="0.1" friction="0.01"/>
  </joint>
  <link name="front_left_roller2">
    <inertial>
      <origin rpy="0 0 0" xyz="5.82867087928207E-16 -9.95687907123788E-15 -0.0215899999999933"/>
      <mass value="0.025"/>
    </inertial>
    <visual>
      <origin rpy="0 0 0" xyz="0 0 0"/>
      <geometry>
        <mesh filename="package://linorobot2_description/mecanum_wheel_left/meshes/roller2.STL"/>
      </geometry>
      <material name="">
        <color rgba="0.752941176470588 0.752941176470588 0.752941176470588 1"/>
      </material>
    </visual>
    <collision>
      <origin rpy="0 0 0" xyz="0 0 0"/>
      <geometry>
        <mesh filename="package://linorobot2_description/mecanum_wheel_left/meshes/roller2.STL"/>
      </geometry>
    </collision>
  </link>
  <joint name="front_left_wheel_to_front_left_roller2" type="continuous">
    <origin rpy="2.3122 0.90744 -0.055132" xyz="-0.05135 -0.01515 0.044467"/>
    <parent link="front_left_wheel"/>
    <child link="front_left_roller2"/>
    <axis xyz="0 0 1"/>
    <dynamics damping="0.1" friction="0.01"/>
  </joint>
  <link name="front_left_roller3">
    <inertial>
      <origin rpy="0 0 0" xyz="5.82867087928207E-16 -3.41003267290141E-15 -0.0215899999999933"/>
      <mass value="0.025"/>
    </inertial>
    <visual>
      <origin rpy="0 0 0" xyz="0 0 0"/>
      <geometry>
        <mesh filename="package://linorobot2_description/mecanum_wheel_left/meshes/roller3.STL"/>
      </geometry>
      <material name="">
        <color rgba="0.752941176470588 0.752941176470588 0.752941176470588 1"/>
      </material>
    </visual>
    <collision>
      <origin rpy="0 0 0" xyz="0 0 0"/>
      <geometry>
        <mesh filename="package://linorobot2_description/mecanum_wheel_left/meshes/roller3.STL"/>
      </geometry>
    </collision>
  </link>
  <joint name="front_left_wheel_to_front_left_roller3" type="continuous">
    <origin rpy="2.22 1.3248 -0.13976" xyz="-0.028824 -0.01515 0.061508"/>
    <parent link="front_left_wheel"/>
    <child link="front_left_roller3"/>
    <axis xyz="0 0 1"/>
    <dynamics damping="0.1" friction="0.01"/>
  </joint>
  <link name="front_left_roller4">
    <inertial>
      <origin rpy="0 0 0" xyz="5.68989300120393E-16 -3.35365415993216E-15 -0.0215899999999933"/>
      <mass value="0.025"/>
    </inertial>
    <visual>
      <origin rpy="0 0 0" xyz="0 0 0"/>
      <geometry>
        <mesh filename="package://linorobot2_description/mecanum_wheel_left/meshes/roller4.STL"/>
      </geometry>
      <material name="">
        <color rgba="0.752941176470588 0.752941176470588 0.752941176470588 1"/>
      </material>
    </visual>
    <collision>
      <origin rpy="0 0 0" xyz="0 0 0"/>
      <geometry>
        <mesh filename="package://linorobot2_description/mecanum_wheel_left/meshes/roller4.STL"/>
      </geometry>
    </collision>
  </link>
  <joint name="front_left_wheel_to_front_left_roller4" type="continuous">
    <origin rpy="-0.59653 1.3924 -2.9492" xyz="-0.0013143 -0.01515 0.067914"/>
    <parent link="front_left_wheel"/>
    <child link="front_left_roller4"/>
    <axis xyz="0 0 1"/>
    <dynamics damping="0.1" friction="0.01"/>
  </joint>
  <link name="front_left_roller5">
    <inertial>
      <origin rpy="0 0 0" xyz="5.96744875736022E-16 2.4459601011273E-15 -0.0215899999999933"/>
      <mass value="0.025"/>
    </inertial>
    <visual>
      <origin rpy="0 0 0" xyz="0 0 0"/>
      <geometry>
        <mesh filename="package://linorobot2_description/mecanum_wheel_left/meshes/roller5.STL"/>
      </geometry>
      <material name="">
        <color rgba="0.752941176470588 0.752941176470588 0.752941176470588 1"/>
      </material>
    </visual>
    <collision>
      <origin rpy="0 0 0" xyz="0 0 0"/>
      <geometry>
        <mesh filename="package://linorobot2_description/mecanum_wheel_left/meshes/roller5.STL"/>
      </geometry>
    </collision>
  </link>
  <joint name="front_left_wheel_to_front_left_roller5" type="continuous">
    <origin rpy="-0.73578 0.97593 -3.081" xyz="0.026423 -0.01515 0.062578"/>
    <parent link="front_left_wheel"/>
    <child link="front_left_roller5"/>
    <axis xyz="0 0 1"/>
    <dynamics damping="0.1" friction="0.01"/>
  </joint>
  <link name="front_left_roller6">
    <inertial>
      <origin rpy="0 0 0" xyz="5.82867087928207E-16 -7.52392939618041E-15 -0.0215899999999933"/>
      <mass value="0.025"/>
    </inertial>
    <visual>
      <origin rpy="0 0 0" xyz="0 0 0"/>
      <geometry>
        <mesh filename="package://linorobot2_description/mecanum_wheel_left/meshes/roller6.STL"/>
      </geometry>
      <material name="">
        <color rgba="0.752941176470588 0.752941176470588 0.752941176470588 1"/>
      </material>
    </visual>
    <collision>
      <origin rpy="0 0 0" xyz="0 0 0"/>
      <geometry>
        <mesh filename="package://linorobot2_description/mecanum_wheel_left/meshes/roller6.STL"/>
      </geometry>
    </collision>
  </link>
  <joint name="front_left_wheel_to_front_left_roller6" type="continuous">
    <origin rpy="-0.76481 0.55754 -3.1016" xyz="0.049591 -0.01515 0.04642"/>
    <parent link="front_left_wheel"/>
    <child link="front_left_roller6"/>
    <axis xyz="0 0 1"/>
    <dynamics damping="0.1" friction="0.01"/>
  </joint>
  <link name="front_left_roller7">
    <inertial>
      <origin rpy="0 0 0" xyz="5.82867087928207E-16 -3.4109000346394E-15 -0.0215899999999933"/>
      <mass value="0.025"/>
    </inertial>
    <visual>
      <origin rpy="0 0 0" xyz="0 0 0"/>
      <geometry>
        <mesh filename="package://linorobot2_description/mecanum_wheel_left/meshes/roller7.STL"/>
      </geometry>
      <material name="">
        <color rgba="0.752941176470588 0.752941176470588 0.752941176470588 1"/>
      </material>
    </visual>
    <collision>
      <origin rpy="0 0 0" xyz="0 0 0"/>
      <geometry>
        <mesh filename="package://linorobot2_description/mecanum_wheel_left/meshes/roller7.STL"/>
      </geometry>
    </collision>
  </link>
  <joint name="front_left_wheel_to_front_left_roller7" type="continuous">
    <origin rpy="-0.78123 0.13894 -3.1073" xyz="0.064184 -0.01515 0.022237"/>
    <parent link="front_left_wheel"/>
    <child link="front_left_roller7"/>
    <axis xyz="0 0 1"/>
    <dynamics damping="0.1" friction="0.01"/>
  </joint>
  <link name="front_left_roller8">
    <inertial>
      <origin rpy="0 0 0" xyz="5.82867087928207E-16 -1.76421377506841E-15 -0.0215899999999933"/>
      <mass value="0.025"/>
    </inertial>
    <visual>
      <origin rpy="0 0 0" xyz="0 0 0"/>
      <geometry>
        <mesh filename="package://linorobot2_description/mecanum_wheel_left/meshes/roller8.STL"/>
      </geometry>
      <material name="">
        <color rgba="0.752941176470588 0.752941176470588 0.752941176470588 1"/>
      </material>
    </visual>
    <collision>
      <origin rpy="0 0 0" xyz="0 0 0"/>
      <geometry>
        <mesh filename="package://linorobot2_description/mecanum_wheel_left/meshes/roller8.STL"/>
      </geometry>
    </collision>
  </link>
  <joint name="front_left_wheel_to_front_left_roller8" type="continuous">
    <origin rpy="-0.79573 -0.27969 -3.1063" xyz="0.06768 -0.01515 -0.0057919"/>
    <parent link="front_left_wheel"/>
    <child link="front_left_roller8"/>
    <axis xyz="0 0 1"/>
    <dynamics damping="0.1" friction="0.01"/>
  </joint>
  <link name="front_left_roller9">
    <inertial>
      <origin rpy="0 0 0" xyz="5.82867087928207E-16 -5.1013880619788E-15 -0.0215899999999933"/>
      <mass value="0.025"/>
    </inertial>
    <visual>
      <origin rpy="0 0 0" xyz="0 0 0"/>
      <geometry>
        <mesh filename="package://linorobot2_description/mecanum_wheel_left/meshes/roller9.STL"/>
      </geometry>
      <material name="">
        <color rgba="0.752941176470588 0.752941176470588 0.752941176470588 1"/>
      </material>
    </visual>
    <collision>
      <origin rpy="0 0 0" xyz="0 0 0"/>
      <geometry>
        <mesh filename="package://linorobot2_description/mecanum_wheel_left/meshes/roller9.STL"/>
      </geometry>
    </collision>
  </link>
  <joint name="front_left_wheel_to_front_left_roller9" type="continuous">
    <origin rpy="-0.81448 -0.69826 -3.0973" xyz="0.059473 -0.01515 -0.032819"/>
    <parent link="front_left_wheel"/>
    <child link="front_left_roller9"/>
    <axis xyz="0 0 1"/>
    <dynamics damping="0.1" friction="0.01"/>
  </joint>
  <link name="front_left_roller10">
    <inertial>
      <origin rpy="0 0 0" xyz="5.96744875736022E-16 -6.51952450358984E-15 -0.0215899999999933"/>
      <mass value="0.025"/>
    </inertial>
    <visual>
      <origin rpy="0 0 0" xyz="0 0 0"/>
      <geometry>
        <mesh filename="package://linorobot2_description/mecanum_wheel_left/meshes/roller10.STL"/>
      </geometry>
      <material name="">
        <color rgba="0.752941176470588 0.752941176470588 0.752941176470588 1"/>
      </material>
    </visual>
    <collision>
      <origin rpy="0 0 0" xyz="0 0 0"/>
      <geometry>
        <mesh filename="package://linorobot2_description/mecanum_wheel_left/meshes/roller10.STL"/>
      </geometry>
    </collision>
  </link>
  <joint name="front_left_wheel_to_front_left_roller10" type="continuous">
    <origin rpy="-0.85554 -1.1164 -3.0642" xyz="0.040982 -0.01515 -0.054171"/>
    <parent link="front_left_wheel"/>
    <child link="front_left_roller10"/>
    <axis xyz="0 0 1"/>
    <dynamics damping="0.1" friction="0.01"/>
  </joint>
  <link name="front_left_roller11">
    <inertial>
      <origin rpy="0 0 0" xyz="5.68989300120393E-16 -3.40699690681845E-15 -0.0215899999999933"/>
      <mass value="0.025"/>
    </inertial>
    <visual>
      <origin rpy="0 0 0" xyz="0 0 0"/>
      <geometry>
        <mesh filename="package://linorobot2_description/mecanum_wheel_left/meshes/roller11.STL"/>
      </geometry>
      <material name="">
        <color rgba="0.752941176470588 0.752941176470588 0.752941176470588 1"/>
      </material>
    </visual>
    <collision>
      <origin rpy="0 0 0" xyz="0 0 0"/>
      <geometry>
        <mesh filename="package://linorobot2_description/mecanum_wheel_left/meshes/roller11.STL"/>
      </geometry>
    </collision>
  </link>
  <joint name="front_left_wheel_to_front_left_roller11" type="continuous">
    <origin rpy="-1.5658 -1.5225 -2.3612" xyz="0.015406 -0.01515 -0.066157"/>
    <parent link="front_left_wheel"/>
    <child link="front_left_roller11"/>
    <axis xyz="0 0 1"/>
    <dynamics damping="0.1" friction="0.01"/>
  </joint>
  <link name="front_left_roller12">
    <inertial>
      <origin rpy="0 0 0" xyz="5.96744875736022E-16 -9.87751547221194E-15 -0.0215899999999933"/>
      <mass value="0.025"/>
    </inertial>
    <visual>
      <origin rpy="0 0 0" xyz="0 0 0"/>
      <geometry>
        <mesh filename="package://linorobot2_description/mecanum_wheel_left/meshes/roller12.STL"/>
      </geometry>
      <material name="">
        <color rgba="0.752941176470588 0.752941176470588 0.752941176470588 1"/>
      </material>
    </visual>
    <collision>
      <origin rpy="0 0 0" xyz="0 0 0"/>
      <geometry>
        <mesh filename="package://linorobot2_description/mecanum_wheel_left/meshes/roller12.STL"/>
      </geometry>
    </collision>
  </link>
  <joint name="front_left_wheel_to_front_left_roller12" type="continuous">
    <origin rpy="2.4393 -1.1848 -0.090248" xyz="-0.012835 -0.01515 -0.066704"/>
    <parent link="front_left_wheel"/>
    <child link="front_left_roller12"/>
    <axis xyz="0 0 1"/>
    <dynamics damping="0.1" friction="0.01"/>
  </joint>
  <link name="front_left_roller13">
    <inertial>
      <origin rpy="0 0 0" xyz="6.10622663543836E-16 -6.50608039665102E-15 -0.0215899999999933"/>
      <mass value="0.025"/>
    </inertial>
    <visual>
      <origin rpy="0 0 0" xyz="0 0 0"/>
      <geometry>
        <mesh filename="package://linorobot2_description/mecanum_wheel_left/meshes/roller13.STL"/>
      </geometry>
      <material name="">
        <color rgba="0.752941176470588 0.752941176470588 0.752941176470588 1"/>
      </material>
    </visual>
    <collision>
      <origin rpy="0 0 0" xyz="0 0 0"/>
      <geometry>
        <mesh filename="package://linorobot2_description/mecanum_wheel_left/meshes/roller13.STL"/>
      </geometry>
    </collision>
  </link>
  <joint name="front_left_wheel_to_front_left_roller13" type="continuous">
    <origin rpy="2.3883 -0.76678 -0.047134" xyz="-0.038856 -0.01515 -0.055716"/>
    <parent link="front_left_wheel"/>
    <child link="front_left_roller13"/>
    <axis xyz="0 0 1"/>
    <dynamics damping="0.1" friction="0.01"/>
  </joint>
  <link name="front_left_roller14">
    <inertial>
      <origin rpy="0 0 0" xyz="5.96744875736022E-16 -3.365797224264E-15 -0.0215899999999933"/>
      <mass value="0.025"/>
    </inertial>
    <visual>
      <origin rpy="0 0 0" xyz="0 0 0"/>
      <geometry>
        <mesh filename="package://linorobot2_description/mecanum_wheel_left/meshes/roller14.STL"/>
      </geometry>
      <material name="">
        <color rgba="0.752941176470588 0.752941176470588 0.752941176470588 1"/>
      </material>
    </visual>
    <collision>
      <origin rpy="0 0 0" xyz="0 0 0"/>
      <geometry>
        <mesh filename="package://linorobot2_description/mecanum_wheel_left/meshes/roller14.STL"/>
      </geometry>
    </collision>
  </link>
  <joint name="front_left_wheel_to_front_left_roller14" type="continuous">
    <origin rpy="2.3679 -0.34825 -0.036106" xyz="-0.058159 -0.01515 -0.035095"/>
    <parent link="front_left_wheel"/>
    <child link="front_left_roller14"/>
    <axis xyz="0 0 1"/>
    <dynamics damping="0.1" friction="0.01"/>
  </joint>
  <link name="front_left_roller15">
    <inertial>
      <origin rpy="0 0 0" xyz="5.82867087928207E-16 -3.35452152167015E-15 -0.0215899999999933"/>
      <mass value="0.025"/>
    </inertial>
    <visual>
      <origin rpy="0 0 0" xyz="0 0 0"/>
      <geometry>
        <mesh filename="package://linorobot2_description/mecanum_wheel_left/meshes/roller15.STL"/>
      </geometry>
      <material name="">
        <color rgba="0.752941176470588 0.752941176470588 0.752941176470588 1"/>
      </material>
    </visual>
    <collision>
      <origin rpy="0 0 0" xyz="0 0 0"/>
      <geometry>
        <mesh filename="package://linorobot2_description/mecanum_wheel_left/meshes/roller15.STL"/>
      </geometry>
    </collision>
  </link>
  <joint name="front_left_wheel_to_front_left_roller15" type="continuous">
    <origin rpy="2.35322166168045 0.070379538766794 -0.0340216727613588" xyz="-0.0674050504299177 -0.0151497403158722 -0.00840608812639412"/>
    <parent link="front_left_wheel"/>
    <child link="front_left_roller15"/>
    <axis xyz="0 0 1"/>
    <dynamics damping="0.1" friction="0.01"/>
  </joint>
  <link name="front_right_wheel">
    <inertial>
      <origin rpy="0 0 0" xyz="-1.48571881243385E-15 -6.7886631592007E-16 -0.0136209233699844"/>
      <mass value="0.25"/>
    </inertial>
    <visual>
      <origin rpy="0 0 0" xyz="0 0 0"/>
      <geometry>
        <mesh filename="package://linorobot2_description/mecanum_wheel_right/meshes/base_link.STL"/>
      </geometry>
      <material name="">
        <color rgba="0.898039215686275 0.917647058823529 0.929411764705882 1"/>
      </material>
    </visual>
    <collision>
      <origin rpy="0 0 0" xyz="0 0 0"/>
      <geometry>
        <mesh filename="package://linorobot2_description/mecanum_wheel_right/meshes/base_link.STL"/>
      </geometry>
    </collision>
  </link>
  <joint name="base_link_to_front_right_wheel" type="continuous">
    <origin rpy="0 0 0" xyz="0.25857 -0.19355 0"/>
    <parent link="base_link"/>
    <child link="front_right_wheel"/>
    <axis xyz="0 1 0"/>
  </joint>
  <link name="front_right_drum">
    <inertial>
      <origin rpy="0 0 0" xyz="0.0136209233699844 6.56957443528167E-16 -1.48512976903392E-15"/>
      <mass value="0.5"/>
    </inertial>
    <visual>
      <origin rpy="0 0 0" xyz="0 0 0"/>
      <geometry>
        <mesh filename="package://linorobot2_description/mecanum_wheel_right/meshes/drum.STL"/>
      </geometry>
      <material name="">
        <color rgba="0.898039215686275 0.917647058823529 0.929411764705882 1"/>
      </material>
    </visual>
    <collision>
      <origin rpy="0 0 0" xyz="0 0 0"/>
      <geometry>
        <mesh filename="package://linorobot2_description/mecanum_wheel_right/meshes/drum.STL"/>
      </geometry>
    </collision>
  </link>
  <joint name="front_right_wheel_to_drum" type="fixed">
    <origin rpy="1.5707963267949 0 -1.5707963267949" xyz="0 0 0"/>
    <parent link="front_right_wheel"/>
    <child link="front_right_drum"/>
    <axis xyz="0 0 0"/>
  </joint>
  <link name="front_right_plate1">
    <inertial>
      <mass value="0.5"/>
    </inertial>
    <visual>
      <origin rpy="0 0 0" xyz="0 0 0"/>
      <geometry>
        <mesh filename="package://linorobot2_description/mecanum_wheel_right/meshes/plate1.STL"/>
      </geometry>
      <material name="">
        <color rgba="0.752941176470588 0.752941176470588 0.752941176470588 1"/>
      </material>
    </visual>
    <collision>
      <origin rpy="0 0 0" xyz="0 0 0"/>
      <geometry>
        <mesh filename="package://linorobot2_description/mecanum_wheel_right/meshes/plate1.STL"/>
      </geometry>
    </collision>
  </link>
  <joint name="front_right_wheel_to_front_right_plate1" type="fixed">
    <origin rpy="-1.60435101016735 0 1.5707963267949" xyz="0 0.0254 0"/>
    <parent link="front_right_wheel"/>
    <child link="front_right_plate1"/>
    <axis xyz="0 0 0"/>
  </joint>
  <link name="front_right_plate2">
    <inertial>
      <mass value="0.5"/>
    </inertial>
    <visual>
      <origin rpy="0 0 0" xyz="0 0 0"/>
      <geometry>
        <mesh filename="package://linorobot2_description/mecanum_wheel_right/meshes/plate2.STL"/>
      </geometry>
      <material name="">
        <color rgba="0.752941176470588 0.752941176470588 0.752941176470588 1"/>
      </material>
    </visual>
    <collision>
      <origin rpy="0 0 0" xyz="0 0 0"/>
      <geometry>
        <mesh filename="package://linorobot2_description/mecanum_wheel_right/meshes/plate2.STL"/>
      </geometry>
    </collision>
  </link>
  <joint name="front_right_wheel_to_front_right_plate2" type="fixed">
    <origin rpy="1.60435101016734 0 -1.5707963267949" xyz="0 -0.0254 0"/>
    <parent link="front_right_wheel"/>
    <child link="front_right_plate2"/>
    <axis xyz="0 0 0"/>
  </joint>
  <link name="front_right_roller1">
    <inertial>
      <origin rpy="0 0 0" xyz="5.82867087928207E-16 3.51108031537706E-15 -0.0215899999999933"/>
      <mass value="0.025"/>
    </inertial>
    <visual>
      <origin rpy="0 0 0" xyz="0 0 0"/>
      <geometry>
        <mesh filename="package://linorobot2_description/mecanum_wheel_right/meshes/roller1.STL"/>
      </geometry>
      <material name="">
        <color rgba="0.752941176470588 0.752941176470588 0.752941176470588 1"/>
      </material>
    </visual>
    <collision>
      <origin rpy="0 0 0" xyz="0 0 0"/>
      <geometry>
        <mesh filename="package://linorobot2_description/mecanum_wheel_right/meshes/roller1.STL"/>
      </geometry>
    </collision>
  </link>
  <joint name="front_right_wheel_to_front_right_roller1" type="continuous">
    <origin rpy="-2.36778917303694 -0.95454994461673 -1.76416393166909" xyz="0.0513105165568448 -0.0151129693198936 0.0444755356274741"/>
    <parent link="front_right_wheel"/>
    <child link="front_right_roller1"/>
    <axis xyz="0 0 1"/>
    <dynamics damping="0.1" friction="0.01"/>
  </joint>
  <link name="front_right_roller2">
    <inertial>
      <origin rpy="0 0 0" xyz="5.68989300120393E-16 -1.90819582357449E-15 -0.0215899999999933"/>
      <mass value="0.025"/>
    </inertial>
    <visual>
      <origin rpy="0 0 0" xyz="0 0 0"/>
      <geometry>
        <mesh filename="package://linorobot2_description/mecanum_wheel_right/meshes/roller2.STL"/>
      </geometry>
      <material name="">
        <color rgba="0.752941176470588 0.752941176470588 0.752941176470588 1"/>
      </material>
    </visual>
    <collision>
      <origin rpy="0 0 0" xyz="0 0 0"/>
      <geometry>
        <mesh filename="package://linorobot2_description/mecanum_wheel_right/meshes/roller2.STL"/>
      </geometry>
    </collision>
  </link>
  <joint name="front_right_wheel_to_front_right_roller2" type="continuous">
    <origin rpy="-1.77439072812908 -0.775855866169197 -2.22324127737972" xyz="0.0287846592696844 -0.0151129693198959 0.0615002908075162"/>
    <parent link="front_right_wheel"/>
    <child link="front_right_roller2"/>
    <axis xyz="0 0 1"/>
    <dynamics damping="0.1" friction="0.01"/>
  </joint>
  <link name="front_right_roller3">
    <inertial>
      <origin rpy="0 0 0" xyz="5.82867087928207E-16 -4.16333634234434E-17 -0.0215899999999933"/>
      <mass value="0.025"/>
    </inertial>
    <visual>
      <origin rpy="0 0 0" xyz="0 0 0"/>
      <geometry>
        <mesh filename="package://linorobot2_description/mecanum_wheel_right/meshes/roller3.STL"/>
      </geometry>
      <material name="">
        <color rgba="0.752941176470588 0.752941176470588 0.752941176470588 1"/>
      </material>
    </visual>
    <collision>
      <origin rpy="0 0 0" xyz="0 0 0"/>
      <geometry>
        <mesh filename="package://linorobot2_description/mecanum_wheel_right/meshes/roller3.STL"/>
      </geometry>
    </collision>
  </link>
  <joint name="front_right_wheel_to_front_right_roller3" type="continuous">
    <origin rpy="-1.40103696999546 -0.48194994387805 -2.44694050545059" xyz="0.00128167289437567 -0.0151129693198984 0.0678910869943366"/>
    <parent link="front_right_wheel"/>
    <child link="front_right_roller3"/>
    <axis xyz="0 0 1"/>
    <dynamics damping="0.1" friction="0.01"/>
  </joint>
  <link name="front_right_roller4">
    <inertial>
      <origin rpy="0 0 0" xyz="5.89805981832114E-16 -3.20576898360514E-15 -0.0215899999999933"/>
      <mass value="0.025"/>
    </inertial>
    <visual>
      <origin rpy="0 0 0" xyz="0 0 0"/>
      <geometry>
        <mesh filename="package://linorobot2_description/mecanum_wheel_right/meshes/roller4.STL"/>
      </geometry>
      <material name="">
        <color rgba="0.752941176470588 0.752941176470588 0.752941176470588 1"/>
      </material>
    </visual>
    <collision>
      <origin rpy="0 0 0" xyz="0 0 0"/>
      <geometry>
        <mesh filename="package://linorobot2_description/mecanum_wheel_right/meshes/roller4.STL"/>
      </geometry>
    </collision>
  </link>
  <joint name="front_right_wheel_to_front_right_roller4" type="continuous">
    <origin rpy="-1.13469826196558 -0.147073422491862 -2.53094960861872" xyz="-0.0264429263680024 -0.0151129693199014 0.062542897468674"/>
    <parent link="front_right_wheel"/>
    <child link="front_right_roller4"/>
    <axis xyz="0 0 1"/>
    <dynamics damping="0.1" friction="0.01"/>
  </joint>
  <link name="front_right_roller5">
    <inertial>
      <origin rpy="0 0 0" xyz="5.82867087928207E-16 -7.39686090156511E-15 -0.0215899999999933"/>
      <mass value="0.025"/>
    </inertial>
    <visual>
      <origin rpy="0 0 0" xyz="0 0 0"/>
      <geometry>
        <mesh filename="package://linorobot2_description/mecanum_wheel_right/meshes/roller5.STL"/>
      </geometry>
      <material name="">
        <color rgba="0.752941176470588 0.752941176470588 0.752941176470588 1"/>
      </material>
    </visual>
    <collision>
      <origin rpy="0 0 0" xyz="0 0 0"/>
      <geometry>
        <mesh filename="package://linorobot2_description/mecanum_wheel_right/meshes/roller5.STL"/>
      </geometry>
    </collision>
  </link>
  <joint name="front_right_wheel_to_front_right_roller5" type="continuous">
    <origin rpy="-0.894575475762315 0.197031441859666 -2.52483292758441" xyz="-0.0495953034349089 -0.0151129693199047 0.0463804727862918"/>
    <parent link="front_right_wheel"/>
    <child link="front_right_roller5"/>
    <axis xyz="0 0 1"/>
    <dynamics damping="0.1" friction="0.01"/>
  </joint>
  <link name="front_right_roller6">
    <inertial>
      <origin rpy="0 0 0" xyz="5.89805981832114E-16 -9.20097331658098E-15 -0.0215899999999933"/>
      <mass value="0.025"/>
    </inertial>
    <visual>
      <origin rpy="0 0 0" xyz="0 0 0"/>
      <geometry>
        <mesh filename="package://linorobot2_description/mecanum_wheel_right/meshes/roller6.STL"/>
      </geometry>
      <material name="">
        <color rgba="0.752941176470588 0.752941176470588 0.752941176470588 1"/>
      </material>
    </visual>
    <collision>
      <origin rpy="0 0 0" xyz="0 0 0"/>
      <geometry>
        <mesh filename="package://linorobot2_description/mecanum_wheel_right/meshes/roller6.STL"/>
      </geometry>
    </collision>
  </link>
  <joint name="front_right_wheel_to_front_right_roller6" type="continuous">
    <origin rpy="-0.618670381864381 0.528470873009444 -2.42501713902796" xyz="-0.0641722019787319 -0.0151129693199074 0.0221984430057918"/>
    <parent link="front_right_wheel"/>
    <child link="front_right_roller6"/>
    <axis xyz="0 0 1"/>
    <dynamics damping="0.1" friction="0.01"/>
  </joint>
  <link name="front_right_roller7">
    <inertial>
      <origin rpy="0 0 0" xyz="5.89805981832114E-16 -8.25034485174569E-15 -0.0215899999999933"/>
      <mass value="0.025"/>
    </inertial>
    <visual>
      <origin rpy="0 0 0" xyz="0 0 0"/>
      <geometry>
        <mesh filename="package://linorobot2_description/mecanum_wheel_right/meshes/roller7.STL"/>
      </geometry>
      <material name="">
        <color rgba="0.752941176470588 0.752941176470588 0.752941176470588 1"/>
      </material>
    </visual>
    <collision>
      <origin rpy="0 0 0" xyz="0 0 0"/>
      <geometry>
        <mesh filename="package://linorobot2_description/mecanum_wheel_right/meshes/roller7.STL"/>
      </geometry>
    </collision>
  </link>
  <joint name="front_right_wheel_to_front_right_roller7" type="continuous">
    <origin rpy="-0.22003525595071 0.81173834281584 -2.17291203984087" xyz="-0.0676531438142786 -0.0151129693199092 -0.0058218992369328"/>
    <parent link="front_right_wheel"/>
    <child link="front_right_roller7"/>
    <axis xyz="0 0 1"/>
    <dynamics damping="0.1" friction="0.01"/>
  </joint>
  <link name="front_right_roller8">
    <inertial>
      <origin rpy="0 0 0" xyz="5.759281940243E-16 2.22044604925031E-15 -0.0215899999999933"/>
      <mass value="0.025"/>
    </inertial>
    <visual>
      <origin rpy="0 0 0" xyz="0 0 0"/>
      <geometry>
        <mesh filename="package://linorobot2_description/mecanum_wheel_right/meshes/roller8.STL"/>
      </geometry>
      <material name="">
        <color rgba="0.752941176470588 0.752941176470588 0.752941176470588 1"/>
      </material>
    </visual>
    <collision>
      <origin rpy="0 0 0" xyz="0 0 0"/>
      <geometry>
        <mesh filename="package://linorobot2_description/mecanum_wheel_right/meshes/roller8.STL"/>
      </geometry>
    </collision>
  </link>
  <joint name="front_right_wheel_to_front_right_roller8" type="continuous">
    <origin rpy="0.408043134594723 0.963708851734786 -1.67797755478808" xyz="-0.0594362424748194 -0.0151129693199101 -0.0328355822112983"/>
    <parent link="front_right_wheel"/>
    <child link="front_right_roller8"/>
    <axis xyz="0 0 1"/>
    <dynamics damping="0.1" friction="0.01"/>
  </joint>
  <link name="front_right_roller9">
    <inertial>
      <origin rpy="0 0 0" xyz="5.759281940243E-16 -2.60208521396521E-15 -0.0215899999999933"/>
      <mass value="0.025"/>
    </inertial>
    <visual>
      <origin rpy="0 0 0" xyz="0 0 0"/>
      <geometry>
        <mesh filename="package://linorobot2_description/mecanum_wheel_right/meshes/roller9.STL"/>
      </geometry>
      <material name="">
        <color rgba="0.752941176470588 0.752941176470588 0.752941176470588 1"/>
      </material>
    </visual>
    <collision>
      <origin rpy="0 0 0" xyz="0 0 0"/>
      <geometry>
        <mesh filename="package://linorobot2_description/mecanum_wheel_right/meshes/roller9.STL"/>
      </geometry>
    </collision>
  </link>
  <joint name="front_right_wheel_to_front_right_roller9" type="continuous">
    <origin rpy="1.1026415771303 0.886919106568413 -1.11464531078552" xyz="-0.0409422748501527 -0.015112969319909 -0.0541716947194296"/>
    <parent link="front_right_wheel"/>
    <child link="front_right_roller9"/>
    <axis xyz="0 0 1"/>
    <dynamics damping="0.1" friction="0.01"/>
  </joint>
  <link name="front_right_roller10">
    <inertial>
      <origin rpy="0 0 0" xyz="5.89805981832114E-16 -3.42087469462626E-15 -0.0215899999999933"/>
      <mass value="0.025"/>
    </inertial>
    <visual>
      <origin rpy="0 0 0" xyz="0 0 0"/>
      <geometry>
        <mesh filename="package://linorobot2_description/mecanum_wheel_right/meshes/roller10.STL"/>
      </geometry>
      <material name="">
        <color rgba="0.752941176470588 0.752941176470588 0.752941176470588 1"/>
      </material>
    </visual>
    <collision>
      <origin rpy="0 0 0" xyz="0 0 0"/>
      <geometry>
        <mesh filename="package://linorobot2_description/mecanum_wheel_right/meshes/roller10.STL"/>
      </geometry>
    </collision>
  </link>
  <joint name="front_right_wheel_to_front_right_roller10" type="continuous">
    <origin rpy="1.57421323203544 0.637163580624169 -0.783361608443036" xyz="-0.0153690159550034 -0.0151129693199065 -0.0661410290761748"/>
    <parent link="front_right_wheel"/>
    <child link="front_right_roller10"/>
    <axis xyz="0 0 1"/>
    <dynamics damping="0.1" friction="0.01"/>
  </joint>
  <link name="front_right_roller11">
    <inertial>
      <origin rpy="0 0 0" xyz="5.89805981832114E-16 -5.03069808033274E-15 -0.0215899999999933"/>
      <mass value="0.025"/>
    </inertial>
    <visual>
      <origin rpy="0 0 0" xyz="0 0 0"/>
      <geometry>
        <mesh filename="package://linorobot2_description/mecanum_wheel_right/meshes/roller11.STL"/>
      </geometry>
      <material name="">
        <color rgba="0.752941176470588 0.752941176470588 0.752941176470588 1"/>
      </material>
    </visual>
    <collision>
      <origin rpy="0 0 0" xyz="0 0 0"/>
      <geometry>
        <mesh filename="package://linorobot2_description/mecanum_wheel_right/meshes/roller11.STL"/>
      </geometry>
    </collision>
  </link>
  <joint name="front_right_wheel_to_front_right_roller11" type="continuous">
    <origin rpy="1.88109068595424 0.317129294370825 -0.639722033593165" xyz="0.0128616854218928 -0.0151129693199038 -0.0666739786332639"/>
    <parent link="front_right_wheel"/>
    <child link="front_right_roller11"/>
    <axis xyz="0 0 1"/>
    <dynamics damping="0.1" friction="0.01"/>
  </joint>
  <link name="front_right_roller12">
    <inertial>
      <origin rpy="0 0 0" xyz="5.759281940243E-16 -3.44169137633799E-15 -0.0215899999999933"/>
      <mass value="0.025"/>
    </inertial>
    <visual>
      <origin rpy="0 0 0" xyz="0 0 0"/>
      <geometry>
        <mesh filename="package://linorobot2_description/mecanum_wheel_right/meshes/roller12.STL"/>
      </geometry>
      <material name="">
        <color rgba="0.752941176470588 0.752941176470588 0.752941176470588 1"/>
      </material>
    </visual>
    <collision>
      <origin rpy="0 0 0" xyz="0 0 0"/>
      <geometry>
        <mesh filename="package://linorobot2_description/mecanum_wheel_right/meshes/roller12.STL"/>
      </geometry>
    </collision>
  </link>
  <joint name="front_right_wheel_to_front_right_roller12" type="continuous">
    <origin rpy="2.12643201705665 -0.025160050703084 -0.60332516970669" xyz="0.0388684845445997 -0.0151129693199006 -0.0556783915705813"/>
    <parent link="front_right_wheel"/>
    <child link="front_right_roller12"/>
    <axis xyz="0 0 1"/>
    <dynamics damping="0.1" friction="0.01"/>
  </joint>
  <link name="front_right_roller13">
    <inertial>
      <origin rpy="0 0 0" xyz="5.89805981832114E-16 -3.36536354339501E-15 -0.0215899999999933"/>
      <mass value="0.025"/>
    </inertial>
    <visual>
      <origin rpy="0 0 0" xyz="0 0 0"/>
      <geometry>
        <mesh filename="package://linorobot2_description/mecanum_wheel_right/meshes/roller13.STL"/>
      </geometry>
      <material name="">
        <color rgba="0.752941176470588 0.752941176470588 0.752941176470588 1"/>
      </material>
    </visual>
    <collision>
      <origin rpy="0 0 0" xyz="0 0 0"/>
      <geometry>
        <mesh filename="package://linorobot2_description/mecanum_wheel_right/meshes/roller13.STL"/>
      </geometry>
    </collision>
  </link>
  <joint name="front_right_wheel_to_front_right_roller13" type="continuous">
    <origin rpy="2.37615666037905 -0.365916365141497 -0.652805521545524" xyz="0.0581545695804492 -0.0151129693198971 -0.0350555047830372"/>
    <parent link="front_right_wheel"/>
    <child link="front_right_roller13"/>
    <axis xyz="0 0 1"/>
    <dynamics damping="0.1" friction="0.01"/>
  </joint>
  <link name="front_right_roller14">
    <inertial>
      <origin rpy="0 0 0" xyz="5.82867087928207E-16 -2.38697950294409E-15 -0.0215899999999933"/>
      <mass value="0.025"/>
    </inertial>
    <visual>
      <origin rpy="0 0 0" xyz="0 0 0"/>
      <geometry>
        <mesh filename="package://linorobot2_description/mecanum_wheel_right/meshes/roller14.STL"/>
      </geometry>
      <material name="">
        <color rgba="0.752941176470588 0.752941176470588 0.752941176470588 1"/>
      </material>
    </visual>
    <collision>
      <origin rpy="0 0 0" xyz="0 0 0"/>
      <geometry>
        <mesh filename="package://linorobot2_description/mecanum_wheel_right/meshes/roller14.STL"/>
      </geometry>
    </collision>
  </link>
  <joint name="front_right_wheel_to_front_right_roller14" type="continuous">
    <origin rpy="2.69941973817462 -0.67973266586857 -0.817294146739146" xyz="0.0673852012181607 -0.0151129693198943 -0.00837120274924246"/>
    <parent link="front_right_wheel"/>
    <child link="front_right_roller14"/>
    <axis xyz="0 0 1"/>
    <dynamics damping="0.1" friction="0.01"/>
  </joint>
  <link name="front_right_roller15">
    <inertial>
      <origin rpy="0 0 0" xyz="5.759281940243E-16 -6.50868248186498E-15 -0.0215899999999933"/>
      <mass value="0.025"/>
    </inertial>
    <visual>
      <origin rpy="0 0 0" xyz="0 0 0"/>
      <geometry>
        <mesh filename="package://linorobot2_description/mecanum_wheel_right/meshes/roller15.STL"/>
      </geometry>
      <material name="">
        <color rgba="0.752941176470588 0.752941176470588 0.752941176470588 1"/>
      </material>
    </visual>
    <collision>
      <origin rpy="0 0 0" xyz="0 0 0"/>
      <geometry>
        <mesh filename="package://linorobot2_description/mecanum_wheel_right/meshes/roller15.STL"/>
      </geometry>
    </collision>
  </link>
  <joint name="front_right_wheel_to_front_right_roller15" type="continuous">
    <origin rpy="-3.077965161563 -0.911914057233449 -1.18487158274901" xyz="0.0649643193899178 -0.0151129693198934 0.0197605562898849"/>
    <parent link="front_right_wheel"/>
    <child link="front_right_roller15"/>
    <axis xyz="0 0 1"/>
    <dynamics damping="0.1" friction="0.01"/>
  </joint>
  <!-- Back wheels mechanum style swapped (left mecanum wheel goes on right side of robot, and vice versa) -->
  <link name="rear_left_wheel">
    <inertial>
      <origin rpy="0 0 0" xyz="-1.48571881243385E-15 -6.7886631592007E-16 -0.0136209233699844"/>
      <mass value="0.25"/>
    </inertial>
    <visual>
      <origin rpy="0 0 0" xyz="0 0 0"/>
      <geometry>
        <mesh filename="package://linorobot2_description/mecanum_wheel_right/meshes/base_link.STL"/>
      </geometry>
      <material name="">
        <color rgba="0.898039215686275 0.917647058823529 0.929411764705882 1"/>
      </material>
    </visual>
    <collision>
      <origin rpy="0 0 0" xyz="0 0 0"/>
      <geometry>
        <mesh filename="package://linorobot2_description/mecanum_wheel_right/meshes/base_link.STL"/>
      </geometry>
    </collision>
  </link>
  <joint name="base_link_to_rear_left_wheel" type="continuous">
    <origin rpy="0 0 0" xyz="-0.25857 0.19355 0"/>
    <parent link="base_link"/>
    <child link="rear_left_wheel"/>
    <axis xyz="0 1 0"/>
  </joint>
  <link name="rear_left_drum">
    <inertial>
      <origin rpy="0 0 0" xyz="0.0136209233699844 6.56957443528167E-16 -1.48512976903392E-15"/>
      <mass value="0.5"/>
    </inertial>
    <visual>
      <origin rpy="0 0 0" xyz="0 0 0"/>
      <geometry>
        <mesh filename="package://linorobot2_description/mecanum_wheel_right/meshes/drum.STL"/>
      </geometry>
      <material name="">
        <color rgba="0.898039215686275 0.917647058823529 0.929411764705882 1"/>
      </material>
    </visual>
    <collision>
      <origin rpy="0 0 0" xyz="0 0 0"/>
      <geometry>
        <mesh filename="package://linorobot2_description/mecanum_wheel_right/meshes/drum.STL"/>
      </geometry>
    </collision>
  </link>
  <joint name="rear_left_wheel_to_drum" type="fixed">
    <origin rpy="1.5707963267949 0 -1.5707963267949" xyz="0 0 0"/>
    <parent link="rear_left_wheel"/>
    <child link="rear_left_drum"/>
    <axis xyz="0 0 0"/>
  </joint>
  <link name="rear_left_plate1">
    <inertial>
      <mass value="0.5"/>
    </inertial>
    <visual>
      <origin rpy="0 0 0" xyz="0 0 0"/>
      <geometry>
        <mesh filename="package://linorobot2_description/mecanum_wheel_right/meshes/plate1.STL"/>
      </geometry>
      <material name="">
        <color rgba="0.752941176470588 0.752941176470588 0.752941176470588 1"/>
      </material>
    </visual>
    <collision>
      <origin rpy="0 0 0" xyz="0 0 0"/>
      <geometry>
        <mesh filename="package://linorobot2_description/mecanum_wheel_right/meshes/plate1.STL"/>
      </geometry>
    </collision>
  </link>
  <joint name="rear_left_wheel_to_rear_left_plate1" type="fixed">
    <origin rpy="-1.60435101016735 0 1.5707963267949" xyz="0 0.0254 0"/>
    <parent link="rear_left_wheel"/>
    <child link="rear_left_plate1"/>
    <axis xyz="0 0 0"/>
  </joint>
  <link name="rear_left_plate2">
    <inertial>
      <mass value="0.5"/>
    </inertial>
    <visual>
      <origin rpy="0 0 0" xyz="0 0 0"/>
      <geometry>
        <mesh filename="package://linorobot2_description/mecanum_wheel_right/meshes/plate2.STL"/>
      </geometry>
      <material name="">
        <color rgba="0.752941176470588 0.752941176470588 0.752941176470588 1"/>
      </material>
    </visual>
    <collision>
      <origin rpy="0 0 0" xyz="0 0 0"/>
      <geometry>
        <mesh filename="package://linorobot2_description/mecanum_wheel_right/meshes/plate2.STL"/>
      </geometry>
    </collision>
  </link>
  <joint name="rear_left_wheel_to_rear_left_plate2" type="fixed">
    <origin rpy="1.60435101016734 0 -1.5707963267949" xyz="0 -0.0254 0"/>
    <parent link="rear_left_wheel"/>
    <child link="rear_left_plate2"/>
    <axis xyz="0 0 0"/>
  </joint>
  <link name="rear_left_roller1">
    <inertial>
      <origin rpy="0 0 0" xyz="5.82867087928207E-16 3.51108031537706E-15 -0.0215899999999933"/>
      <mass value="0.025"/>
    </inertial>
    <visual>
      <origin rpy="0 0 0" xyz="0 0 0"/>
      <geometry>
        <mesh filename="package://linorobot2_description/mecanum_wheel_right/meshes/roller1.STL"/>
      </geometry>
      <material name="">
        <color rgba="0.752941176470588 0.752941176470588 0.752941176470588 1"/>
      </material>
    </visual>
    <collision>
      <origin rpy="0 0 0" xyz="0 0 0"/>
      <geometry>
        <mesh filename="package://linorobot2_description/mecanum_wheel_right/meshes/roller1.STL"/>
      </geometry>
    </collision>
  </link>
  <joint name="rear_left_wheel_to_rear_left_roller1" type="continuous">
    <origin rpy="-2.36778917303694 -0.95454994461673 -1.76416393166909" xyz="0.0513105165568448 -0.0151129693198936 0.0444755356274741"/>
    <parent link="rear_left_wheel"/>
    <child link="rear_left_roller1"/>
    <axis xyz="0 0 1"/>
    <dynamics damping="0.1" friction="0.01"/>
  </joint>
  <link name="rear_left_roller2">
    <inertial>
      <origin rpy="0 0 0" xyz="5.68989300120393E-16 -1.90819582357449E-15 -0.0215899999999933"/>
      <mass value="0.025"/>
    </inertial>
    <visual>
      <origin rpy="0 0 0" xyz="0 0 0"/>
      <geometry>
        <mesh filename="package://linorobot2_description/mecanum_wheel_right/meshes/roller2.STL"/>
      </geometry>
      <material name="">
        <color rgba="0.752941176470588 0.752941176470588 0.752941176470588 1"/>
      </material>
    </visual>
    <collision>
      <origin rpy="0 0 0" xyz="0 0 0"/>
      <geometry>
        <mesh filename="package://linorobot2_description/mecanum_wheel_right/meshes/roller2.STL"/>
      </geometry>
    </collision>
  </link>
  <joint name="rear_left_wheel_to_rear_left_roller2" type="continuous">
    <origin rpy="-1.77439072812908 -0.775855866169197 -2.22324127737972" xyz="0.0287846592696844 -0.0151129693198959 0.0615002908075162"/>
    <parent link="rear_left_wheel"/>
    <child link="rear_left_roller2"/>
    <axis xyz="0 0 1"/>
    <dynamics damping="0.1" friction="0.01"/>
  </joint>
  <link name="rear_left_roller3">
    <inertial>
      <origin rpy="0 0 0" xyz="5.82867087928207E-16 -4.16333634234434E-17 -0.0215899999999933"/>
      <mass value="0.025"/>
    </inertial>
    <visual>
      <origin rpy="0 0 0" xyz="0 0 0"/>
      <geometry>
        <mesh filename="package://linorobot2_description/mecanum_wheel_right/meshes/roller3.STL"/>
      </geometry>
      <material name="">
        <color rgba="0.752941176470588 0.752941176470588 0.752941176470588 1"/>
      </material>
    </visual>
    <collision>
      <origin rpy="0 0 0" xyz="0 0 0"/>
      <geometry>
        <mesh filename="package://linorobot2_description/mecanum_wheel_right/meshes/roller3.STL"/>
      </geometry>
    </collision>
  </link>
  <joint name="rear_left_wheel_to_rear_left_roller3" type="continuous">
    <origin rpy="-1.40103696999546 -0.48194994387805 -2.44694050545059" xyz="0.00128167289437567 -0.0151129693198984 0.0678910869943366"/>
    <parent link="rear_left_wheel"/>
    <child link="rear_left_roller3"/>
    <axis xyz="0 0 1"/>
    <dynamics damping="0.1" friction="0.01"/>
  </joint>
  <link name="rear_left_roller4">
    <inertial>
      <origin rpy="0 0 0" xyz="5.89805981832114E-16 -3.20576898360514E-15 -0.0215899999999933"/>
      <mass value="0.025"/>
    </inertial>
    <visual>
      <origin rpy="0 0 0" xyz="0 0 0"/>
      <geometry>
        <mesh filename="package://linorobot2_description/mecanum_wheel_right/meshes/roller4.STL"/>
      </geometry>
      <material name="">
        <color rgba="0.752941176470588 0.752941176470588 0.752941176470588 1"/>
      </material>
    </visual>
    <collision>
      <origin rpy="0 0 0" xyz="0 0 0"/>
      <geometry>
        <mesh filename="package://linorobot2_description/mecanum_wheel_right/meshes/roller4.STL"/>
      </geometry>
    </collision>
  </link>
  <joint name="rear_left_wheel_to_rear_left_roller4" type="continuous">
    <origin rpy="-1.13469826196558 -0.147073422491862 -2.53094960861872" xyz="-0.0264429263680024 -0.0151129693199014 0.062542897468674"/>
    <parent link="rear_left_wheel"/>
    <child link="rear_left_roller4"/>
    <axis xyz="0 0 1"/>
    <dynamics damping="0.1" friction="0.01"/>
  </joint>
  <link name="rear_left_roller5">
    <inertial>
      <origin rpy="0 0 0" xyz="5.82867087928207E-16 -7.39686090156511E-15 -0.0215899999999933"/>
      <mass value="0.025"/>
    </inertial>
    <visual>
      <origin rpy="0 0 0" xyz="0 0 0"/>
      <geometry>
        <mesh filename="package://linorobot2_description/mecanum_wheel_right/meshes/roller5.STL"/>
      </geometry>
      <material name="">
        <color rgba="0.752941176470588 0.752941176470588 0.752941176470588 1"/>
      </material>
    </visual>
    <collision>
      <origin rpy="0 0 0" xyz="0 0 0"/>
      <geometry>
        <mesh filename="package://linorobot2_description/mecanum_wheel_right/meshes/roller5.STL"/>
      </geometry>
    </collision>
  </link>
  <joint name="rear_left_wheel_to_rear_left_roller5" type="continuous">
    <origin rpy="-0.894575475762315 0.197031441859666 -2.52483292758441" xyz="-0.0495953034349089 -0.0151129693199047 0.0463804727862918"/>
    <parent link="rear_left_wheel"/>
    <child link="rear_left_roller5"/>
    <axis xyz="0 0 1"/>
    <dynamics damping="0.1" friction="0.01"/>
  </joint>
  <link name="rear_left_roller6">
    <inertial>
      <origin rpy="0 0 0" xyz="5.89805981832114E-16 -9.20097331658098E-15 -0.0215899999999933"/>
      <mass value="0.025"/>
    </inertial>
    <visual>
      <origin rpy="0 0 0" xyz="0 0 0"/>
      <geometry>
        <mesh filename="package://linorobot2_description/mecanum_wheel_right/meshes/roller6.STL"/>
      </geometry>
      <material name="">
        <color rgba="0.752941176470588 0.752941176470588 0.752941176470588 1"/>
      </material>
    </visual>
    <collision>
      <origin rpy="0 0 0" xyz="0 0 0"/>
      <geometry>
        <mesh filename="package://linorobot2_description/mecanum_wheel_right/meshes/roller6.STL"/>
      </geometry>
    </collision>
  </link>
  <joint name="rear_left_wheel_to_rear_left_roller6" type="continuous">
    <origin rpy="-0.618670381864381 0.528470873009444 -2.42501713902796" xyz="-0.0641722019787319 -0.0151129693199074 0.0221984430057918"/>
    <parent link="rear_left_wheel"/>
    <child link="rear_left_roller6"/>
    <axis xyz="0 0 1"/>
    <dynamics damping="0.1" friction="0.01"/>
  </joint>
  <link name="rear_left_roller7">
    <inertial>
      <origin rpy="0 0 0" xyz="5.89805981832114E-16 -8.25034485174569E-15 -0.0215899999999933"/>
      <mass value="0.025"/>
    </inertial>
    <visual>
      <origin rpy="0 0 0" xyz="0 0 0"/>
      <geometry>
        <mesh filename="package://linorobot2_description/mecanum_wheel_right/meshes/roller7.STL"/>
      </geometry>
      <material name="">
        <color rgba="0.752941176470588 0.752941176470588 0.752941176470588 1"/>
      </material>
    </visual>
    <collision>
      <origin rpy="0 0 0" xyz="0 0 0"/>
      <geometry>
        <mesh filename="package://linorobot2_description/mecanum_wheel_right/meshes/roller7.STL"/>
      </geometry>
    </collision>
  </link>
  <joint name="rear_left_wheel_to_rear_left_roller7" type="continuous">
    <origin rpy="-0.22003525595071 0.81173834281584 -2.17291203984087" xyz="-0.0676531438142786 -0.0151129693199092 -0.0058218992369328"/>
    <parent link="rear_left_wheel"/>
    <child link="rear_left_roller7"/>
    <axis xyz="0 0 1"/>
    <dynamics damping="0.1" friction="0.01"/>
  </joint>
  <link name="rear_left_roller8">
    <inertial>
      <origin rpy="0 0 0" xyz="5.759281940243E-16 2.22044604925031E-15 -0.0215899999999933"/>
      <mass value="0.025"/>
    </inertial>
    <visual>
      <origin rpy="0 0 0" xyz="0 0 0"/>
      <geometry>
        <mesh filename="package://linorobot2_description/mecanum_wheel_right/meshes/roller8.STL"/>
      </geometry>
      <material name="">
        <color rgba="0.752941176470588 0.752941176470588 0.752941176470588 1"/>
      </material>
    </visual>
    <collision>
      <origin rpy="0 0 0" xyz="0 0 0"/>
      <geometry>
        <mesh filename="package://linorobot2_description/mecanum_wheel_right/meshes/roller8.STL"/>
      </geometry>
    </collision>
  </link>
  <joint name="rear_left_wheel_to_rear_left_roller8" type="continuous">
    <origin rpy="0.408043134594723 0.963708851734786 -1.67797755478808" xyz="-0.0594362424748194 -0.0151129693199101 -0.0328355822112983"/>
    <parent link="rear_left_wheel"/>
    <child link="rear_left_roller8"/>
    <axis xyz="0 0 1"/>
    <dynamics damping="0.1" friction="0.01"/>
  </joint>
  <link name="rear_left_roller9">
    <inertial>
      <origin rpy="0 0 0" xyz="5.759281940243E-16 -2.60208521396521E-15 -0.0215899999999933"/>
      <mass value="0.025"/>
    </inertial>
    <visual>
      <origin rpy="0 0 0" xyz="0 0 0"/>
      <geometry>
        <mesh filename="package://linorobot2_description/mecanum_wheel_right/meshes/roller9.STL"/>
      </geometry>
      <material name="">
        <color rgba="0.752941176470588 0.752941176470588 0.752941176470588 1"/>
      </material>
    </visual>
    <collision>
      <origin rpy="0 0 0" xyz="0 0 0"/>
      <geometry>
        <mesh filename="package://linorobot2_description/mecanum_wheel_right/meshes/roller9.STL"/>
      </geometry>
    </collision>
  </link>
  <joint name="rear_left_wheel_to_rear_left_roller9" type="continuous">
    <origin rpy="1.1026415771303 0.886919106568413 -1.11464531078552" xyz="-0.0409422748501527 -0.015112969319909 -0.0541716947194296"/>
    <parent link="rear_left_wheel"/>
    <child link="rear_left_roller9"/>
    <axis xyz="0 0 1"/>
    <dynamics damping="0.1" friction="0.01"/>
  </joint>
  <link name="rear_left_roller10">
    <inertial>
      <origin rpy="0 0 0" xyz="5.89805981832114E-16 -3.42087469462626E-15 -0.0215899999999933"/>
      <mass value="0.025"/>
    </inertial>
    <visual>
      <origin rpy="0 0 0" xyz="0 0 0"/>
      <geometry>
        <mesh filename="package://linorobot2_description/mecanum_wheel_right/meshes/roller10.STL"/>
      </geometry>
      <material name="">
        <color rgba="0.752941176470588 0.752941176470588 0.752941176470588 1"/>
      </material>
    </visual>
    <collision>
      <origin rpy="0 0 0" xyz="0 0 0"/>
      <geometry>
        <mesh filename="package://linorobot2_description/mecanum_wheel_right/meshes/roller10.STL"/>
      </geometry>
    </collision>
  </link>
  <joint name="rear_left_wheel_to_rear_left_roller10" type="continuous">
    <origin rpy="1.57421323203544 0.637163580624169 -0.783361608443036" xyz="-0.0153690159550034 -0.0151129693199065 -0.0661410290761748"/>
    <parent link="rear_left_wheel"/>
    <child link="rear_left_roller10"/>
    <axis xyz="0 0 1"/>
    <dynamics damping="0.1" friction="0.01"/>
  </joint>
  <link name="rear_left_roller11">
    <inertial>
      <origin rpy="0 0 0" xyz="5.89805981832114E-16 -5.03069808033274E-15 -0.0215899999999933"/>
      <mass value="0.025"/>
    </inertial>
    <visual>
      <origin rpy="0 0 0" xyz="0 0 0"/>
      <geometry>
        <mesh filename="package://linorobot2_description/mecanum_wheel_right/meshes/roller11.STL"/>
      </geometry>
      <material name="">
        <color rgba="0.752941176470588 0.752941176470588 0.752941176470588 1"/>
      </material>
    </visual>
    <collision>
      <origin rpy="0 0 0" xyz="0 0 0"/>
      <geometry>
        <mesh filename="package://linorobot2_description/mecanum_wheel_right/meshes/roller11.STL"/>
      </geometry>
    </collision>
  </link>
  <joint name="rear_left_wheel_to_rear_left_roller11" type="continuous">
    <origin rpy="1.88109068595424 0.317129294370825 -0.639722033593165" xyz="0.0128616854218928 -0.0151129693199038 -0.0666739786332639"/>
    <parent link="rear_left_wheel"/>
    <child link="rear_left_roller11"/>
    <axis xyz="0 0 1"/>
    <dynamics damping="0.1" friction="0.01"/>
  </joint>
  <link name="rear_left_roller12">
    <inertial>
      <origin rpy="0 0 0" xyz="5.759281940243E-16 -3.44169137633799E-15 -0.0215899999999933"/>
      <mass value="0.025"/>
    </inertial>
    <visual>
      <origin rpy="0 0 0" xyz="0 0 0"/>
      <geometry>
        <mesh filename="package://linorobot2_description/mecanum_wheel_right/meshes/roller12.STL"/>
      </geometry>
      <material name="">
        <color rgba="0.752941176470588 0.752941176470588 0.752941176470588 1"/>
      </material>
    </visual>
    <collision>
      <origin rpy="0 0 0" xyz="0 0 0"/>
      <geometry>
        <mesh filename="package://linorobot2_description/mecanum_wheel_right/meshes/roller12.STL"/>
      </geometry>
    </collision>
  </link>
  <joint name="rear_left_wheel_to_rear_left_roller12" type="continuous">
    <origin rpy="2.12643201705665 -0.025160050703084 -0.60332516970669" xyz="0.0388684845445997 -0.0151129693199006 -0.0556783915705813"/>
    <parent link="rear_left_wheel"/>
    <child link="rear_left_roller12"/>
    <axis xyz="0 0 1"/>
    <dynamics damping="0.1" friction="0.01"/>
  </joint>
  <link name="rear_left_roller13">
    <inertial>
      <origin rpy="0 0 0" xyz="5.89805981832114E-16 -3.36536354339501E-15 -0.0215899999999933"/>
      <mass value="0.025"/>
    </inertial>
    <visual>
      <origin rpy="0 0 0" xyz="0 0 0"/>
      <geometry>
        <mesh filename="package://linorobot2_description/mecanum_wheel_right/meshes/roller13.STL"/>
      </geometry>
      <material name="">
        <color rgba="0.752941176470588 0.752941176470588 0.752941176470588 1"/>
      </material>
    </visual>
    <collision>
      <origin rpy="0 0 0" xyz="0 0 0"/>
      <geometry>
        <mesh filename="package://linorobot2_description/mecanum_wheel_right/meshes/roller13.STL"/>
      </geometry>
    </collision>
  </link>
  <joint name="rear_left_wheel_to_rear_left_roller13" type="continuous">
    <origin rpy="2.37615666037905 -0.365916365141497 -0.652805521545524" xyz="0.0581545695804492 -0.0151129693198971 -0.0350555047830372"/>
    <parent link="rear_left_wheel"/>
    <child link="rear_left_roller13"/>
    <axis xyz="0 0 1"/>
    <dynamics damping="0.1" friction="0.01"/>
  </joint>
  <link name="rear_left_roller14">
    <inertial>
      <origin rpy="0 0 0" xyz="5.82867087928207E-16 -2.38697950294409E-15 -0.0215899999999933"/>
      <mass value="0.025"/>
    </inertial>
    <visual>
      <origin rpy="0 0 0" xyz="0 0 0"/>
      <geometry>
        <mesh filename="package://linorobot2_description/mecanum_wheel_right/meshes/roller14.STL"/>
      </geometry>
      <material name="">
        <color rgba="0.752941176470588 0.752941176470588 0.752941176470588 1"/>
      </material>
    </visual>
    <collision>
      <origin rpy="0 0 0" xyz="0 0 0"/>
      <geometry>
        <mesh filename="package://linorobot2_description/mecanum_wheel_right/meshes/roller14.STL"/>
      </geometry>
    </collision>
  </link>
  <joint name="rear_left_wheel_to_rear_left_roller14" type="continuous">
    <origin rpy="2.69941973817462 -0.67973266586857 -0.817294146739146" xyz="0.0673852012181607 -0.0151129693198943 -0.00837120274924246"/>
    <parent link="rear_left_wheel"/>
    <child link="rear_left_roller14"/>
    <axis xyz="0 0 1"/>
    <dynamics damping="0.1" friction="0.01"/>
  </joint>
  <link name="rear_left_roller15">
    <inertial>
      <origin rpy="0 0 0" xyz="5.759281940243E-16 -6.50868248186498E-15 -0.0215899999999933"/>
      <mass value="0.025"/>
    </inertial>
    <visual>
      <origin rpy="0 0 0" xyz="0 0 0"/>
      <geometry>
        <mesh filename="package://linorobot2_description/mecanum_wheel_right/meshes/roller15.STL"/>
      </geometry>
      <material name="">
        <color rgba="0.752941176470588 0.752941176470588 0.752941176470588 1"/>
      </material>
    </visual>
    <collision>
      <origin rpy="0 0 0" xyz="0 0 0"/>
      <geometry>
        <mesh filename="package://linorobot2_description/mecanum_wheel_right/meshes/roller15.STL"/>
      </geometry>
    </collision>
  </link>
  <joint name="rear_left_wheel_to_rear_left_roller15" type="continuous">
    <origin rpy="-3.077965161563 -0.911914057233449 -1.18487158274901" xyz="0.0649643193899178 -0.0151129693198934 0.0197605562898849"/>
    <parent link="rear_left_wheel"/>
    <child link="rear_left_roller15"/>
    <axis xyz="0 0 1"/>
    <dynamics damping="0.1" friction="0.01"/>
  </joint>
  <link name="rear_right_wheel">
    <inertial>
      <origin rpy="0 0 0" xyz="-3.9077136779291E-16 -0.0136205707454137 -1.44489682185117E-14"/>
      <mass value="0.25"/>
    </inertial>
    <visual>
      <origin rpy="0 0 0" xyz="0 0 0"/>
      <geometry>
        <mesh filename="package://linorobot2_description/mecanum_wheel_left/meshes/base_link.STL"/>
      </geometry>
      <material name="">
        <color rgba="0.898039215686275 0.917647058823529 0.929411764705882 1"/>
      </material>
    </visual>
    <collision>
      <origin rpy="0 0 0" xyz="0 0 0"/>
      <geometry>
        <mesh filename="package://linorobot2_description/mecanum_wheel_left/meshes/base_link.STL"/>
      </geometry>
    </collision>
  </link>
  <joint name="base_link_to_rear_right_wheel" type="continuous">
    <origin rpy="0 0 0" xyz="-0.25857 -0.19355 0"/>
    <parent link="base_link"/>
    <child link="rear_right_wheel"/>
    <axis xyz="0 1 0"/>
    <dynamics damping="0.1" friction="0.01"/>
  </joint>
  <link name="rear_right_plate1">
    <inertial>
      <mass value="0.5"/>
    </inertial>
    <visual>
      <origin rpy="0 0 0" xyz="0 0 0"/>
      <geometry>
        <mesh filename="package://linorobot2_description/mecanum_wheel_left/meshes/plate1.STL"/>
      </geometry>
      <material name="">
        <color rgba="0.650980392156863 0.619607843137255 0.588235294117647 1"/>
      </material>
    </visual>
    <collision>
      <origin rpy="0 0 0" xyz="0 0 0"/>
      <geometry>
        <mesh filename="package://linorobot2_description/mecanum_wheel_left/meshes/plate1.STL"/>
      </geometry>
    </collision>
  </link>
  <joint name="rear_right_wheel_to_rear_right_plate1" type="fixed">
    <origin rpy="-1.5708 0.03287 0" xyz="0 0.023114 0"/>
    <parent link="rear_right_wheel"/>
    <child link="rear_right_plate1"/>
    <axis xyz="0 0 0"/>
  </joint>
  <link name="rear_right_plate2">
    <inertial>
      <mass value="0.5"/>
    </inertial>
    <visual>
      <origin rpy="0 0 0" xyz="0 0 0"/>
      <geometry>
        <mesh filename="package://linorobot2_description/mecanum_wheel_left/meshes/plate2.STL"/>
      </geometry>
      <material name="">
        <color rgba="0.650980392156863 0.619607843137255 0.588235294117647 1"/>
      </material>
    </visual>
    <collision>
      <origin rpy="0 0 0" xyz="0 0 0"/>
      <geometry>
        <mesh filename="package://linorobot2_description/mecanum_wheel_left/meshes/plate2.STL"/>
      </geometry>
    </collision>
  </link>
  <joint name="rear_right_wheel_to_rear_right_plate2" type="fixed">
    <origin rpy="-1.5707963267949 0.0335546833724646 -3.14159265358979" xyz="0 -0.023114 0"/>
    <parent link="rear_right_wheel"/>
    <child link="rear_right_plate2"/>
    <axis xyz="0 0 0"/>
  </joint>
  <link name="rear_right_roller1">
    <inertial>
      <origin rpy="0 0 0" xyz="5.96744875736022E-16 -1.24475083018716E-14 -0.0215899999999933"/>
      <mass value="0.025"/>
    </inertial>
    <visual>
      <origin rpy="0 0 0" xyz="0 0 0"/>
      <geometry>
        <mesh filename="package://linorobot2_description/mecanum_wheel_left/meshes/roller1.STL"/>
      </geometry>
      <material name="">
        <color rgba="0.752941176470588 0.752941176470588 0.752941176470588 1"/>
      </material>
    </visual>
    <collision>
      <origin rpy="0 0 0" xyz="0 0 0"/>
      <geometry>
        <mesh filename="package://linorobot2_description/mecanum_wheel_left/meshes/roller1.STL"/>
      </geometry>
    </collision>
  </link>
  <joint name="rear_right_wheel_to_rear_right_roller1" type="continuous">
    <origin rpy="2.3375 0.48899 -0.038445" xyz="-0.064997 -0.01515 0.019737"/>
    <parent link="rear_right_wheel"/>
    <child link="rear_right_roller1"/>
    <axis xyz="0 0 1"/>
    <dynamics damping="0.1" friction="0.01"/>
  </joint>
  <link name="rear_right_roller2">
    <inertial>
      <origin rpy="0 0 0" xyz="5.82867087928207E-16 -9.95687907123788E-15 -0.0215899999999933"/>
      <mass value="0.025"/>
    </inertial>
    <visual>
      <origin rpy="0 0 0" xyz="0 0 0"/>
      <geometry>
        <mesh filename="package://linorobot2_description/mecanum_wheel_left/meshes/roller2.STL"/>
      </geometry>
      <material name="">
        <color rgba="0.752941176470588 0.752941176470588 0.752941176470588 1"/>
      </material>
    </visual>
    <collision>
      <origin rpy="0 0 0" xyz="0 0 0"/>
      <geometry>
        <mesh filename="package://linorobot2_description/mecanum_wheel_left/meshes/roller2.STL"/>
      </geometry>
    </collision>
  </link>
  <joint name="rear_right_wheel_to_rear_right_roller2" type="continuous">
    <origin rpy="2.3122 0.90744 -0.055132" xyz="-0.05135 -0.01515 0.044467"/>
    <parent link="rear_right_wheel"/>
    <child link="rear_right_roller2"/>
    <axis xyz="0 0 1"/>
    <dynamics damping="0.1" friction="0.01"/>
  </joint>
  <link name="rear_right_roller3">
    <inertial>
      <origin rpy="0 0 0" xyz="5.82867087928207E-16 -3.41003267290141E-15 -0.0215899999999933"/>
      <mass value="0.025"/>
    </inertial>
    <visual>
      <origin rpy="0 0 0" xyz="0 0 0"/>
      <geometry>
        <mesh filename="package://linorobot2_description/mecanum_wheel_left/meshes/roller3.STL"/>
      </geometry>
      <material name="">
        <color rgba="0.752941176470588 0.752941176470588 0.752941176470588 1"/>
      </material>
    </visual>
    <collision>
      <origin rpy="0 0 0" xyz="0 0 0"/>
      <geometry>
        <mesh filename="package://linorobot2_description/mecanum_wheel_left/meshes/roller3.STL"/>
      </geometry>
    </collision>
  </link>
  <joint name="rear_right_wheel_to_rear_right_roller3" type="continuous">
    <origin rpy="2.22 1.3248 -0.13976" xyz="-0.028824 -0.01515 0.061508"/>
    <parent link="rear_right_wheel"/>
    <child link="rear_right_roller3"/>
    <axis xyz="0 0 1"/>
    <dynamics damping="0.1" friction="0.01"/>
  </joint>
  <link name="rear_right_roller4">
    <inertial>
      <origin rpy="0 0 0" xyz="5.68989300120393E-16 -3.35365415993216E-15 -0.0215899999999933"/>
      <mass value="0.025"/>
    </inertial>
    <visual>
      <origin rpy="0 0 0" xyz="0 0 0"/>
      <geometry>
        <mesh filename="package://linorobot2_description/mecanum_wheel_left/meshes/roller4.STL"/>
      </geometry>
      <material name="">
        <color rgba="0.752941176470588 0.752941176470588 0.752941176470588 1"/>
      </material>
    </visual>
    <collision>
      <origin rpy="0 0 0" xyz="0 0 0"/>
      <geometry>
        <mesh filename="package://linorobot2_description/mecanum_wheel_left/meshes/roller4.STL"/>
      </geometry>
    </collision>
  </link>
  <joint name="rear_right_wheel_to_rear_right_roller4" type="continuous">
    <origin rpy="-0.59653 1.3924 -2.9492" xyz="-0.0013143 -0.01515 0.067914"/>
    <parent link="rear_right_wheel"/>
    <child link="rear_right_roller4"/>
    <axis xyz="0 0 1"/>
    <dynamics damping="0.1" friction="0.01"/>
  </joint>
  <link name="rear_right_roller5">
    <inertial>
      <origin rpy="0 0 0" xyz="5.96744875736022E-16 2.4459601011273E-15 -0.0215899999999933"/>
      <mass value="0.025"/>
    </inertial>
    <visual>
      <origin rpy="0 0 0" xyz="0 0 0"/>
      <geometry>
        <mesh filename="package://linorobot2_description/mecanum_wheel_left/meshes/roller5.STL"/>
      </geometry>
      <material name="">
        <color rgba="0.752941176470588 0.752941176470588 0.752941176470588 1"/>
      </material>
    </visual>
    <collision>
      <origin rpy="0 0 0" xyz="0 0 0"/>
      <geometry>
        <mesh filename="package://linorobot2_description/mecanum_wheel_left/meshes/roller5.STL"/>
      </geometry>
    </collision>
  </link>
  <joint name="rear_right_wheel_to_rear_right_roller5" type="continuous">
    <origin rpy="-0.73578 0.97593 -3.081" xyz="0.026423 -0.01515 0.062578"/>
    <parent link="rear_right_wheel"/>
    <child link="rear_right_roller5"/>
    <axis xyz="0 0 1"/>
    <dynamics damping="0.1" friction="0.01"/>
  </joint>
  <link name="rear_right_roller6">
    <inertial>
      <origin rpy="0 0 0" xyz="5.82867087928207E-16 -7.52392939618041E-15 -0.0215899999999933"/>
      <mass value="0.025"/>
    </inertial>
    <visual>
      <origin rpy="0 0 0" xyz="0 0 0"/>
      <geometry>
        <mesh filename="package://linorobot2_description/mecanum_wheel_left/meshes/roller6.STL"/>
      </geometry>
      <material name="">
        <color rgba="0.752941176470588 0.752941176470588 0.752941176470588 1"/>
      </material>
    </visual>
    <collision>
      <origin rpy="0 0 0" xyz="0 0 0"/>
      <geometry>
        <mesh filename="package://linorobot2_description/mecanum_wheel_left/meshes/roller6.STL"/>
      </geometry>
    </collision>
  </link>
  <joint name="rear_right_wheel_to_rear_right_roller6" type="continuous">
    <origin rpy="-0.76481 0.55754 -3.1016" xyz="0.049591 -0.01515 0.04642"/>
    <parent link="rear_right_wheel"/>
    <child link="rear_right_roller6"/>
    <axis xyz="0 0 1"/>
    <dynamics damping="0.1" friction="0.01"/>
  </joint>
  <link name="rear_right_roller7">
    <inertial>
      <origin rpy="0 0 0" xyz="5.82867087928207E-16 -3.4109000346394E-15 -0.0215899999999933"/>
      <mass value="0.025"/>
    </inertial>
    <visual>
      <origin rpy="0 0 0" xyz="0 0 0"/>
      <geometry>
        <mesh filename="package://linorobot2_description/mecanum_wheel_left/meshes/roller7.STL"/>
      </geometry>
      <material name="">
        <color rgba="0.752941176470588 0.752941176470588 0.752941176470588 1"/>
      </material>
    </visual>
    <collision>
      <origin rpy="0 0 0" xyz="0 0 0"/>
      <geometry>
        <mesh filename="package://linorobot2_description/mecanum_wheel_left/meshes/roller7.STL"/>
      </geometry>
    </collision>
  </link>
  <joint name="rear_right_wheel_to_rear_right_roller7" type="continuous">
    <origin rpy="-0.78123 0.13894 -3.1073" xyz="0.064184 -0.01515 0.022237"/>
    <parent link="rear_right_wheel"/>
    <child link="rear_right_roller7"/>
    <axis xyz="0 0 1"/>
    <dynamics damping="0.1" friction="0.01"/>
  </joint>
  <link name="rear_right_roller8">
    <inertial>
      <origin rpy="0 0 0" xyz="5.82867087928207E-16 -1.76421377506841E-15 -0.0215899999999933"/>
      <mass value="0.025"/>
    </inertial>
    <visual>
      <origin rpy="0 0 0" xyz="0 0 0"/>
      <geometry>
        <mesh filename="package://linorobot2_description/mecanum_wheel_left/meshes/roller8.STL"/>
      </geometry>
      <material name="">
        <color rgba="0.752941176470588 0.752941176470588 0.752941176470588 1"/>
      </material>
    </visual>
    <collision>
      <origin rpy="0 0 0" xyz="0 0 0"/>
      <geometry>
        <mesh filename="package://linorobot2_description/mecanum_wheel_left/meshes/roller8.STL"/>
      </geometry>
    </collision>
  </link>
  <joint name="rear_right_wheel_to_rear_right_roller8" type="continuous">
    <origin rpy="-0.79573 -0.27969 -3.1063" xyz="0.06768 -0.01515 -0.0057919"/>
    <parent link="rear_right_wheel"/>
    <child link="rear_right_roller8"/>
    <axis xyz="0 0 1"/>
    <dynamics damping="0.1" friction="0.01"/>
  </joint>
  <link name="rear_right_roller9">
    <inertial>
      <origin rpy="0 0 0" xyz="5.82867087928207E-16 -5.1013880619788E-15 -0.0215899999999933"/>
      <mass value="0.025"/>
    </inertial>
    <visual>
      <origin rpy="0 0 0" xyz="0 0 0"/>
      <geometry>
        <mesh filename="package://linorobot2_description/mecanum_wheel_left/meshes/roller9.STL"/>
      </geometry>
      <material name="">
        <color rgba="0.752941176470588 0.752941176470588 0.752941176470588 1"/>
      </material>
    </visual>
    <collision>
      <origin rpy="0 0 0" xyz="0 0 0"/>
      <geometry>
        <mesh filename="package://linorobot2_description/mecanum_wheel_left/meshes/roller9.STL"/>
      </geometry>
    </collision>
  </link>
  <joint name="rear_right_wheel_to_rear_right_roller9" type="continuous">
    <origin rpy="-0.81448 -0.69826 -3.0973" xyz="0.059473 -0.01515 -0.032819"/>
    <parent link="rear_right_wheel"/>
    <child link="rear_right_roller9"/>
    <axis xyz="0 0 1"/>
    <dynamics damping="0.1" friction="0.01"/>
  </joint>
  <link name="rear_right_roller10">
    <inertial>
      <origin rpy="0 0 0" xyz="5.96744875736022E-16 -6.51952450358984E-15 -0.0215899999999933"/>
      <mass value="0.025"/>
    </inertial>
    <visual>
      <origin rpy="0 0 0" xyz="0 0 0"/>
      <geometry>
        <mesh filename="package://linorobot2_description/mecanum_wheel_left/meshes/roller10.STL"/>
      </geometry>
      <material name="">
        <color rgba="0.752941176470588 0.752941176470588 0.752941176470588 1"/>
      </material>
    </visual>
    <collision>
      <origin rpy="0 0 0" xyz="0 0 0"/>
      <geometry>
        <mesh filename="package://linorobot2_description/mecanum_wheel_left/meshes/roller10.STL"/>
      </geometry>
    </collision>
  </link>
  <joint name="rear_right_wheel_to_rear_right_roller10" type="continuous">
    <origin rpy="-0.85554 -1.1164 -3.0642" xyz="0.040982 -0.01515 -0.054171"/>
    <parent link="rear_right_wheel"/>
    <child link="rear_right_roller10"/>
    <axis xyz="0 0 1"/>
    <dynamics damping="0.1" friction="0.01"/>
  </joint>
  <link name="rear_right_roller11">
    <inertial>
      <origin rpy="0 0 0" xyz="5.68989300120393E-16 -3.40699690681845E-15 -0.0215899999999933"/>
      <mass value="0.025"/>
    </inertial>
    <visual>
      <origin rpy="0 0 0" xyz="0 0 0"/>
      <geometry>
        <mesh filename="package://linorobot2_description/mecanum_wheel_left/meshes/roller11.STL"/>
      </geometry>
      <material name="">
        <color rgba="0.752941176470588 0.752941176470588 0.752941176470588 1"/>
      </material>
    </visual>
    <collision>
      <origin rpy="0 0 0" xyz="0 0 0"/>
      <geometry>
        <mesh filename="package://linorobot2_description/mecanum_wheel_left/meshes/roller11.STL"/>
      </geometry>
    </collision>
  </link>
  <joint name="rear_right_wheel_to_rear_right_roller11" type="continuous">
    <origin rpy="-1.5658 -1.5225 -2.3612" xyz="0.015406 -0.01515 -0.066157"/>
    <parent link="rear_right_wheel"/>
    <child link="rear_right_roller11"/>
    <axis xyz="0 0 1"/>
    <dynamics damping="0.1" friction="0.01"/>
  </joint>
  <link name="rear_right_roller12">
    <inertial>
      <origin rpy="0 0 0" xyz="5.96744875736022E-16 -9.87751547221194E-15 -0.0215899999999933"/>
      <mass value="0.025"/>
    </inertial>
    <visual>
      <origin rpy="0 0 0" xyz="0 0 0"/>
      <geometry>
        <mesh filename="package://linorobot2_description/mecanum_wheel_left/meshes/roller12.STL"/>
      </geometry>
      <material name="">
        <color rgba="0.752941176470588 0.752941176470588 0.752941176470588 1"/>
      </material>
    </visual>
    <collision>
      <origin rpy="0 0 0" xyz="0 0 0"/>
      <geometry>
        <mesh filename="package://linorobot2_description/mecanum_wheel_left/meshes/roller12.STL"/>
      </geometry>
    </collision>
  </link>
  <joint name="rear_right_wheel_to_rear_right_roller12" type="continuous">
    <origin rpy="2.4393 -1.1848 -0.090248" xyz="-0.012835 -0.01515 -0.066704"/>
    <parent link="rear_right_wheel"/>
    <child link="rear_right_roller12"/>
    <axis xyz="0 0 1"/>
    <dynamics damping="0.1" friction="0.01"/>
  </joint>
  <link name="rear_right_roller13">
    <inertial>
      <origin rpy="0 0 0" xyz="6.10622663543836E-16 -6.50608039665102E-15 -0.0215899999999933"/>
      <mass value="0.025"/>
    </inertial>
    <visual>
      <origin rpy="0 0 0" xyz="0 0 0"/>
      <geometry>
        <mesh filename="package://linorobot2_description/mecanum_wheel_left/meshes/roller13.STL"/>
      </geometry>
      <material name="">
        <color rgba="0.752941176470588 0.752941176470588 0.752941176470588 1"/>
      </material>
    </visual>
    <collision>
      <origin rpy="0 0 0" xyz="0 0 0"/>
      <geometry>
        <mesh filename="package://linorobot2_description/mecanum_wheel_left/meshes/roller13.STL"/>
      </geometry>
    </collision>
  </link>
  <joint name="rear_right_wheel_to_rear_right_roller13" type="continuous">
    <origin rpy="2.3883 -0.76678 -0.047134" xyz="-0.038856 -0.01515 -0.055716"/>
    <parent link="rear_right_wheel"/>
    <child link="rear_right_roller13"/>
    <axis xyz="0 0 1"/>
    <dynamics damping="0.1" friction="0.01"/>
  </joint>
  <link name="rear_right_roller14">
    <inertial>
      <origin rpy="0 0 0" xyz="5.96744875736022E-16 -3.365797224264E-15 -0.0215899999999933"/>
      <mass value="0.025"/>
    </inertial>
    <visual>
      <origin rpy="0 0 0" xyz="0 0 0"/>
      <geometry>
        <mesh filename="package://linorobot2_description/mecanum_wheel_left/meshes/roller14.STL"/>
      </geometry>
      <material name="">
        <color rgba="0.752941176470588 0.752941176470588 0.752941176470588 1"/>
      </material>
    </visual>
    <collision>
      <origin rpy="0 0 0" xyz="0 0 0"/>
      <geometry>
        <mesh filename="package://linorobot2_description/mecanum_wheel_left/meshes/roller14.STL"/>
      </geometry>
    </collision>
  </link>
  <joint name="rear_right_wheel_to_rear_right_roller14" type="continuous">
    <origin rpy="2.3679 -0.34825 -0.036106" xyz="-0.058159 -0.01515 -0.035095"/>
    <parent link="rear_right_wheel"/>
    <child link="rear_right_roller14"/>
    <axis xyz="0 0 1"/>
    <dynamics damping="0.1" friction="0.01"/>
  </joint>
  <link name="rear_right_roller15">
    <inertial>
      <origin rpy="0 0 0" xyz="5.82867087928207E-16 -3.35452152167015E-15 -0.0215899999999933"/>
      <mass value="0.025"/>
    </inertial>
    <visual>
      <origin rpy="0 0 0" xyz="0 0 0"/>
      <geometry>
        <mesh filename="package://linorobot2_description/mecanum_wheel_left/meshes/roller15.STL"/>
      </geometry>
      <material name="">
        <color rgba="0.752941176470588 0.752941176470588 0.752941176470588 1"/>
      </material>
    </visual>
    <collision>
      <origin rpy="0 0 0" xyz="0 0 0"/>
      <geometry>
        <mesh filename="package://linorobot2_description/mecanum_wheel_left/meshes/roller15.STL"/>
      </geometry>
    </collision>
  </link>
  <joint name="rear_right_wheel_to_rear_right_roller15" type="continuous">
    <origin rpy="2.35322166168045 0.070379538766794 -0.0340216727613588" xyz="-0.0674050504299177 -0.0151497403158722 -0.00840608812639412"/>
    <parent link="rear_right_wheel"/>
    <child link="rear_right_roller15"/>
    <axis xyz="0 0 1"/>
    <dynamics damping="0.1" friction="0.01"/>
  </joint>

  <link name="front_rs_depth_optical_frame">
    <inertial>
      <mass value="0.025" />
    </inertial>
    <visual>
      <origin
        xyz="0 0 0"
        rpy="0 0 0" />
    </visual>
    <collision>
      <origin
        xyz="0 0 0"
        rpy="0 0 0" />
    </collision>
  </link>

  <!-- IsaacSim will likely not respect joint angles for realsense joints -->
  <joint
    name="base_link_to_front_rs" type="fixed">
    <origin
      xyz="0.410335 0 0.0892"
      rpy="-1.57 1.57 0" />
    <parent link="base_link" />
    <child link="front_rs_depth_optical_frame" />
  </joint>


  <link name="rear_rs_depth_optical_frame">
    <inertial>
      <mass value="0.025" />
    </inertial>
    <visual>
      <origin
        xyz="0 0 0"
        rpy="0 0 0" />
    </visual>
    <collision>
      <origin
        xyz="0 0 0"
        rpy="0 0 0" />
    </collision>
  </link>

  <!-- IsaacSim will likely not respect joint angles for realsense joints -->
  <joint
    name="base_link_to_rear_rs" type="fixed">
    <origin
      xyz="-0.41 0 0.089"
      rpy="-1.57 -1.57 0" />
    <parent link="base_link" />
    <child link="rear_rs_depth_optical_frame" />
  </joint>


  <link name="left_rs_depth_optical_frame">
    <inertial>
      <mass value="0.025" />
    </inertial>
    <visual>
      <origin
        xyz="0 0 0"
        rpy="0 0 0" />
    </visual>
    <collision>
      <origin
        xyz="0 0 0"
        rpy="0 0 0" />
    </collision>
  </link>

  <!-- IsaacSim will likely not respect joint angles for realsense joints -->
  <joint
    name="base_link_to_left_rs" type="fixed">
    <origin
      xyz="0 0.247 0.089"
      rpy="-1.57 0 0" />
    <parent link="base_link" />
    <child link="left_rs_depth_optical_frame" />
  </joint>


  <link name="right_rs_depth_optical_frame">
    <inertial>
      <mass value="0.025" />
    </inertial>
    <visual>
      <origin
        xyz="0 0 0"
        rpy="0 0 0" />
    </visual>
    <collision>
      <origin
        xyz="0 0 0"
        rpy="0 0 0" />
    </collision>
  </link>

  <!-- IsaacSim will likely not respect joint angles for realsense joints -->
  <joint
    name="base_link_to_right_rs" type="fixed">
    <origin
      xyz="0 -0.247 0.089"
      rpy="1.57 0 3.14" />
    <parent link="base_link" />
    <child link="right_rs_depth_optical_frame" />
  </joint>


</robot>
