<?xml version="1.0" ?>
<!-- =================================================================================== -->
<!-- |    This document was autogenerated by xacro from mecanum.urdf.xacro             | -->
<!-- |    EDITING THIS FILE BY HAND IS NOT RECOMMENDED                                 | -->
<!-- =================================================================================== -->
<robot name="linorobot2_2wd">
  <link name="base_footprint"/>
  <link name="base_link">
    <visual>
      <origin rpy="0 0 0" xyz="0 0 0"/>
      <geometry>
        <box size="0.82067 0.3175 0.07772"/>
        <!-- <mesh filename="" scale="0.001 0.001 0.001"/> -->
      </geometry>
      <material name="gray_base">
        <color rgba="0.8 0.8 0.83 1.0"/>
      </material>
    </visual>
    <collision>
      <origin rpy="0 0 0" xyz="0 0 0"/>
      <geometry>
        <box size="0.82067 0.3175 0.07772"/>
      </geometry>
    </collision>
    <inertial>
      <origin rpy="0 0 0" xyz="0 0 0"/>
      <mass value="30"/>
      <inertia ixx="0.267116621" ixy="0.0" ixz="0.0" iyy="1.69884911825" iyz="0.0" izz="1.93576374725"/>
    </inertial>
  </link>
  <gazebo reference="base_link">
    <visual>
      <material>
        <ambient>0.8392 0.6314 0.0 1.0</ambient>
        <diffuse>0.8392 0.6314 0.0 1.0</diffuse>
        <specular>0.99 0.99 0.99 1.0</specular>
        <emissive>0.0 0.0 0.0 0.0</emissive>
      </material>
    </visual>
  </gazebo>
  <joint name="base_to_footprint" type="fixed">
    <parent link="base_footprint"/>
    <child link="base_link"/>
    <origin rpy="0 0 0" xyz="0 0 0.06972"/>
  </joint>
  <link name="front_channel">
    <visual>
      <geometry>
        <box size="0.05398 0.4953 0.08458"/>
        <!-- Box dimensions (x, y, z) -->
      </geometry>
      <material name="gray">
        <color rgba="0.70 0.70 0.73 1.0"/>
        <!-- Blue color -->
      </material>
    </visual>
    <collision>
      <geometry>
        <box size="0.05398 0.4953 0.08458"/>
        <!-- Box dimensions (x, y, z) -->
      </geometry>
    </collision>
  </link>
  <joint name="base_link_to_front_channel" type="fixed">
    <parent link="base_link"/>
    <child link="front_channel"/>
    <origin rpy="0 0 0" xyz="0.383345 0 0"/>
  </joint>
  <link name="back_channel">
    <visual>
      <geometry>
        <box size="0.05398 0.4953 0.08458"/>
        <!-- Box dimensions (x, y, z) -->
      </geometry>
      <material name="gray">
        <color rgba="0.70 0.70 0.73 1.0"/>
        <!-- Blue color -->
      </material>
    </visual>
    <collision>
      <geometry>
        <box size="0.05398 0.4953 0.08458"/>
        <!-- Box dimensions (x, y, z) -->
      </geometry>
    </collision>
  </link>
  <joint name="base_link_to_back_channel" type="fixed">
    <parent link="base_link"/>
    <child link="back_channel"/>
    <origin rpy="0 0 0" xyz="-0.383345 0 0"/>
  </joint>
  <link name="left_channel">
    <visual>
      <geometry>
        <box size="0.82067 0.02224 0.07772"/>
      </geometry>
      <material name="gray">
        <color rgba="0.70 0.70 0.73 1.0"/>
      </material>
    </visual>
    <collision>
      <geometry>
        <box size="0.82067 0.02224 0.07772"/>
      </geometry>
    </collision>
  </link>
  <joint name="base_link_to_left_channel" type="fixed">
    <parent link="base_link"/>
    <child link="left_channel"/>
    <origin rpy="0 0 0" xyz="0 0.23653 0"/>
  </joint>
  <link name="right_channel">
    <visual>
      <geometry>
        <box size="0.82067 0.02224 0.07772"/>
      </geometry>
      <material name="gray">
        <color rgba="0.70 0.70 0.73 1.0"/>
      </material>
    </visual>
    <collision>
      <geometry>
        <box size="0.82067 0.02224 0.07772"/>
      </geometry>
    </collision>
  </link>
  <joint name="base_link_to_right_channel" type="fixed">
    <parent link="base_link"/>
    <child link="right_channel"/>
    <origin rpy="0 0 0" xyz="0 -0.23653 0"/>
  </joint>
  <link name="front_left_base_link">
    <inertial>
      <origin rpy="0 0 0" xyz="-3.9077136779291E-16 -0.0136205707454137 -1.44489682185117E-14"/>
      <mass value="0.039620820516108"/>
      <inertia ixx="3.76577202480009E-05" ixy="-1.07908308681007E-19" ixz="3.89356499633093E-22" iyy="7.10123305553507E-05" iyz="-1.66085499471637E-18" izz="3.76577202480009E-05"/>
    </inertial>
    <visual>
      <origin rpy="0 0 0" xyz="0 0 0"/>
      <geometry>
        <mesh filename="package://linorobot2_description/mecanum_wheel_left/meshes/base_link.STL"/>
      </geometry>
      <material name="">
        <color rgba="0.898039215686275 0.917647058823529 0.929411764705882 1"/>
      </material>
    </visual>
    <collision>
      <origin rpy="0 0 0" xyz="0 0 0"/>
      <geometry>
        <mesh filename="package://linorobot2_description/mecanum_wheel_left/meshes/base_link.STL"/>
      </geometry>
    </collision>
  </link>
  <joint name="base_link_to_front_left_base_link" type="continuous">
    <origin rpy="0 0 0" xyz="0.25857 0.19355 0"/>
    <parent link="base_link"/>
    <child link="front_left_base_link"/>
    <axis xyz="0 1 0"/>
  </joint>
  <link name="front_left_plate1">
    <inertial>
      <origin rpy="0 0 0" xyz="8.83119736279022E-16 3.33301269118141E-17 -0.000551568670724527"/>
      <mass value="0.0253986639693882"/>
      <inertia ixx="4.21627753206923E-05" ixy="1.3976043629696E-20" ixz="-2.39458839321443E-21" iyy="4.21627753206922E-05" iyz="4.06169630282727E-21" izz="8.39719993847474E-05"/>
    </inertial>
    <visual>
      <origin rpy="0 0 0" xyz="0 0 0"/>
      <geometry>
        <mesh filename="package://linorobot2_description/mecanum_wheel_left/meshes/plate1.STL"/>
      </geometry>
      <material name="">
        <color rgba="0.650980392156863 0.619607843137255 0.588235294117647 1"/>
      </material>
    </visual>
    <collision>
      <origin rpy="0 0 0" xyz="0 0 0"/>
      <geometry>
        <mesh filename="package://linorobot2_description/mecanum_wheel_left/meshes/plate1.STL"/>
      </geometry>
    </collision>
  </link>
  <joint name="front_left_base_link_to_front_left_plate1" type="fixed">
    <origin rpy="-1.5708 0.03287 0" xyz="0 0.023114 0"/>
    <parent link="front_left_base_link"/>
    <child link="front_left_plate1"/>
    <axis xyz="0 0 0"/>
  </joint>
  <link name="front_left_plate2">
    <inertial>
      <origin rpy="0 0 0" xyz="-1.10651810076925E-15 8.09386876632109E-17 -0.000551568670724527"/>
      <mass value="0.0253986639693882"/>
      <inertia ixx="4.21627753206924E-05" ixy="1.65171424714589E-20" ixz="4.28643950323039E-22" iyy="4.21627753206923E-05" iyz="2.75305456980319E-21" izz="8.39719993847476E-05"/>
    </inertial>
    <visual>
      <origin rpy="0 0 0" xyz="0 0 0"/>
      <geometry>
        <mesh filename="package://linorobot2_description/mecanum_wheel_left/meshes/plate2.STL"/>
      </geometry>
      <material name="">
        <color rgba="0.650980392156863 0.619607843137255 0.588235294117647 1"/>
      </material>
    </visual>
    <collision>
      <origin rpy="0 0 0" xyz="0 0 0"/>
      <geometry>
        <mesh filename="package://linorobot2_description/mecanum_wheel_left/meshes/plate2.STL"/>
      </geometry>
    </collision>
  </link>
  <joint name="front_left_base_link_to_front_left_plate2" type="fixed">
    <origin rpy="-1.5707963267949 0.0335546833724646 -3.14159265358979" xyz="0 -0.023114 0"/>
    <parent link="front_left_base_link"/>
    <child link="front_left_plate2"/>
    <axis xyz="0 0 0"/>
  </joint>
  <link name="front_left_roller1">
    <inertial>
      <origin rpy="0 0 0" xyz="5.96744875736022E-16 -1.24475083018716E-14 -0.0215899999999933"/>
      <mass value="0.00499543658848208"/>
      <inertia ixx="8.99919949242919E-07" ixy="3.97046694025453E-23" ixz="9.81863387100444E-22" iyy="8.9991994924288E-07" iyz="-8.0163727523739E-19" izz="3.31951561004127E-07"/>
    </inertial>
    <visual>
      <origin rpy="0 0 0" xyz="0 0 0"/>
      <geometry>
        <mesh filename="package://linorobot2_description/mecanum_wheel_left/meshes/roller1.STL"/>
      </geometry>
      <material name="">
        <color rgba="0.752941176470588 0.752941176470588 0.752941176470588 1"/>
      </material>
    </visual>
    <collision>
      <origin rpy="0 0 0" xyz="0 0 0"/>
      <geometry>
        <mesh filename="package://linorobot2_description/mecanum_wheel_left/meshes/roller1.STL"/>
      </geometry>
    </collision>
  </link>
  <joint name="front_left_base_link_to_front_left_roller1" type="continuous">
    <origin rpy="2.3375 0.48899 -0.038445" xyz="-0.064997 -0.01515 0.019737"/>
    <parent link="front_left_base_link"/>
    <child link="front_left_roller1"/>
    <axis xyz="0 0 1"/>
  </joint>
  <link name="front_left_roller2">
    <inertial>
      <origin rpy="0 0 0" xyz="5.82867087928207E-16 -9.95687907123788E-15 -0.0215899999999933"/>
      <mass value="0.00499543658848216"/>
      <inertia ixx="8.99919949245561E-07" ixy="-3.30872245021211E-24" ixz="8.56959114604937E-22" iyy="8.99919949245641E-07" iyz="-8.01716684576195E-19" izz="3.31951561009139E-07"/>
    </inertial>
    <visual>
      <origin rpy="0 0 0" xyz="0 0 0"/>
      <geometry>
        <mesh filename="package://linorobot2_description/mecanum_wheel_left/meshes/roller2.STL"/>
      </geometry>
      <material name="">
        <color rgba="0.752941176470588 0.752941176470588 0.752941176470588 1"/>
      </material>
    </visual>
    <collision>
      <origin rpy="0 0 0" xyz="0 0 0"/>
      <geometry>
        <mesh filename="package://linorobot2_description/mecanum_wheel_left/meshes/roller2.STL"/>
      </geometry>
    </collision>
  </link>
  <joint name="front_left_base_link_to_front_left_roller2" type="continuous">
    <origin rpy="2.3122 0.90744 -0.055132" xyz="-0.05135 -0.01515 0.044467"/>
    <parent link="front_left_base_link"/>
    <child link="front_left_roller2"/>
    <axis xyz="0 0 1"/>
  </joint>
  <link name="front_left_roller3">
    <inertial>
      <origin rpy="0 0 0" xyz="5.82867087928207E-16 -3.41003267290141E-15 -0.0215899999999933"/>
      <mass value="0.00499543658848228"/>
      <inertia ixx="8.9991994924907E-07" ixy="-9.92616735063633E-24" ixz="8.47860127866853E-22" iyy="8.99919949249046E-07" iyz="-8.01743154355797E-19" izz="3.3195156101569E-07"/>
    </inertial>
    <visual>
      <origin rpy="0 0 0" xyz="0 0 0"/>
      <geometry>
        <mesh filename="package://linorobot2_description/mecanum_wheel_left/meshes/roller3.STL"/>
      </geometry>
      <material name="">
        <color rgba="0.752941176470588 0.752941176470588 0.752941176470588 1"/>
      </material>
    </visual>
    <collision>
      <origin rpy="0 0 0" xyz="0 0 0"/>
      <geometry>
        <mesh filename="package://linorobot2_description/mecanum_wheel_left/meshes/roller3.STL"/>
      </geometry>
    </collision>
  </link>
  <joint name="front_left_base_link_to_front_left_roller3" type="continuous">
    <origin rpy="2.22 1.3248 -0.13976" xyz="-0.028824 -0.01515 0.061508"/>
    <parent link="front_left_base_link"/>
    <child link="front_left_roller3"/>
    <axis xyz="0 0 1"/>
  </joint>
  <link name="front_left_roller4">
    <inertial>
      <origin rpy="0 0 0" xyz="5.68989300120393E-16 -3.35365415993216E-15 -0.0215899999999933"/>
      <mass value="0.00499543658848229"/>
      <inertia ixx="8.9991994924904E-07" ixy="1.65436122510606E-23" ixz="7.69277969674316E-22" iyy="8.99919949249123E-07" iyz="-8.01796093915E-19" izz="3.31951561015737E-07"/>
    </inertial>
    <visual>
      <origin rpy="0 0 0" xyz="0 0 0"/>
      <geometry>
        <mesh filename="package://linorobot2_description/mecanum_wheel_left/meshes/roller4.STL"/>
      </geometry>
      <material name="">
        <color rgba="0.752941176470588 0.752941176470588 0.752941176470588 1"/>
      </material>
    </visual>
    <collision>
      <origin rpy="0 0 0" xyz="0 0 0"/>
      <geometry>
        <mesh filename="package://linorobot2_description/mecanum_wheel_left/meshes/roller4.STL"/>
      </geometry>
    </collision>
  </link>
  <joint name="front_left_base_link_to_front_left_roller4" type="continuous">
    <origin rpy="-0.59653 1.3924 -2.9492" xyz="-0.0013143 -0.01515 0.067914"/>
    <parent link="front_left_base_link"/>
    <child link="front_left_roller4"/>
    <axis xyz="0 0 1"/>
  </joint>
  <link name="front_left_roller5">
    <inertial>
      <origin rpy="0 0 0" xyz="5.96744875736022E-16 2.4459601011273E-15 -0.0215899999999933"/>
      <mass value="0.00499543658848241"/>
      <inertia ixx="8.99919949250993E-07" ixy="3.14328632770151E-23" ixz="7.25437397209005E-22" iyy="8.99919949251052E-07" iyz="-8.01796093915E-19" izz="3.31951561019638E-07"/>
    </inertial>
    <visual>
      <origin rpy="0 0 0" xyz="0 0 0"/>
      <geometry>
        <mesh filename="package://linorobot2_description/mecanum_wheel_left/meshes/roller5.STL"/>
      </geometry>
      <material name="">
        <color rgba="0.752941176470588 0.752941176470588 0.752941176470588 1"/>
      </material>
    </visual>
    <collision>
      <origin rpy="0 0 0" xyz="0 0 0"/>
      <geometry>
        <mesh filename="package://linorobot2_description/mecanum_wheel_left/meshes/roller5.STL"/>
      </geometry>
    </collision>
  </link>
  <joint name="front_left_base_link_to_front_left_roller5" type="continuous">
    <origin rpy="-0.73578 0.97593 -3.081" xyz="0.026423 -0.01515 0.062578"/>
    <parent link="front_left_base_link"/>
    <child link="front_left_roller5"/>
    <axis xyz="0 0 1"/>
  </joint>
  <link name="front_left_roller6">
    <inertial>
      <origin rpy="0 0 0" xyz="5.82867087928207E-16 -7.52392939618041E-15 -0.0215899999999933"/>
      <mass value="0.00499543658848228"/>
      <inertia ixx="8.99919949249441E-07" ixy="5.9557004103818E-23" ixz="8.28834973778134E-22" iyy="8.99919949249495E-07" iyz="-8.017828590252E-19" izz="3.31951561016508E-07"/>
    </inertial>
    <visual>
      <origin rpy="0 0 0" xyz="0 0 0"/>
      <geometry>
        <mesh filename="package://linorobot2_description/mecanum_wheel_left/meshes/roller6.STL"/>
      </geometry>
      <material name="">
        <color rgba="0.752941176470588 0.752941176470588 0.752941176470588 1"/>
      </material>
    </visual>
    <collision>
      <origin rpy="0 0 0" xyz="0 0 0"/>
      <geometry>
        <mesh filename="package://linorobot2_description/mecanum_wheel_left/meshes/roller6.STL"/>
      </geometry>
    </collision>
  </link>
  <joint name="front_left_base_link_to_front_left_roller6" type="continuous">
    <origin rpy="-0.76481 0.55754 -3.1016" xyz="0.049591 -0.01515 0.04642"/>
    <parent link="front_left_base_link"/>
    <child link="front_left_roller6"/>
    <axis xyz="0 0 1"/>
  </joint>
  <link name="front_left_roller7">
    <inertial>
      <origin rpy="0 0 0" xyz="5.82867087928207E-16 -3.4109000346394E-15 -0.0215899999999933"/>
      <mass value="0.00499543658848228"/>
      <inertia ixx="8.9991994924911E-07" ixy="-3.30872245021211E-24" ixz="7.51079996198149E-22" iyy="8.99919949249103E-07" iyz="-8.00353490926708E-19" izz="3.31951561015786E-07"/>
    </inertial>
    <visual>
      <origin rpy="0 0 0" xyz="0 0 0"/>
      <geometry>
        <mesh filename="package://linorobot2_description/mecanum_wheel_left/meshes/roller7.STL"/>
      </geometry>
      <material name="">
        <color rgba="0.752941176470588 0.752941176470588 0.752941176470588 1"/>
      </material>
    </visual>
    <collision>
      <origin rpy="0 0 0" xyz="0 0 0"/>
      <geometry>
        <mesh filename="package://linorobot2_description/mecanum_wheel_left/meshes/roller7.STL"/>
      </geometry>
    </collision>
  </link>
  <joint name="front_left_base_link_to_front_left_roller7" type="continuous">
    <origin rpy="-0.78123 0.13894 -3.1073" xyz="0.064184 -0.01515 0.022237"/>
    <parent link="front_left_base_link"/>
    <child link="front_left_roller7"/>
    <axis xyz="0 0 1"/>
  </joint>
  <link name="front_left_roller8">
    <inertial>
      <origin rpy="0 0 0" xyz="5.82867087928207E-16 -1.76421377506841E-15 -0.0215899999999933"/>
      <mass value="0.00499543658848253"/>
      <inertia ixx="8.9991994925561E-07" ixy="-4.13590306276514E-23" ixz="7.46944093135384E-22" iyy="8.99919949255578E-07" iyz="-8.01624040347589E-19" izz="3.31951561027997E-07"/>
    </inertial>
    <visual>
      <origin rpy="0 0 0" xyz="0 0 0"/>
      <geometry>
        <mesh filename="package://linorobot2_description/mecanum_wheel_left/meshes/roller8.STL"/>
      </geometry>
      <material name="">
        <color rgba="0.752941176470588 0.752941176470588 0.752941176470588 1"/>
      </material>
    </visual>
    <collision>
      <origin rpy="0 0 0" xyz="0 0 0"/>
      <geometry>
        <mesh filename="package://linorobot2_description/mecanum_wheel_left/meshes/roller8.STL"/>
      </geometry>
    </collision>
  </link>
  <joint name="front_left_base_link_to_front_left_roller8" type="continuous">
    <origin rpy="-0.79573 -0.27969 -3.1063" xyz="0.06768 -0.01515 -0.0057919"/>
    <parent link="front_left_base_link"/>
    <child link="front_left_roller8"/>
    <axis xyz="0 0 1"/>
  </joint>
  <link name="front_left_roller9">
    <inertial>
      <origin rpy="0 0 0" xyz="5.82867087928207E-16 -5.1013880619788E-15 -0.0215899999999933"/>
      <mass value="0.00499543658848228"/>
      <inertia ixx="8.99919949250354E-07" ixy="1.81979734761666E-22" ixz="8.08982639076861E-22" iyy="8.99919949250367E-07" iyz="-8.01835798584403E-19" izz="3.31951561017902E-07"/>
    </inertial>
    <visual>
      <origin rpy="0 0 0" xyz="0 0 0"/>
      <geometry>
        <mesh filename="package://linorobot2_description/mecanum_wheel_left/meshes/roller9.STL"/>
      </geometry>
      <material name="">
        <color rgba="0.752941176470588 0.752941176470588 0.752941176470588 1"/>
      </material>
    </visual>
    <collision>
      <origin rpy="0 0 0" xyz="0 0 0"/>
      <geometry>
        <mesh filename="package://linorobot2_description/mecanum_wheel_left/meshes/roller9.STL"/>
      </geometry>
    </collision>
  </link>
  <joint name="front_left_base_link_to_front_left_roller9" type="continuous">
    <origin rpy="-0.81448 -0.69826 -3.0973" xyz="0.059473 -0.01515 -0.032819"/>
    <parent link="front_left_base_link"/>
    <child link="front_left_roller9"/>
    <axis xyz="0 0 1"/>
  </joint>
  <link name="front_left_roller10">
    <inertial>
      <origin rpy="0 0 0" xyz="5.96744875736022E-16 -6.51952450358984E-15 -0.0215899999999933"/>
      <mass value="0.00499543658848228"/>
      <inertia ixx="8.99919949250464E-07" ixy="-1.43929426584227E-22" ixz="8.58613475830043E-22" iyy="8.99919949250483E-07" iyz="-8.01756389245598E-19" izz="3.31951561018128E-07"/>
    </inertial>
    <visual>
      <origin rpy="0 0 0" xyz="0 0 0"/>
      <geometry>
        <mesh filename="package://linorobot2_description/mecanum_wheel_left/meshes/roller10.STL"/>
      </geometry>
      <material name="">
        <color rgba="0.752941176470588 0.752941176470588 0.752941176470588 1"/>
      </material>
    </visual>
    <collision>
      <origin rpy="0 0 0" xyz="0 0 0"/>
      <geometry>
        <mesh filename="package://linorobot2_description/mecanum_wheel_left/meshes/roller10.STL"/>
      </geometry>
    </collision>
  </link>
  <joint name="front_left_base_link_to_front_left_roller10" type="continuous">
    <origin rpy="-0.85554 -1.1164 -3.0642" xyz="0.040982 -0.01515 -0.054171"/>
    <parent link="front_left_base_link"/>
    <child link="front_left_roller10"/>
    <axis xyz="0 0 1"/>
  </joint>
  <link name="front_left_roller11">
    <inertial>
      <origin rpy="0 0 0" xyz="5.68989300120393E-16 -3.40699690681845E-15 -0.0215899999999933"/>
      <mass value="0.00499543658848228"/>
      <inertia ixx="8.99919949249114E-07" ixy="-6.61744490042422E-24" ixz="8.13118542139626E-22" iyy="8.99919949249044E-07" iyz="-8.00419665375712E-19" izz="3.31951561015731E-07"/>
    </inertial>
    <visual>
      <origin rpy="0 0 0" xyz="0 0 0"/>
      <geometry>
        <mesh filename="package://linorobot2_description/mecanum_wheel_left/meshes/roller11.STL"/>
      </geometry>
      <material name="">
        <color rgba="0.752941176470588 0.752941176470588 0.752941176470588 1"/>
      </material>
    </visual>
    <collision>
      <origin rpy="0 0 0" xyz="0 0 0"/>
      <geometry>
        <mesh filename="package://linorobot2_description/mecanum_wheel_left/meshes/roller11.STL"/>
      </geometry>
    </collision>
  </link>
  <joint name="front_left_base_link_to_front_left_roller11" type="continuous">
    <origin rpy="-1.5658 -1.5225 -2.3612" xyz="0.015406 -0.01515 -0.066157"/>
    <parent link="front_left_base_link"/>
    <child link="front_left_roller11"/>
    <axis xyz="0 0 1"/>
  </joint>
  <link name="front_left_roller12">
    <inertial>
      <origin rpy="0 0 0" xyz="5.96744875736022E-16 -9.87751547221194E-15 -0.0215899999999933"/>
      <mass value="0.00499543658848222"/>
      <inertia ixx="8.99919949247458E-07" ixy="8.27180612553028E-24" ixz="7.10548146183051E-22" iyy="8.99919949247364E-07" iyz="-8.01716684576195E-19" izz="3.31951561012396E-07"/>
    </inertial>
    <visual>
      <origin rpy="0 0 0" xyz="0 0 0"/>
      <geometry>
        <mesh filename="package://linorobot2_description/mecanum_wheel_left/meshes/roller12.STL"/>
      </geometry>
      <material name="">
        <color rgba="0.752941176470588 0.752941176470588 0.752941176470588 1"/>
      </material>
    </visual>
    <collision>
      <origin rpy="0 0 0" xyz="0 0 0"/>
      <geometry>
        <mesh filename="package://linorobot2_description/mecanum_wheel_left/meshes/roller12.STL"/>
      </geometry>
    </collision>
  </link>
  <joint name="front_left_base_link_to_front_left_roller12" type="continuous">
    <origin rpy="2.4393 -1.1848 -0.090248" xyz="-0.012835 -0.01515 -0.066704"/>
    <parent link="front_left_base_link"/>
    <child link="front_left_roller12"/>
    <axis xyz="0 0 1"/>
  </joint>
  <link name="front_left_roller13">
    <inertial>
      <origin rpy="0 0 0" xyz="6.10622663543836E-16 -6.50608039665102E-15 -0.0215899999999933"/>
      <mass value="0.0049954365884824"/>
      <inertia ixx="8.99919949251263E-07" ixy="3.30872245021211E-24" ixz="8.75984268693656E-22" iyy="8.9991994925119E-07" iyz="-8.01491691449581E-19" izz="3.31951561019653E-07"/>
    </inertial>
    <visual>
      <origin rpy="0 0 0" xyz="0 0 0"/>
      <geometry>
        <mesh filename="package://linorobot2_description/mecanum_wheel_left/meshes/roller13.STL"/>
      </geometry>
      <material name="">
        <color rgba="0.752941176470588 0.752941176470588 0.752941176470588 1"/>
      </material>
    </visual>
    <collision>
      <origin rpy="0 0 0" xyz="0 0 0"/>
      <geometry>
        <mesh filename="package://linorobot2_description/mecanum_wheel_left/meshes/roller13.STL"/>
      </geometry>
    </collision>
  </link>
  <joint name="front_left_base_link_to_front_left_roller13" type="continuous">
    <origin rpy="2.3883 -0.76678 -0.047134" xyz="-0.038856 -0.01515 -0.055716"/>
    <parent link="front_left_base_link"/>
    <child link="front_left_roller13"/>
    <axis xyz="0 0 1"/>
  </joint>
  <link name="front_left_roller14">
    <inertial>
      <origin rpy="0 0 0" xyz="5.96744875736022E-16 -3.365797224264E-15 -0.0215899999999933"/>
      <mass value="0.00499543658848228"/>
      <inertia ixx="8.99919949249125E-07" ixy="2.81241408268029E-23" ixz="6.46855239016468E-22" iyy="8.99919949249103E-07" iyz="-8.01888738143606E-19" izz="3.31951561015801E-07"/>
    </inertial>
    <visual>
      <origin rpy="0 0 0" xyz="0 0 0"/>
      <geometry>
        <mesh filename="package://linorobot2_description/mecanum_wheel_left/meshes/roller14.STL"/>
      </geometry>
      <material name="">
        <color rgba="0.752941176470588 0.752941176470588 0.752941176470588 1"/>
      </material>
    </visual>
    <collision>
      <origin rpy="0 0 0" xyz="0 0 0"/>
      <geometry>
        <mesh filename="package://linorobot2_description/mecanum_wheel_left/meshes/roller14.STL"/>
      </geometry>
    </collision>
  </link>
  <joint name="front_left_base_link_to_front_left_roller14" type="continuous">
    <origin rpy="2.3679 -0.34825 -0.036106" xyz="-0.058159 -0.01515 -0.035095"/>
    <parent link="front_left_base_link"/>
    <child link="front_left_roller14"/>
    <axis xyz="0 0 1"/>
  </joint>
  <link name="front_left_roller15">
    <inertial>
      <origin rpy="0 0 0" xyz="5.82867087928207E-16 -3.35452152167015E-15 -0.0215899999999933"/>
      <mass value="0.00499543658848229"/>
      <inertia ixx="8.99919949249126E-07" ixy="-1.15805285757424E-23" ixz="8.54477572767278E-22" iyy="8.99919949249124E-07" iyz="-8.01796093915E-19" izz="3.31951561015821E-07"/>
    </inertial>
    <visual>
      <origin rpy="0 0 0" xyz="0 0 0"/>
      <geometry>
        <mesh filename="package://linorobot2_description/mecanum_wheel_left/meshes/roller15.STL"/>
      </geometry>
      <material name="">
        <color rgba="0.752941176470588 0.752941176470588 0.752941176470588 1"/>
      </material>
    </visual>
    <collision>
      <origin rpy="0 0 0" xyz="0 0 0"/>
      <geometry>
        <mesh filename="package://linorobot2_description/mecanum_wheel_left/meshes/roller15.STL"/>
      </geometry>
    </collision>
  </link>
  <joint name="front_left_base_link_to_front_left_roller15" type="continuous">
    <origin rpy="2.35322166168045 0.070379538766794 -0.0340216727613588" xyz="-0.0674050504299177 -0.0151497403158722 -0.00840608812639412"/>
    <parent link="front_left_base_link"/>
    <child link="front_left_roller15"/>
    <axis xyz="0 0 1"/>
  </joint>
  <link name="front_right_base_link">
    <inertial>
      <origin rpy="0 0 0" xyz="-1.48571881243385E-15 -6.7886631592007E-16 -0.0136209233699844"/>
      <mass value="0.0396439871820506"/>
      <inertia ixx="3.76805204137311E-05" ixy="1.66580607308995E-20" ixz="3.71031510257902E-18" iyy="3.76805204137311E-05" iyz="1.63812405352096E-18" izz="7.1054120055567E-05"/>
    </inertial>
    <visual>
      <origin rpy="0 0 0" xyz="0 0 0"/>
      <geometry>
        <mesh filename="package://linorobot2_description/mecanum_wheel_right/meshes/base_link.STL"/>
      </geometry>
      <material name="">
        <color rgba="0.898039215686275 0.917647058823529 0.929411764705882 1"/>
      </material>
    </visual>
    <collision>
      <origin rpy="0 0 0" xyz="0 0 0"/>
      <geometry>
        <mesh filename="package://linorobot2_description/mecanum_wheel_right/meshes/base_link.STL"/>
      </geometry>
    </collision>
  </link>
  <joint name="base_link_to_front_right_base_link" type="continuous">
    <origin rpy="0 0 0" xyz="0.25857 -0.19355 0"/>
    <parent link="base_link"/>
    <child link="front_right_base_link"/>
    <axis xyz="0 1 0"/>
  </joint>
  <link name="front_right_drum">
    <inertial>
      <origin rpy="0 0 0" xyz="0.0136209233699844 6.56957443528167E-16 -1.48512976903392E-15"/>
      <mass value="0.0396439871820506"/>
      <inertia ixx="7.1054120055567E-05" ixy="1.62690471844664E-18" ixz="-3.70636817664487E-18" iyy="3.76805204137311E-05" iyz="1.0973915143622E-20" izz="3.76805204137311E-05"/>
    </inertial>
    <visual>
      <origin rpy="0 0 0" xyz="0 0 0"/>
      <geometry>
        <mesh filename="package://linorobot2_description/mecanum_wheel_right/meshes/drum.STL"/>
      </geometry>
      <material name="">
        <color rgba="0.898039215686275 0.917647058823529 0.929411764705882 1"/>
      </material>
    </visual>
    <collision>
      <origin rpy="0 0 0" xyz="0 0 0"/>
      <geometry>
        <mesh filename="package://linorobot2_description/mecanum_wheel_right/meshes/drum.STL"/>
      </geometry>
    </collision>
  </link>
  <joint name="front_right_base_link_to_drum" type="fixed">
    <origin rpy="1.5707963267949 0 -1.5707963267949" xyz="0 0 0"/>
    <parent link="front_right_base_link"/>
    <child link="front_right_drum"/>
    <axis xyz="0 0 0"/>
  </joint>
  <link name="front_right_plate1">
    <inertial>
      <origin rpy="0 0 0" xyz="-0.00283756867072453 8.89413056967719E-16 2.68096171575045E-15"/>
      <mass value="0.0253986639693881"/>
      <inertia ixx="8.39719993847471E-05" ixy="1.90079838330856E-18" ixz="4.7133202434868E-18" iyy="4.21627753206921E-05" iyz="-1.48230765769502E-20" izz="4.21627753206921E-05"/>
    </inertial>
    <visual>
      <origin rpy="0 0 0" xyz="0 0 0"/>
      <geometry>
        <mesh filename="package://linorobot2_description/mecanum_wheel_right/meshes/plate1.STL"/>
      </geometry>
      <material name="">
        <color rgba="0.752941176470588 0.752941176470588 0.752941176470588 1"/>
      </material>
    </visual>
    <collision>
      <origin rpy="0 0 0" xyz="0 0 0"/>
      <geometry>
        <mesh filename="package://linorobot2_description/mecanum_wheel_right/meshes/plate1.STL"/>
      </geometry>
    </collision>
  </link>
  <joint name="front_right_base_link_to_front_right_plate1" type="fixed">
    <origin rpy="-1.60435101016735 0 1.5707963267949" xyz="0 0.0254 0"/>
    <parent link="front_right_base_link"/>
    <child link="front_right_plate1"/>
    <axis xyz="0 0 0"/>
  </joint>
  <link name="front_right_plate2">
    <inertial>
      <origin rpy="0 0 0" xyz="-0.00283756867072453 -9.8249688244021E-17 5.89771118826868E-17"/>
      <mass value="0.0253986639693881"/>
      <inertia ixx="8.39719993847471E-05" ixy="-9.13983660820293E-21" ixz="5.31128745957199E-22" iyy="4.2162775320692E-05" iyz="1.59877468794249E-20" izz="4.21627753206921E-05"/>
    </inertial>
    <visual>
      <origin rpy="0 0 0" xyz="0 0 0"/>
      <geometry>
        <mesh filename="package://linorobot2_description/mecanum_wheel_right/meshes/plate2.STL"/>
      </geometry>
      <material name="">
        <color rgba="0.752941176470588 0.752941176470588 0.752941176470588 1"/>
      </material>
    </visual>
    <collision>
      <origin rpy="0 0 0" xyz="0 0 0"/>
      <geometry>
        <mesh filename="package://linorobot2_description/mecanum_wheel_right/meshes/plate2.STL"/>
      </geometry>
    </collision>
  </link>
  <joint name="front_right_base_link_to_front_right_plate2" type="fixed">
    <origin rpy="1.60435101016734 0 -1.5707963267949" xyz="0 -0.0254 0"/>
    <parent link="front_right_base_link"/>
    <child link="front_right_plate2"/>
    <axis xyz="0 0 0"/>
  </joint>
  <link name="front_right_roller1">
    <inertial>
      <origin rpy="0 0 0" xyz="5.82867087928207E-16 3.51108031537706E-15 -0.0215899999999933"/>
      <mass value="0.00499543658848254"/>
      <inertia ixx="8.99919949255961E-07" ixy="0" ixz="7.14684049245816E-22" iyy="8.999199492559E-07" iyz="-8.01670362461892E-19" izz="3.31951561028667E-07"/>
    </inertial>
    <visual>
      <origin rpy="0 0 0" xyz="0 0 0"/>
      <geometry>
        <mesh filename="package://linorobot2_description/mecanum_wheel_right/meshes/roller1.STL"/>
      </geometry>
      <material name="">
        <color rgba="0.752941176470588 0.752941176470588 0.752941176470588 1"/>
      </material>
    </visual>
    <collision>
      <origin rpy="0 0 0" xyz="0 0 0"/>
      <geometry>
        <mesh filename="package://linorobot2_description/mecanum_wheel_right/meshes/roller1.STL"/>
      </geometry>
    </collision>
  </link>
  <joint name="front_right_base_link_to_front_right_roller1" type="continuous">
    <origin rpy="-2.36778917303694 -0.95454994461673 -1.76416393166909" xyz="0.0513105165568448 -0.0151129693198936 0.0444755356274741"/>
    <parent link="front_right_base_link"/>
    <child link="front_right_roller1"/>
    <axis xyz="0 0 1"/>
  </joint>
  <link name="front_right_roller2">
    <inertial>
      <origin rpy="0 0 0" xyz="5.68989300120393E-16 -1.90819582357449E-15 -0.0215899999999933"/>
      <mass value="0.00499543658848222"/>
      <inertia ixx="8.99919949249302E-07" ixy="-1.32348898008484E-22" ixz="5.16160702233089E-22" iyy="8.99919949249335E-07" iyz="-8.02001234706914E-19" izz="3.31951561015819E-07"/>
    </inertial>
    <visual>
      <origin rpy="0 0 0" xyz="0 0 0"/>
      <geometry>
        <mesh filename="package://linorobot2_description/mecanum_wheel_right/meshes/roller2.STL"/>
      </geometry>
      <material name="">
        <color rgba="0.752941176470588 0.752941176470588 0.752941176470588 1"/>
      </material>
    </visual>
    <collision>
      <origin rpy="0 0 0" xyz="0 0 0"/>
      <geometry>
        <mesh filename="package://linorobot2_description/mecanum_wheel_right/meshes/roller2.STL"/>
      </geometry>
    </collision>
  </link>
  <joint name="front_right_base_link_to_front_right_roller2" type="continuous">
    <origin rpy="-1.77439072812908 -0.775855866169197 -2.22324127737972" xyz="0.0287846592696844 -0.0151129693198959 0.0615002908075162"/>
    <parent link="front_right_base_link"/>
    <child link="front_right_roller2"/>
    <axis xyz="0 0 1"/>
  </joint>
  <link name="front_right_roller3">
    <inertial>
      <origin rpy="0 0 0" xyz="5.82867087928207E-16 -4.16333634234434E-17 -0.0215899999999933"/>
      <mass value="0.00499543658848234"/>
      <inertia ixx="8.99919949252429E-07" ixy="-1.45583787809333E-22" ixz="6.48509600241574E-22" iyy="8.9991994925244E-07" iyz="-8.05501863059238E-19" izz="3.3195156102205E-07"/>
    </inertial>
    <visual>
      <origin rpy="0 0 0" xyz="0 0 0"/>
      <geometry>
        <mesh filename="package://linorobot2_description/mecanum_wheel_right/meshes/roller3.STL"/>
      </geometry>
      <material name="">
        <color rgba="0.752941176470588 0.752941176470588 0.752941176470588 1"/>
      </material>
    </visual>
    <collision>
      <origin rpy="0 0 0" xyz="0 0 0"/>
      <geometry>
        <mesh filename="package://linorobot2_description/mecanum_wheel_right/meshes/roller3.STL"/>
      </geometry>
    </collision>
  </link>
  <joint name="front_right_base_link_to_front_right_roller3" type="continuous">
    <origin rpy="-1.40103696999546 -0.48194994387805 -2.44694050545059" xyz="0.00128167289437567 -0.0151129693198984 0.0678910869943366"/>
    <parent link="front_right_base_link"/>
    <child link="front_right_roller3"/>
    <axis xyz="0 0 1"/>
  </joint>
  <link name="front_right_roller4">
    <inertial>
      <origin rpy="0 0 0" xyz="5.89805981832114E-16 -3.20576898360514E-15 -0.0215899999999933"/>
      <mass value="0.00499543658848215"/>
      <inertia ixx="8.99919949244641E-07" ixy="0" ixz="8.73502726855997E-22" iyy="8.99919949244639E-07" iyz="-8.01855650919104E-19" izz="3.31951561007608E-07"/>
    </inertial>
    <visual>
      <origin rpy="0 0 0" xyz="0 0 0"/>
      <geometry>
        <mesh filename="package://linorobot2_description/mecanum_wheel_right/meshes/roller4.STL"/>
      </geometry>
      <material name="">
        <color rgba="0.752941176470588 0.752941176470588 0.752941176470588 1"/>
      </material>
    </visual>
    <collision>
      <origin rpy="0 0 0" xyz="0 0 0"/>
      <geometry>
        <mesh filename="package://linorobot2_description/mecanum_wheel_right/meshes/roller4.STL"/>
      </geometry>
    </collision>
  </link>
  <joint name="front_right_base_link_to_front_right_roller4" type="continuous">
    <origin rpy="-1.13469826196558 -0.147073422491862 -2.53094960861872" xyz="-0.0264429263680024 -0.0151129693199014 0.062542897468674"/>
    <parent link="front_right_base_link"/>
    <child link="front_right_roller4"/>
    <axis xyz="0 0 1"/>
  </joint>
  <link name="front_right_roller5">
    <inertial>
      <origin rpy="0 0 0" xyz="5.82867087928207E-16 -7.39686090156511E-15 -0.0215899999999933"/>
      <mass value="0.00499543658848228"/>
      <inertia ixx="8.99919949249555E-07" ixy="-7.94093388050907E-23" ixz="9.26442286059391E-22" iyy="8.99919949249567E-07" iyz="-8.01729919465996E-19" izz="3.31951561016665E-07"/>
    </inertial>
    <visual>
      <origin rpy="0 0 0" xyz="0 0 0"/>
      <geometry>
        <mesh filename="package://linorobot2_description/mecanum_wheel_right/meshes/roller5.STL"/>
      </geometry>
      <material name="">
        <color rgba="0.752941176470588 0.752941176470588 0.752941176470588 1"/>
      </material>
    </visual>
    <collision>
      <origin rpy="0 0 0" xyz="0 0 0"/>
      <geometry>
        <mesh filename="package://linorobot2_description/mecanum_wheel_right/meshes/roller5.STL"/>
      </geometry>
    </collision>
  </link>
  <joint name="front_right_base_link_to_front_right_roller5" type="continuous">
    <origin rpy="-0.894575475762315 0.197031441859666 -2.52483292758441" xyz="-0.0495953034349089 -0.0151129693199047 0.0463804727862918"/>
    <parent link="front_right_base_link"/>
    <child link="front_right_roller5"/>
    <axis xyz="0 0 1"/>
  </joint>
  <link name="front_right_roller6">
    <inertial>
      <origin rpy="0 0 0" xyz="5.89805981832114E-16 -9.20097331658098E-15 -0.0215899999999933"/>
      <mass value="0.00499543658848248"/>
      <inertia ixx="8.99919949253375E-07" ixy="-1.05879118406788E-22" ixz="8.73502726855997E-22" iyy="8.99919949253382E-07" iyz="-8.01961530037511E-19" izz="3.31951561023958E-07"/>
    </inertial>
    <visual>
      <origin rpy="0 0 0" xyz="0 0 0"/>
      <geometry>
        <mesh filename="package://linorobot2_description/mecanum_wheel_right/meshes/roller6.STL"/>
      </geometry>
      <material name="">
        <color rgba="0.752941176470588 0.752941176470588 0.752941176470588 1"/>
      </material>
    </visual>
    <collision>
      <origin rpy="0 0 0" xyz="0 0 0"/>
      <geometry>
        <mesh filename="package://linorobot2_description/mecanum_wheel_right/meshes/roller6.STL"/>
      </geometry>
    </collision>
  </link>
  <joint name="front_right_base_link_to_front_right_roller6" type="continuous">
    <origin rpy="-0.618670381864381 0.528470873009444 -2.42501713902796" xyz="-0.0641722019787319 -0.0151129693199074 0.0221984430057918"/>
    <parent link="front_right_base_link"/>
    <child link="front_right_roller6"/>
    <axis xyz="0 0 1"/>
  </joint>
  <link name="front_right_roller7">
    <inertial>
      <origin rpy="0 0 0" xyz="5.89805981832114E-16 -8.25034485174569E-15 -0.0215899999999933"/>
      <mass value="0.00499543658848216"/>
      <inertia ixx="8.99919949243988E-07" ixy="-1.58818677610181E-22" ixz="6.88214269644119E-22" iyy="8.99919949243943E-07" iyz="-8.01842416029303E-19" izz="3.31951561006258E-07"/>
    </inertial>
    <visual>
      <origin rpy="0 0 0" xyz="0 0 0"/>
      <geometry>
        <mesh filename="package://linorobot2_description/mecanum_wheel_right/meshes/roller7.STL"/>
      </geometry>
      <material name="">
        <color rgba="0.752941176470588 0.752941176470588 0.752941176470588 1"/>
      </material>
    </visual>
    <collision>
      <origin rpy="0 0 0" xyz="0 0 0"/>
      <geometry>
        <mesh filename="package://linorobot2_description/mecanum_wheel_right/meshes/roller7.STL"/>
      </geometry>
    </collision>
  </link>
  <joint name="front_right_base_link_to_front_right_roller7" type="continuous">
    <origin rpy="-0.22003525595071 0.81173834281584 -2.17291203984087" xyz="-0.0676531438142786 -0.0151129693199092 -0.0058218992369328"/>
    <parent link="front_right_base_link"/>
    <child link="front_right_roller7"/>
    <axis xyz="0 0 1"/>
  </joint>
  <link name="front_right_roller8">
    <inertial>
      <origin rpy="0 0 0" xyz="5.759281940243E-16 2.22044604925031E-15 -0.0215899999999933"/>
      <mass value="0.00499543658848215"/>
      <inertia ixx="8.99919949245218E-07" ixy="-2.64697796016969E-23" ixz="7.94093388050907E-22" iyy="8.99919949245208E-07" iyz="-8.02067409155918E-19" izz="3.31951561008361E-07"/>
    </inertial>
    <visual>
      <origin rpy="0 0 0" xyz="0 0 0"/>
      <geometry>
        <mesh filename="package://linorobot2_description/mecanum_wheel_right/meshes/roller8.STL"/>
      </geometry>
      <material name="">
        <color rgba="0.752941176470588 0.752941176470588 0.752941176470588 1"/>
      </material>
    </visual>
    <collision>
      <origin rpy="0 0 0" xyz="0 0 0"/>
      <geometry>
        <mesh filename="package://linorobot2_description/mecanum_wheel_right/meshes/roller8.STL"/>
      </geometry>
    </collision>
  </link>
  <joint name="front_right_base_link_to_front_right_roller8" type="continuous">
    <origin rpy="0.408043134594723 0.963708851734786 -1.67797755478808" xyz="-0.0594362424748194 -0.0151129693199101 -0.0328355822112983"/>
    <parent link="front_right_base_link"/>
    <child link="front_right_roller8"/>
    <axis xyz="0 0 1"/>
  </joint>
  <link name="front_right_roller9">
    <inertial>
      <origin rpy="0 0 0" xyz="5.759281940243E-16 -2.60208521396521E-15 -0.0215899999999933"/>
      <mass value="0.00499543658848229"/>
      <inertia ixx="8.9991994924954E-07" ixy="-2.64697796016969E-23" ixz="7.6762360844921E-22" iyy="8.99919949249544E-07" iyz="-8.01743154355797E-19" izz="3.31951561016627E-07"/>
    </inertial>
    <visual>
      <origin rpy="0 0 0" xyz="0 0 0"/>
      <geometry>
        <mesh filename="package://linorobot2_description/mecanum_wheel_right/meshes/roller9.STL"/>
      </geometry>
      <material name="">
        <color rgba="0.752941176470588 0.752941176470588 0.752941176470588 1"/>
      </material>
    </visual>
    <collision>
      <origin rpy="0 0 0" xyz="0 0 0"/>
      <geometry>
        <mesh filename="package://linorobot2_description/mecanum_wheel_right/meshes/roller9.STL"/>
      </geometry>
    </collision>
  </link>
  <joint name="front_right_base_link_to_front_right_roller9" type="continuous">
    <origin rpy="1.1026415771303 0.886919106568413 -1.11464531078552" xyz="-0.0409422748501527 -0.015112969319909 -0.0541716947194296"/>
    <parent link="front_right_base_link"/>
    <child link="front_right_roller9"/>
    <axis xyz="0 0 1"/>
  </joint>
  <link name="front_right_roller10">
    <inertial>
      <origin rpy="0 0 0" xyz="5.89805981832114E-16 -3.42087469462626E-15 -0.0215899999999933"/>
      <mass value="0.00499543658848216"/>
      <inertia ixx="8.99919949244339E-07" ixy="-1.05879118406788E-22" ixz="8.33798057453452E-22" iyy="8.99919949244339E-07" iyz="-8.05177608259117E-19" izz="3.31951561007005E-07"/>
    </inertial>
    <visual>
      <origin rpy="0 0 0" xyz="0 0 0"/>
      <geometry>
        <mesh filename="package://linorobot2_description/mecanum_wheel_right/meshes/roller10.STL"/>
      </geometry>
      <material name="">
        <color rgba="0.752941176470588 0.752941176470588 0.752941176470588 1"/>
      </material>
    </visual>
    <collision>
      <origin rpy="0 0 0" xyz="0 0 0"/>
      <geometry>
        <mesh filename="package://linorobot2_description/mecanum_wheel_right/meshes/roller10.STL"/>
      </geometry>
    </collision>
  </link>
  <joint name="front_right_base_link_to_front_right_roller10" type="continuous">
    <origin rpy="1.57421323203544 0.637163580624169 -0.783361608443036" xyz="-0.0153690159550034 -0.0151129693199065 -0.0661410290761748"/>
    <parent link="front_right_base_link"/>
    <child link="front_right_roller10"/>
    <axis xyz="0 0 1"/>
  </joint>
  <link name="front_right_roller11">
    <inertial>
      <origin rpy="0 0 0" xyz="5.89805981832114E-16 -5.03069808033274E-15 -0.0215899999999933"/>
      <mass value="0.00499543658848235"/>
      <inertia ixx="8.99919949251756E-07" ixy="-1.7205356741103E-22" ixz="7.41153828847513E-22" iyy="8.99919949251703E-07" iyz="-8.01815946249702E-19" izz="3.3195156102064E-07"/>
    </inertial>
    <visual>
      <origin rpy="0 0 0" xyz="0 0 0"/>
      <geometry>
        <mesh filename="package://linorobot2_description/mecanum_wheel_right/meshes/roller11.STL"/>
      </geometry>
      <material name="">
        <color rgba="0.752941176470588 0.752941176470588 0.752941176470588 1"/>
      </material>
    </visual>
    <collision>
      <origin rpy="0 0 0" xyz="0 0 0"/>
      <geometry>
        <mesh filename="package://linorobot2_description/mecanum_wheel_right/meshes/roller11.STL"/>
      </geometry>
    </collision>
  </link>
  <joint name="front_right_base_link_to_front_right_roller11" type="continuous">
    <origin rpy="1.88109068595424 0.317129294370825 -0.639722033593165" xyz="0.0128616854218928 -0.0151129693199038 -0.0666739786332639"/>
    <parent link="front_right_base_link"/>
    <child link="front_right_roller11"/>
    <axis xyz="0 0 1"/>
  </joint>
  <link name="front_right_roller12">
    <inertial>
      <origin rpy="0 0 0" xyz="5.759281940243E-16 -3.44169137633799E-15 -0.0215899999999933"/>
      <mass value="0.00499543658848216"/>
      <inertia ixx="8.99919949244308E-07" ixy="-5.29395592033938E-23" ixz="6.88214269644119E-22" iyy="8.99919949244286E-07" iyz="-8.02021087041615E-19" izz="3.3195156100692E-07"/>
    </inertial>
    <visual>
      <origin rpy="0 0 0" xyz="0 0 0"/>
      <geometry>
        <mesh filename="package://linorobot2_description/mecanum_wheel_right/meshes/roller12.STL"/>
      </geometry>
      <material name="">
        <color rgba="0.752941176470588 0.752941176470588 0.752941176470588 1"/>
      </material>
    </visual>
    <collision>
      <origin rpy="0 0 0" xyz="0 0 0"/>
      <geometry>
        <mesh filename="package://linorobot2_description/mecanum_wheel_right/meshes/roller12.STL"/>
      </geometry>
    </collision>
  </link>
  <joint name="front_right_base_link_to_front_right_roller12" type="continuous">
    <origin rpy="2.12643201705665 -0.025160050703084 -0.60332516970669" xyz="0.0388684845445997 -0.0151129693199006 -0.0556783915705813"/>
    <parent link="front_right_base_link"/>
    <child link="front_right_roller12"/>
    <axis xyz="0 0 1"/>
  </joint>
  <link name="front_right_roller13">
    <inertial>
      <origin rpy="0 0 0" xyz="5.89805981832114E-16 -3.36536354339501E-15 -0.0215899999999933"/>
      <mass value="0.00499543658848228"/>
      <inertia ixx="8.99919949249124E-07" ixy="6.61744490042422E-23" ixz="9.66146955461936E-22" iyy="8.99919949249017E-07" iyz="-8.01875503253805E-19" izz="3.31951561015716E-07"/>
    </inertial>
    <visual>
      <origin rpy="0 0 0" xyz="0 0 0"/>
      <geometry>
        <mesh filename="package://linorobot2_description/mecanum_wheel_right/meshes/roller13.STL"/>
      </geometry>
      <material name="">
        <color rgba="0.752941176470588 0.752941176470588 0.752941176470588 1"/>
      </material>
    </visual>
    <collision>
      <origin rpy="0 0 0" xyz="0 0 0"/>
      <geometry>
        <mesh filename="package://linorobot2_description/mecanum_wheel_right/meshes/roller13.STL"/>
      </geometry>
    </collision>
  </link>
  <joint name="front_right_base_link_to_front_right_roller13" type="continuous">
    <origin rpy="2.37615666037905 -0.365916365141497 -0.652805521545524" xyz="0.0581545695804492 -0.0151129693198971 -0.0350555047830372"/>
    <parent link="front_right_base_link"/>
    <child link="front_right_roller13"/>
    <axis xyz="0 0 1"/>
  </joint>
  <link name="front_right_roller14">
    <inertial>
      <origin rpy="0 0 0" xyz="5.82867087928207E-16 -2.38697950294409E-15 -0.0215899999999933"/>
      <mass value="0.00499543658848209"/>
      <inertia ixx="8.99919949243614E-07" ixy="5.29395592033938E-23" ixz="6.61744490042422E-22" iyy="8.99919949243616E-07" iyz="-8.05343044381628E-19" izz="3.31951561005557E-07"/>
    </inertial>
    <visual>
      <origin rpy="0 0 0" xyz="0 0 0"/>
      <geometry>
        <mesh filename="package://linorobot2_description/mecanum_wheel_right/meshes/roller14.STL"/>
      </geometry>
      <material name="">
        <color rgba="0.752941176470588 0.752941176470588 0.752941176470588 1"/>
      </material>
    </visual>
    <collision>
      <origin rpy="0 0 0" xyz="0 0 0"/>
      <geometry>
        <mesh filename="package://linorobot2_description/mecanum_wheel_right/meshes/roller14.STL"/>
      </geometry>
    </collision>
  </link>
  <joint name="front_right_base_link_to_front_right_roller14" type="continuous">
    <origin rpy="2.69941973817462 -0.67973266586857 -0.817294146739146" xyz="0.0673852012181607 -0.0151129693198943 -0.00837120274924246"/>
    <parent link="front_right_base_link"/>
    <child link="front_right_roller14"/>
    <axis xyz="0 0 1"/>
  </joint>
  <link name="front_right_roller15">
    <inertial>
      <origin rpy="0 0 0" xyz="5.759281940243E-16 -6.50868248186498E-15 -0.0215899999999933"/>
      <mass value="0.00499543658848241"/>
      <inertia ixx="8.99919949251262E-07" ixy="1.05879118406788E-22" ixz="9.13207396258543E-22" iyy="8.99919949251201E-07" iyz="-8.01763006690498E-19" izz="3.31951561019665E-07"/>
    </inertial>
    <visual>
      <origin rpy="0 0 0" xyz="0 0 0"/>
      <geometry>
        <mesh filename="package://linorobot2_description/mecanum_wheel_right/meshes/roller15.STL"/>
      </geometry>
      <material name="">
        <color rgba="0.752941176470588 0.752941176470588 0.752941176470588 1"/>
      </material>
    </visual>
    <collision>
      <origin rpy="0 0 0" xyz="0 0 0"/>
      <geometry>
        <mesh filename="package://linorobot2_description/mecanum_wheel_right/meshes/roller15.STL"/>
      </geometry>
    </collision>
  </link>
  <joint name="front_right_base_link_to_front_right_roller15" type="continuous">
    <origin rpy="-3.077965161563 -0.911914057233449 -1.18487158274901" xyz="0.0649643193899178 -0.0151129693198934 0.0197605562898849"/>
    <parent link="front_right_base_link"/>
    <child link="front_right_roller15"/>
    <axis xyz="0 0 1"/>
  </joint>
  <!-- Back wheels mechanum style swapped (left mecanum wheel goes on right side of robot, and vice versa) -->
  <link name="rear_left_base_link">
    <inertial>
      <origin rpy="0 0 0" xyz="-1.48571881243385E-15 -6.7886631592007E-16 -0.0136209233699844"/>
      <mass value="0.0396439871820506"/>
      <inertia ixx="3.76805204137311E-05" ixy="1.66580607308995E-20" ixz="3.71031510257902E-18" iyy="3.76805204137311E-05" iyz="1.63812405352096E-18" izz="7.1054120055567E-05"/>
    </inertial>
    <visual>
      <origin rpy="0 0 0" xyz="0 0 0"/>
      <geometry>
        <mesh filename="package://linorobot2_description/mecanum_wheel_right/meshes/base_link.STL"/>
      </geometry>
      <material name="">
        <color rgba="0.898039215686275 0.917647058823529 0.929411764705882 1"/>
      </material>
    </visual>
    <collision>
      <origin rpy="0 0 0" xyz="0 0 0"/>
      <geometry>
        <mesh filename="package://linorobot2_description/mecanum_wheel_right/meshes/base_link.STL"/>
      </geometry>
    </collision>
  </link>
  <joint name="base_link_to_rear_left_base_link" type="continuous">
    <origin rpy="0 0 0" xyz="-0.25857 0.19355 0"/>
    <parent link="base_link"/>
    <child link="rear_left_base_link"/>
    <axis xyz="0 1 0"/>
  </joint>
  <link name="rear_left_drum">
    <inertial>
      <origin rpy="0 0 0" xyz="0.0136209233699844 6.56957443528167E-16 -1.48512976903392E-15"/>
      <mass value="0.0396439871820506"/>
      <inertia ixx="7.1054120055567E-05" ixy="1.62690471844664E-18" ixz="-3.70636817664487E-18" iyy="3.76805204137311E-05" iyz="1.0973915143622E-20" izz="3.76805204137311E-05"/>
    </inertial>
    <visual>
      <origin rpy="0 0 0" xyz="0 0 0"/>
      <geometry>
        <mesh filename="package://linorobot2_description/mecanum_wheel_right/meshes/drum.STL"/>
      </geometry>
      <material name="">
        <color rgba="0.898039215686275 0.917647058823529 0.929411764705882 1"/>
      </material>
    </visual>
    <collision>
      <origin rpy="0 0 0" xyz="0 0 0"/>
      <geometry>
        <mesh filename="package://linorobot2_description/mecanum_wheel_right/meshes/drum.STL"/>
      </geometry>
    </collision>
  </link>
  <joint name="rear_left_base_link_to_drum" type="fixed">
    <origin rpy="1.5707963267949 0 -1.5707963267949" xyz="0 0 0"/>
    <parent link="rear_left_base_link"/>
    <child link="rear_left_drum"/>
    <axis xyz="0 0 0"/>
  </joint>
  <link name="rear_left_plate1">
    <inertial>
      <origin rpy="0 0 0" xyz="-0.00283756867072453 8.89413056967719E-16 2.68096171575045E-15"/>
      <mass value="0.0253986639693881"/>
      <inertia ixx="8.39719993847471E-05" ixy="1.90079838330856E-18" ixz="4.7133202434868E-18" iyy="4.21627753206921E-05" iyz="-1.48230765769502E-20" izz="4.21627753206921E-05"/>
    </inertial>
    <visual>
      <origin rpy="0 0 0" xyz="0 0 0"/>
      <geometry>
        <mesh filename="package://linorobot2_description/mecanum_wheel_right/meshes/plate1.STL"/>
      </geometry>
      <material name="">
        <color rgba="0.752941176470588 0.752941176470588 0.752941176470588 1"/>
      </material>
    </visual>
    <collision>
      <origin rpy="0 0 0" xyz="0 0 0"/>
      <geometry>
        <mesh filename="package://linorobot2_description/mecanum_wheel_right/meshes/plate1.STL"/>
      </geometry>
    </collision>
  </link>
  <joint name="rear_left_base_link_to_rear_left_plate1" type="fixed">
    <origin rpy="-1.60435101016735 0 1.5707963267949" xyz="0 0.0254 0"/>
    <parent link="rear_left_base_link"/>
    <child link="rear_left_plate1"/>
    <axis xyz="0 0 0"/>
  </joint>
  <link name="rear_left_plate2">
    <inertial>
      <origin rpy="0 0 0" xyz="-0.00283756867072453 -9.8249688244021E-17 5.89771118826868E-17"/>
      <mass value="0.0253986639693881"/>
      <inertia ixx="8.39719993847471E-05" ixy="-9.13983660820293E-21" ixz="5.31128745957199E-22" iyy="4.2162775320692E-05" iyz="1.59877468794249E-20" izz="4.21627753206921E-05"/>
    </inertial>
    <visual>
      <origin rpy="0 0 0" xyz="0 0 0"/>
      <geometry>
        <mesh filename="package://linorobot2_description/mecanum_wheel_right/meshes/plate2.STL"/>
      </geometry>
      <material name="">
        <color rgba="0.752941176470588 0.752941176470588 0.752941176470588 1"/>
      </material>
    </visual>
    <collision>
      <origin rpy="0 0 0" xyz="0 0 0"/>
      <geometry>
        <mesh filename="package://linorobot2_description/mecanum_wheel_right/meshes/plate2.STL"/>
      </geometry>
    </collision>
  </link>
  <joint name="rear_left_base_link_to_rear_left_plate2" type="fixed">
    <origin rpy="1.60435101016734 0 -1.5707963267949" xyz="0 -0.0254 0"/>
    <parent link="rear_left_base_link"/>
    <child link="rear_left_plate2"/>
    <axis xyz="0 0 0"/>
  </joint>
  <link name="rear_left_roller1">
    <inertial>
      <origin rpy="0 0 0" xyz="5.82867087928207E-16 3.51108031537706E-15 -0.0215899999999933"/>
      <mass value="0.00499543658848254"/>
      <inertia ixx="8.99919949255961E-07" ixy="0" ixz="7.14684049245816E-22" iyy="8.999199492559E-07" iyz="-8.01670362461892E-19" izz="3.31951561028667E-07"/>
    </inertial>
    <visual>
      <origin rpy="0 0 0" xyz="0 0 0"/>
      <geometry>
        <mesh filename="package://linorobot2_description/mecanum_wheel_right/meshes/roller1.STL"/>
      </geometry>
      <material name="">
        <color rgba="0.752941176470588 0.752941176470588 0.752941176470588 1"/>
      </material>
    </visual>
    <collision>
      <origin rpy="0 0 0" xyz="0 0 0"/>
      <geometry>
        <mesh filename="package://linorobot2_description/mecanum_wheel_right/meshes/roller1.STL"/>
      </geometry>
    </collision>
  </link>
  <joint name="rear_left_base_link_to_rear_left_roller1" type="continuous">
    <origin rpy="-2.36778917303694 -0.95454994461673 -1.76416393166909" xyz="0.0513105165568448 -0.0151129693198936 0.0444755356274741"/>
    <parent link="rear_left_base_link"/>
    <child link="rear_left_roller1"/>
    <axis xyz="0 0 1"/>
  </joint>
  <link name="rear_left_roller2">
    <inertial>
      <origin rpy="0 0 0" xyz="5.68989300120393E-16 -1.90819582357449E-15 -0.0215899999999933"/>
      <mass value="0.00499543658848222"/>
      <inertia ixx="8.99919949249302E-07" ixy="-1.32348898008484E-22" ixz="5.16160702233089E-22" iyy="8.99919949249335E-07" iyz="-8.02001234706914E-19" izz="3.31951561015819E-07"/>
    </inertial>
    <visual>
      <origin rpy="0 0 0" xyz="0 0 0"/>
      <geometry>
        <mesh filename="package://linorobot2_description/mecanum_wheel_right/meshes/roller2.STL"/>
      </geometry>
      <material name="">
        <color rgba="0.752941176470588 0.752941176470588 0.752941176470588 1"/>
      </material>
    </visual>
    <collision>
      <origin rpy="0 0 0" xyz="0 0 0"/>
      <geometry>
        <mesh filename="package://linorobot2_description/mecanum_wheel_right/meshes/roller2.STL"/>
      </geometry>
    </collision>
  </link>
  <joint name="rear_left_base_link_to_rear_left_roller2" type="continuous">
    <origin rpy="-1.77439072812908 -0.775855866169197 -2.22324127737972" xyz="0.0287846592696844 -0.0151129693198959 0.0615002908075162"/>
    <parent link="rear_left_base_link"/>
    <child link="rear_left_roller2"/>
    <axis xyz="0 0 1"/>
  </joint>
  <link name="rear_left_roller3">
    <inertial>
      <origin rpy="0 0 0" xyz="5.82867087928207E-16 -4.16333634234434E-17 -0.0215899999999933"/>
      <mass value="0.00499543658848234"/>
      <inertia ixx="8.99919949252429E-07" ixy="-1.45583787809333E-22" ixz="6.48509600241574E-22" iyy="8.9991994925244E-07" iyz="-8.05501863059238E-19" izz="3.3195156102205E-07"/>
    </inertial>
    <visual>
      <origin rpy="0 0 0" xyz="0 0 0"/>
      <geometry>
        <mesh filename="package://linorobot2_description/mecanum_wheel_right/meshes/roller3.STL"/>
      </geometry>
      <material name="">
        <color rgba="0.752941176470588 0.752941176470588 0.752941176470588 1"/>
      </material>
    </visual>
    <collision>
      <origin rpy="0 0 0" xyz="0 0 0"/>
      <geometry>
        <mesh filename="package://linorobot2_description/mecanum_wheel_right/meshes/roller3.STL"/>
      </geometry>
    </collision>
  </link>
  <joint name="rear_left_base_link_to_rear_left_roller3" type="continuous">
    <origin rpy="-1.40103696999546 -0.48194994387805 -2.44694050545059" xyz="0.00128167289437567 -0.0151129693198984 0.0678910869943366"/>
    <parent link="rear_left_base_link"/>
    <child link="rear_left_roller3"/>
    <axis xyz="0 0 1"/>
  </joint>
  <link name="rear_left_roller4">
    <inertial>
      <origin rpy="0 0 0" xyz="5.89805981832114E-16 -3.20576898360514E-15 -0.0215899999999933"/>
      <mass value="0.00499543658848215"/>
      <inertia ixx="8.99919949244641E-07" ixy="0" ixz="8.73502726855997E-22" iyy="8.99919949244639E-07" iyz="-8.01855650919104E-19" izz="3.31951561007608E-07"/>
    </inertial>
    <visual>
      <origin rpy="0 0 0" xyz="0 0 0"/>
      <geometry>
        <mesh filename="package://linorobot2_description/mecanum_wheel_right/meshes/roller4.STL"/>
      </geometry>
      <material name="">
        <color rgba="0.752941176470588 0.752941176470588 0.752941176470588 1"/>
      </material>
    </visual>
    <collision>
      <origin rpy="0 0 0" xyz="0 0 0"/>
      <geometry>
        <mesh filename="package://linorobot2_description/mecanum_wheel_right/meshes/roller4.STL"/>
      </geometry>
    </collision>
  </link>
  <joint name="rear_left_base_link_to_rear_left_roller4" type="continuous">
    <origin rpy="-1.13469826196558 -0.147073422491862 -2.53094960861872" xyz="-0.0264429263680024 -0.0151129693199014 0.062542897468674"/>
    <parent link="rear_left_base_link"/>
    <child link="rear_left_roller4"/>
    <axis xyz="0 0 1"/>
  </joint>
  <link name="rear_left_roller5">
    <inertial>
      <origin rpy="0 0 0" xyz="5.82867087928207E-16 -7.39686090156511E-15 -0.0215899999999933"/>
      <mass value="0.00499543658848228"/>
      <inertia ixx="8.99919949249555E-07" ixy="-7.94093388050907E-23" ixz="9.26442286059391E-22" iyy="8.99919949249567E-07" iyz="-8.01729919465996E-19" izz="3.31951561016665E-07"/>
    </inertial>
    <visual>
      <origin rpy="0 0 0" xyz="0 0 0"/>
      <geometry>
        <mesh filename="package://linorobot2_description/mecanum_wheel_right/meshes/roller5.STL"/>
      </geometry>
      <material name="">
        <color rgba="0.752941176470588 0.752941176470588 0.752941176470588 1"/>
      </material>
    </visual>
    <collision>
      <origin rpy="0 0 0" xyz="0 0 0"/>
      <geometry>
        <mesh filename="package://linorobot2_description/mecanum_wheel_right/meshes/roller5.STL"/>
      </geometry>
    </collision>
  </link>
  <joint name="rear_left_base_link_to_rear_left_roller5" type="continuous">
    <origin rpy="-0.894575475762315 0.197031441859666 -2.52483292758441" xyz="-0.0495953034349089 -0.0151129693199047 0.0463804727862918"/>
    <parent link="rear_left_base_link"/>
    <child link="rear_left_roller5"/>
    <axis xyz="0 0 1"/>
  </joint>
  <link name="rear_left_roller6">
    <inertial>
      <origin rpy="0 0 0" xyz="5.89805981832114E-16 -9.20097331658098E-15 -0.0215899999999933"/>
      <mass value="0.00499543658848248"/>
      <inertia ixx="8.99919949253375E-07" ixy="-1.05879118406788E-22" ixz="8.73502726855997E-22" iyy="8.99919949253382E-07" iyz="-8.01961530037511E-19" izz="3.31951561023958E-07"/>
    </inertial>
    <visual>
      <origin rpy="0 0 0" xyz="0 0 0"/>
      <geometry>
        <mesh filename="package://linorobot2_description/mecanum_wheel_right/meshes/roller6.STL"/>
      </geometry>
      <material name="">
        <color rgba="0.752941176470588 0.752941176470588 0.752941176470588 1"/>
      </material>
    </visual>
    <collision>
      <origin rpy="0 0 0" xyz="0 0 0"/>
      <geometry>
        <mesh filename="package://linorobot2_description/mecanum_wheel_right/meshes/roller6.STL"/>
      </geometry>
    </collision>
  </link>
  <joint name="rear_left_base_link_to_rear_left_roller6" type="continuous">
    <origin rpy="-0.618670381864381 0.528470873009444 -2.42501713902796" xyz="-0.0641722019787319 -0.0151129693199074 0.0221984430057918"/>
    <parent link="rear_left_base_link"/>
    <child link="rear_left_roller6"/>
    <axis xyz="0 0 1"/>
  </joint>
  <link name="rear_left_roller7">
    <inertial>
      <origin rpy="0 0 0" xyz="5.89805981832114E-16 -8.25034485174569E-15 -0.0215899999999933"/>
      <mass value="0.00499543658848216"/>
      <inertia ixx="8.99919949243988E-07" ixy="-1.58818677610181E-22" ixz="6.88214269644119E-22" iyy="8.99919949243943E-07" iyz="-8.01842416029303E-19" izz="3.31951561006258E-07"/>
    </inertial>
    <visual>
      <origin rpy="0 0 0" xyz="0 0 0"/>
      <geometry>
        <mesh filename="package://linorobot2_description/mecanum_wheel_right/meshes/roller7.STL"/>
      </geometry>
      <material name="">
        <color rgba="0.752941176470588 0.752941176470588 0.752941176470588 1"/>
      </material>
    </visual>
    <collision>
      <origin rpy="0 0 0" xyz="0 0 0"/>
      <geometry>
        <mesh filename="package://linorobot2_description/mecanum_wheel_right/meshes/roller7.STL"/>
      </geometry>
    </collision>
  </link>
  <joint name="rear_left_base_link_to_rear_left_roller7" type="continuous">
    <origin rpy="-0.22003525595071 0.81173834281584 -2.17291203984087" xyz="-0.0676531438142786 -0.0151129693199092 -0.0058218992369328"/>
    <parent link="rear_left_base_link"/>
    <child link="rear_left_roller7"/>
    <axis xyz="0 0 1"/>
  </joint>
  <link name="rear_left_roller8">
    <inertial>
      <origin rpy="0 0 0" xyz="5.759281940243E-16 2.22044604925031E-15 -0.0215899999999933"/>
      <mass value="0.00499543658848215"/>
      <inertia ixx="8.99919949245218E-07" ixy="-2.64697796016969E-23" ixz="7.94093388050907E-22" iyy="8.99919949245208E-07" iyz="-8.02067409155918E-19" izz="3.31951561008361E-07"/>
    </inertial>
    <visual>
      <origin rpy="0 0 0" xyz="0 0 0"/>
      <geometry>
        <mesh filename="package://linorobot2_description/mecanum_wheel_right/meshes/roller8.STL"/>
      </geometry>
      <material name="">
        <color rgba="0.752941176470588 0.752941176470588 0.752941176470588 1"/>
      </material>
    </visual>
    <collision>
      <origin rpy="0 0 0" xyz="0 0 0"/>
      <geometry>
        <mesh filename="package://linorobot2_description/mecanum_wheel_right/meshes/roller8.STL"/>
      </geometry>
    </collision>
  </link>
  <joint name="rear_left_base_link_to_rear_left_roller8" type="continuous">
    <origin rpy="0.408043134594723 0.963708851734786 -1.67797755478808" xyz="-0.0594362424748194 -0.0151129693199101 -0.0328355822112983"/>
    <parent link="rear_left_base_link"/>
    <child link="rear_left_roller8"/>
    <axis xyz="0 0 1"/>
  </joint>
  <link name="rear_left_roller9">
    <inertial>
      <origin rpy="0 0 0" xyz="5.759281940243E-16 -2.60208521396521E-15 -0.0215899999999933"/>
      <mass value="0.00499543658848229"/>
      <inertia ixx="8.9991994924954E-07" ixy="-2.64697796016969E-23" ixz="7.6762360844921E-22" iyy="8.99919949249544E-07" iyz="-8.01743154355797E-19" izz="3.31951561016627E-07"/>
    </inertial>
    <visual>
      <origin rpy="0 0 0" xyz="0 0 0"/>
      <geometry>
        <mesh filename="package://linorobot2_description/mecanum_wheel_right/meshes/roller9.STL"/>
      </geometry>
      <material name="">
        <color rgba="0.752941176470588 0.752941176470588 0.752941176470588 1"/>
      </material>
    </visual>
    <collision>
      <origin rpy="0 0 0" xyz="0 0 0"/>
      <geometry>
        <mesh filename="package://linorobot2_description/mecanum_wheel_right/meshes/roller9.STL"/>
      </geometry>
    </collision>
  </link>
  <joint name="rear_left_base_link_to_rear_left_roller9" type="continuous">
    <origin rpy="1.1026415771303 0.886919106568413 -1.11464531078552" xyz="-0.0409422748501527 -0.015112969319909 -0.0541716947194296"/>
    <parent link="rear_left_base_link"/>
    <child link="rear_left_roller9"/>
    <axis xyz="0 0 1"/>
  </joint>
  <link name="rear_left_roller10">
    <inertial>
      <origin rpy="0 0 0" xyz="5.89805981832114E-16 -3.42087469462626E-15 -0.0215899999999933"/>
      <mass value="0.00499543658848216"/>
      <inertia ixx="8.99919949244339E-07" ixy="-1.05879118406788E-22" ixz="8.33798057453452E-22" iyy="8.99919949244339E-07" iyz="-8.05177608259117E-19" izz="3.31951561007005E-07"/>
    </inertial>
    <visual>
      <origin rpy="0 0 0" xyz="0 0 0"/>
      <geometry>
        <mesh filename="package://linorobot2_description/mecanum_wheel_right/meshes/roller10.STL"/>
      </geometry>
      <material name="">
        <color rgba="0.752941176470588 0.752941176470588 0.752941176470588 1"/>
      </material>
    </visual>
    <collision>
      <origin rpy="0 0 0" xyz="0 0 0"/>
      <geometry>
        <mesh filename="package://linorobot2_description/mecanum_wheel_right/meshes/roller10.STL"/>
      </geometry>
    </collision>
  </link>
  <joint name="rear_left_base_link_to_rear_left_roller10" type="continuous">
    <origin rpy="1.57421323203544 0.637163580624169 -0.783361608443036" xyz="-0.0153690159550034 -0.0151129693199065 -0.0661410290761748"/>
    <parent link="rear_left_base_link"/>
    <child link="rear_left_roller10"/>
    <axis xyz="0 0 1"/>
  </joint>
  <link name="rear_left_roller11">
    <inertial>
      <origin rpy="0 0 0" xyz="5.89805981832114E-16 -5.03069808033274E-15 -0.0215899999999933"/>
      <mass value="0.00499543658848235"/>
      <inertia ixx="8.99919949251756E-07" ixy="-1.7205356741103E-22" ixz="7.41153828847513E-22" iyy="8.99919949251703E-07" iyz="-8.01815946249702E-19" izz="3.3195156102064E-07"/>
    </inertial>
    <visual>
      <origin rpy="0 0 0" xyz="0 0 0"/>
      <geometry>
        <mesh filename="package://linorobot2_description/mecanum_wheel_right/meshes/roller11.STL"/>
      </geometry>
      <material name="">
        <color rgba="0.752941176470588 0.752941176470588 0.752941176470588 1"/>
      </material>
    </visual>
    <collision>
      <origin rpy="0 0 0" xyz="0 0 0"/>
      <geometry>
        <mesh filename="package://linorobot2_description/mecanum_wheel_right/meshes/roller11.STL"/>
      </geometry>
    </collision>
  </link>
  <joint name="rear_left_base_link_to_rear_left_roller11" type="continuous">
    <origin rpy="1.88109068595424 0.317129294370825 -0.639722033593165" xyz="0.0128616854218928 -0.0151129693199038 -0.0666739786332639"/>
    <parent link="rear_left_base_link"/>
    <child link="rear_left_roller11"/>
    <axis xyz="0 0 1"/>
  </joint>
  <link name="rear_left_roller12">
    <inertial>
      <origin rpy="0 0 0" xyz="5.759281940243E-16 -3.44169137633799E-15 -0.0215899999999933"/>
      <mass value="0.00499543658848216"/>
      <inertia ixx="8.99919949244308E-07" ixy="-5.29395592033938E-23" ixz="6.88214269644119E-22" iyy="8.99919949244286E-07" iyz="-8.02021087041615E-19" izz="3.3195156100692E-07"/>
    </inertial>
    <visual>
      <origin rpy="0 0 0" xyz="0 0 0"/>
      <geometry>
        <mesh filename="package://linorobot2_description/mecanum_wheel_right/meshes/roller12.STL"/>
      </geometry>
      <material name="">
        <color rgba="0.752941176470588 0.752941176470588 0.752941176470588 1"/>
      </material>
    </visual>
    <collision>
      <origin rpy="0 0 0" xyz="0 0 0"/>
      <geometry>
        <mesh filename="package://linorobot2_description/mecanum_wheel_right/meshes/roller12.STL"/>
      </geometry>
    </collision>
  </link>
  <joint name="rear_left_base_link_to_rear_left_roller12" type="continuous">
    <origin rpy="2.12643201705665 -0.025160050703084 -0.60332516970669" xyz="0.0388684845445997 -0.0151129693199006 -0.0556783915705813"/>
    <parent link="rear_left_base_link"/>
    <child link="rear_left_roller12"/>
    <axis xyz="0 0 1"/>
  </joint>
  <link name="rear_left_roller13">
    <inertial>
      <origin rpy="0 0 0" xyz="5.89805981832114E-16 -3.36536354339501E-15 -0.0215899999999933"/>
      <mass value="0.00499543658848228"/>
      <inertia ixx="8.99919949249124E-07" ixy="6.61744490042422E-23" ixz="9.66146955461936E-22" iyy="8.99919949249017E-07" iyz="-8.01875503253805E-19" izz="3.31951561015716E-07"/>
    </inertial>
    <visual>
      <origin rpy="0 0 0" xyz="0 0 0"/>
      <geometry>
        <mesh filename="package://linorobot2_description/mecanum_wheel_right/meshes/roller13.STL"/>
      </geometry>
      <material name="">
        <color rgba="0.752941176470588 0.752941176470588 0.752941176470588 1"/>
      </material>
    </visual>
    <collision>
      <origin rpy="0 0 0" xyz="0 0 0"/>
      <geometry>
        <mesh filename="package://linorobot2_description/mecanum_wheel_right/meshes/roller13.STL"/>
      </geometry>
    </collision>
  </link>
  <joint name="rear_left_base_link_to_rear_left_roller13" type="continuous">
    <origin rpy="2.37615666037905 -0.365916365141497 -0.652805521545524" xyz="0.0581545695804492 -0.0151129693198971 -0.0350555047830372"/>
    <parent link="rear_left_base_link"/>
    <child link="rear_left_roller13"/>
    <axis xyz="0 0 1"/>
  </joint>
  <link name="rear_left_roller14">
    <inertial>
      <origin rpy="0 0 0" xyz="5.82867087928207E-16 -2.38697950294409E-15 -0.0215899999999933"/>
      <mass value="0.00499543658848209"/>
      <inertia ixx="8.99919949243614E-07" ixy="5.29395592033938E-23" ixz="6.61744490042422E-22" iyy="8.99919949243616E-07" iyz="-8.05343044381628E-19" izz="3.31951561005557E-07"/>
    </inertial>
    <visual>
      <origin rpy="0 0 0" xyz="0 0 0"/>
      <geometry>
        <mesh filename="package://linorobot2_description/mecanum_wheel_right/meshes/roller14.STL"/>
      </geometry>
      <material name="">
        <color rgba="0.752941176470588 0.752941176470588 0.752941176470588 1"/>
      </material>
    </visual>
    <collision>
      <origin rpy="0 0 0" xyz="0 0 0"/>
      <geometry>
        <mesh filename="package://linorobot2_description/mecanum_wheel_right/meshes/roller14.STL"/>
      </geometry>
    </collision>
  </link>
  <joint name="rear_left_base_link_to_rear_left_roller14" type="continuous">
    <origin rpy="2.69941973817462 -0.67973266586857 -0.817294146739146" xyz="0.0673852012181607 -0.0151129693198943 -0.00837120274924246"/>
    <parent link="rear_left_base_link"/>
    <child link="rear_left_roller14"/>
    <axis xyz="0 0 1"/>
  </joint>
  <link name="rear_left_roller15">
    <inertial>
      <origin rpy="0 0 0" xyz="5.759281940243E-16 -6.50868248186498E-15 -0.0215899999999933"/>
      <mass value="0.00499543658848241"/>
      <inertia ixx="8.99919949251262E-07" ixy="1.05879118406788E-22" ixz="9.13207396258543E-22" iyy="8.99919949251201E-07" iyz="-8.01763006690498E-19" izz="3.31951561019665E-07"/>
    </inertial>
    <visual>
      <origin rpy="0 0 0" xyz="0 0 0"/>
      <geometry>
        <mesh filename="package://linorobot2_description/mecanum_wheel_right/meshes/roller15.STL"/>
      </geometry>
      <material name="">
        <color rgba="0.752941176470588 0.752941176470588 0.752941176470588 1"/>
      </material>
    </visual>
    <collision>
      <origin rpy="0 0 0" xyz="0 0 0"/>
      <geometry>
        <mesh filename="package://linorobot2_description/mecanum_wheel_right/meshes/roller15.STL"/>
      </geometry>
    </collision>
  </link>
  <joint name="rear_left_base_link_to_rear_left_roller15" type="continuous">
    <origin rpy="-3.077965161563 -0.911914057233449 -1.18487158274901" xyz="0.0649643193899178 -0.0151129693198934 0.0197605562898849"/>
    <parent link="rear_left_base_link"/>
    <child link="rear_left_roller15"/>
    <axis xyz="0 0 1"/>
  </joint>
  <link name="rear_right_base_link">
    <inertial>
      <origin rpy="0 0 0" xyz="-3.9077136779291E-16 -0.0136205707454137 -1.44489682185117E-14"/>
      <mass value="0.039620820516108"/>
      <inertia ixx="3.76577202480009E-05" ixy="-1.07908308681007E-19" ixz="3.89356499633093E-22" iyy="7.10123305553507E-05" iyz="-1.66085499471637E-18" izz="3.76577202480009E-05"/>
    </inertial>
    <visual>
      <origin rpy="0 0 0" xyz="0 0 0"/>
      <geometry>
        <mesh filename="package://linorobot2_description/mecanum_wheel_left/meshes/base_link.STL"/>
      </geometry>
      <material name="">
        <color rgba="0.898039215686275 0.917647058823529 0.929411764705882 1"/>
      </material>
    </visual>
    <collision>
      <origin rpy="0 0 0" xyz="0 0 0"/>
      <geometry>
        <mesh filename="package://linorobot2_description/mecanum_wheel_left/meshes/base_link.STL"/>
      </geometry>
    </collision>
  </link>
  <joint name="base_link_to_rear_right_base_link" type="continuous">
    <origin rpy="0 0 0" xyz="-0.25857 -0.19355 0"/>
    <parent link="base_link"/>
    <child link="rear_right_base_link"/>
    <axis xyz="0 1 0"/>
  </joint>
  <link name="rear_right_plate1">
    <inertial>
      <origin rpy="0 0 0" xyz="8.83119736279022E-16 3.33301269118141E-17 -0.000551568670724527"/>
      <mass value="0.0253986639693882"/>
      <inertia ixx="4.21627753206923E-05" ixy="1.3976043629696E-20" ixz="-2.39458839321443E-21" iyy="4.21627753206922E-05" iyz="4.06169630282727E-21" izz="8.39719993847474E-05"/>
    </inertial>
    <visual>
      <origin rpy="0 0 0" xyz="0 0 0"/>
      <geometry>
        <mesh filename="package://linorobot2_description/mecanum_wheel_left/meshes/plate1.STL"/>
      </geometry>
      <material name="">
        <color rgba="0.650980392156863 0.619607843137255 0.588235294117647 1"/>
      </material>
    </visual>
    <collision>
      <origin rpy="0 0 0" xyz="0 0 0"/>
      <geometry>
        <mesh filename="package://linorobot2_description/mecanum_wheel_left/meshes/plate1.STL"/>
      </geometry>
    </collision>
  </link>
  <joint name="rear_right_base_link_to_rear_right_plate1" type="fixed">
    <origin rpy="-1.5708 0.03287 0" xyz="0 0.023114 0"/>
    <parent link="rear_right_base_link"/>
    <child link="rear_right_plate1"/>
    <axis xyz="0 0 0"/>
  </joint>
  <link name="rear_right_plate2">
    <inertial>
      <origin rpy="0 0 0" xyz="-1.10651810076925E-15 8.09386876632109E-17 -0.000551568670724527"/>
      <mass value="0.0253986639693882"/>
      <inertia ixx="4.21627753206924E-05" ixy="1.65171424714589E-20" ixz="4.28643950323039E-22" iyy="4.21627753206923E-05" iyz="2.75305456980319E-21" izz="8.39719993847476E-05"/>
    </inertial>
    <visual>
      <origin rpy="0 0 0" xyz="0 0 0"/>
      <geometry>
        <mesh filename="package://linorobot2_description/mecanum_wheel_left/meshes/plate2.STL"/>
      </geometry>
      <material name="">
        <color rgba="0.650980392156863 0.619607843137255 0.588235294117647 1"/>
      </material>
    </visual>
    <collision>
      <origin rpy="0 0 0" xyz="0 0 0"/>
      <geometry>
        <mesh filename="package://linorobot2_description/mecanum_wheel_left/meshes/plate2.STL"/>
      </geometry>
    </collision>
  </link>
  <joint name="rear_right_base_link_to_rear_right_plate2" type="fixed">
    <origin rpy="-1.5707963267949 0.0335546833724646 -3.14159265358979" xyz="0 -0.023114 0"/>
    <parent link="rear_right_base_link"/>
    <child link="rear_right_plate2"/>
    <axis xyz="0 0 0"/>
  </joint>
  <link name="rear_right_roller1">
    <inertial>
      <origin rpy="0 0 0" xyz="5.96744875736022E-16 -1.24475083018716E-14 -0.0215899999999933"/>
      <mass value="0.00499543658848208"/>
      <inertia ixx="8.99919949242919E-07" ixy="3.97046694025453E-23" ixz="9.81863387100444E-22" iyy="8.9991994924288E-07" iyz="-8.0163727523739E-19" izz="3.31951561004127E-07"/>
    </inertial>
    <visual>
      <origin rpy="0 0 0" xyz="0 0 0"/>
      <geometry>
        <mesh filename="package://linorobot2_description/mecanum_wheel_left/meshes/roller1.STL"/>
      </geometry>
      <material name="">
        <color rgba="0.752941176470588 0.752941176470588 0.752941176470588 1"/>
      </material>
    </visual>
    <collision>
      <origin rpy="0 0 0" xyz="0 0 0"/>
      <geometry>
        <mesh filename="package://linorobot2_description/mecanum_wheel_left/meshes/roller1.STL"/>
      </geometry>
    </collision>
  </link>
  <joint name="rear_right_base_link_to_rear_right_roller1" type="continuous">
    <origin rpy="2.3375 0.48899 -0.038445" xyz="-0.064997 -0.01515 0.019737"/>
    <parent link="rear_right_base_link"/>
    <child link="rear_right_roller1"/>
    <axis xyz="0 0 1"/>
  </joint>
  <link name="rear_right_roller2">
    <inertial>
      <origin rpy="0 0 0" xyz="5.82867087928207E-16 -9.95687907123788E-15 -0.0215899999999933"/>
      <mass value="0.00499543658848216"/>
      <inertia ixx="8.99919949245561E-07" ixy="-3.30872245021211E-24" ixz="8.56959114604937E-22" iyy="8.99919949245641E-07" iyz="-8.01716684576195E-19" izz="3.31951561009139E-07"/>
    </inertial>
    <visual>
      <origin rpy="0 0 0" xyz="0 0 0"/>
      <geometry>
        <mesh filename="package://linorobot2_description/mecanum_wheel_left/meshes/roller2.STL"/>
      </geometry>
      <material name="">
        <color rgba="0.752941176470588 0.752941176470588 0.752941176470588 1"/>
      </material>
    </visual>
    <collision>
      <origin rpy="0 0 0" xyz="0 0 0"/>
      <geometry>
        <mesh filename="package://linorobot2_description/mecanum_wheel_left/meshes/roller2.STL"/>
      </geometry>
    </collision>
  </link>
  <joint name="rear_right_base_link_to_rear_right_roller2" type="continuous">
    <origin rpy="2.3122 0.90744 -0.055132" xyz="-0.05135 -0.01515 0.044467"/>
    <parent link="rear_right_base_link"/>
    <child link="rear_right_roller2"/>
    <axis xyz="0 0 1"/>
  </joint>
  <link name="rear_right_roller3">
    <inertial>
      <origin rpy="0 0 0" xyz="5.82867087928207E-16 -3.41003267290141E-15 -0.0215899999999933"/>
      <mass value="0.00499543658848228"/>
      <inertia ixx="8.9991994924907E-07" ixy="-9.92616735063633E-24" ixz="8.47860127866853E-22" iyy="8.99919949249046E-07" iyz="-8.01743154355797E-19" izz="3.3195156101569E-07"/>
    </inertial>
    <visual>
      <origin rpy="0 0 0" xyz="0 0 0"/>
      <geometry>
        <mesh filename="package://linorobot2_description/mecanum_wheel_left/meshes/roller3.STL"/>
      </geometry>
      <material name="">
        <color rgba="0.752941176470588 0.752941176470588 0.752941176470588 1"/>
      </material>
    </visual>
    <collision>
      <origin rpy="0 0 0" xyz="0 0 0"/>
      <geometry>
        <mesh filename="package://linorobot2_description/mecanum_wheel_left/meshes/roller3.STL"/>
      </geometry>
    </collision>
  </link>
  <joint name="rear_right_base_link_to_rear_right_roller3" type="continuous">
    <origin rpy="2.22 1.3248 -0.13976" xyz="-0.028824 -0.01515 0.061508"/>
    <parent link="rear_right_base_link"/>
    <child link="rear_right_roller3"/>
    <axis xyz="0 0 1"/>
  </joint>
  <link name="rear_right_roller4">
    <inertial>
      <origin rpy="0 0 0" xyz="5.68989300120393E-16 -3.35365415993216E-15 -0.0215899999999933"/>
      <mass value="0.00499543658848229"/>
      <inertia ixx="8.9991994924904E-07" ixy="1.65436122510606E-23" ixz="7.69277969674316E-22" iyy="8.99919949249123E-07" iyz="-8.01796093915E-19" izz="3.31951561015737E-07"/>
    </inertial>
    <visual>
      <origin rpy="0 0 0" xyz="0 0 0"/>
      <geometry>
        <mesh filename="package://linorobot2_description/mecanum_wheel_left/meshes/roller4.STL"/>
      </geometry>
      <material name="">
        <color rgba="0.752941176470588 0.752941176470588 0.752941176470588 1"/>
      </material>
    </visual>
    <collision>
      <origin rpy="0 0 0" xyz="0 0 0"/>
      <geometry>
        <mesh filename="package://linorobot2_description/mecanum_wheel_left/meshes/roller4.STL"/>
      </geometry>
    </collision>
  </link>
  <joint name="rear_right_base_link_to_rear_right_roller4" type="continuous">
    <origin rpy="-0.59653 1.3924 -2.9492" xyz="-0.0013143 -0.01515 0.067914"/>
    <parent link="rear_right_base_link"/>
    <child link="rear_right_roller4"/>
    <axis xyz="0 0 1"/>
  </joint>
  <link name="rear_right_roller5">
    <inertial>
      <origin rpy="0 0 0" xyz="5.96744875736022E-16 2.4459601011273E-15 -0.0215899999999933"/>
      <mass value="0.00499543658848241"/>
      <inertia ixx="8.99919949250993E-07" ixy="3.14328632770151E-23" ixz="7.25437397209005E-22" iyy="8.99919949251052E-07" iyz="-8.01796093915E-19" izz="3.31951561019638E-07"/>
    </inertial>
    <visual>
      <origin rpy="0 0 0" xyz="0 0 0"/>
      <geometry>
        <mesh filename="package://linorobot2_description/mecanum_wheel_left/meshes/roller5.STL"/>
      </geometry>
      <material name="">
        <color rgba="0.752941176470588 0.752941176470588 0.752941176470588 1"/>
      </material>
    </visual>
    <collision>
      <origin rpy="0 0 0" xyz="0 0 0"/>
      <geometry>
        <mesh filename="package://linorobot2_description/mecanum_wheel_left/meshes/roller5.STL"/>
      </geometry>
    </collision>
  </link>
  <joint name="rear_right_base_link_to_rear_right_roller5" type="continuous">
    <origin rpy="-0.73578 0.97593 -3.081" xyz="0.026423 -0.01515 0.062578"/>
    <parent link="rear_right_base_link"/>
    <child link="rear_right_roller5"/>
    <axis xyz="0 0 1"/>
  </joint>
  <link name="rear_right_roller6">
    <inertial>
      <origin rpy="0 0 0" xyz="5.82867087928207E-16 -7.52392939618041E-15 -0.0215899999999933"/>
      <mass value="0.00499543658848228"/>
      <inertia ixx="8.99919949249441E-07" ixy="5.9557004103818E-23" ixz="8.28834973778134E-22" iyy="8.99919949249495E-07" iyz="-8.017828590252E-19" izz="3.31951561016508E-07"/>
    </inertial>
    <visual>
      <origin rpy="0 0 0" xyz="0 0 0"/>
      <geometry>
        <mesh filename="package://linorobot2_description/mecanum_wheel_left/meshes/roller6.STL"/>
      </geometry>
      <material name="">
        <color rgba="0.752941176470588 0.752941176470588 0.752941176470588 1"/>
      </material>
    </visual>
    <collision>
      <origin rpy="0 0 0" xyz="0 0 0"/>
      <geometry>
        <mesh filename="package://linorobot2_description/mecanum_wheel_left/meshes/roller6.STL"/>
      </geometry>
    </collision>
  </link>
  <joint name="rear_right_base_link_to_rear_right_roller6" type="continuous">
    <origin rpy="-0.76481 0.55754 -3.1016" xyz="0.049591 -0.01515 0.04642"/>
    <parent link="rear_right_base_link"/>
    <child link="rear_right_roller6"/>
    <axis xyz="0 0 1"/>
  </joint>
  <link name="rear_right_roller7">
    <inertial>
      <origin rpy="0 0 0" xyz="5.82867087928207E-16 -3.4109000346394E-15 -0.0215899999999933"/>
      <mass value="0.00499543658848228"/>
      <inertia ixx="8.9991994924911E-07" ixy="-3.30872245021211E-24" ixz="7.51079996198149E-22" iyy="8.99919949249103E-07" iyz="-8.00353490926708E-19" izz="3.31951561015786E-07"/>
    </inertial>
    <visual>
      <origin rpy="0 0 0" xyz="0 0 0"/>
      <geometry>
        <mesh filename="package://linorobot2_description/mecanum_wheel_left/meshes/roller7.STL"/>
      </geometry>
      <material name="">
        <color rgba="0.752941176470588 0.752941176470588 0.752941176470588 1"/>
      </material>
    </visual>
    <collision>
      <origin rpy="0 0 0" xyz="0 0 0"/>
      <geometry>
        <mesh filename="package://linorobot2_description/mecanum_wheel_left/meshes/roller7.STL"/>
      </geometry>
    </collision>
  </link>
  <joint name="rear_right_base_link_to_rear_right_roller7" type="continuous">
    <origin rpy="-0.78123 0.13894 -3.1073" xyz="0.064184 -0.01515 0.022237"/>
    <parent link="rear_right_base_link"/>
    <child link="rear_right_roller7"/>
    <axis xyz="0 0 1"/>
  </joint>
  <link name="rear_right_roller8">
    <inertial>
      <origin rpy="0 0 0" xyz="5.82867087928207E-16 -1.76421377506841E-15 -0.0215899999999933"/>
      <mass value="0.00499543658848253"/>
      <inertia ixx="8.9991994925561E-07" ixy="-4.13590306276514E-23" ixz="7.46944093135384E-22" iyy="8.99919949255578E-07" iyz="-8.01624040347589E-19" izz="3.31951561027997E-07"/>
    </inertial>
    <visual>
      <origin rpy="0 0 0" xyz="0 0 0"/>
      <geometry>
        <mesh filename="package://linorobot2_description/mecanum_wheel_left/meshes/roller8.STL"/>
      </geometry>
      <material name="">
        <color rgba="0.752941176470588 0.752941176470588 0.752941176470588 1"/>
      </material>
    </visual>
    <collision>
      <origin rpy="0 0 0" xyz="0 0 0"/>
      <geometry>
        <mesh filename="package://linorobot2_description/mecanum_wheel_left/meshes/roller8.STL"/>
      </geometry>
    </collision>
  </link>
  <joint name="rear_right_base_link_to_rear_right_roller8" type="continuous">
    <origin rpy="-0.79573 -0.27969 -3.1063" xyz="0.06768 -0.01515 -0.0057919"/>
    <parent link="rear_right_base_link"/>
    <child link="rear_right_roller8"/>
    <axis xyz="0 0 1"/>
  </joint>
  <link name="rear_right_roller9">
    <inertial>
      <origin rpy="0 0 0" xyz="5.82867087928207E-16 -5.1013880619788E-15 -0.0215899999999933"/>
      <mass value="0.00499543658848228"/>
      <inertia ixx="8.99919949250354E-07" ixy="1.81979734761666E-22" ixz="8.08982639076861E-22" iyy="8.99919949250367E-07" iyz="-8.01835798584403E-19" izz="3.31951561017902E-07"/>
    </inertial>
    <visual>
      <origin rpy="0 0 0" xyz="0 0 0"/>
      <geometry>
        <mesh filename="package://linorobot2_description/mecanum_wheel_left/meshes/roller9.STL"/>
      </geometry>
      <material name="">
        <color rgba="0.752941176470588 0.752941176470588 0.752941176470588 1"/>
      </material>
    </visual>
    <collision>
      <origin rpy="0 0 0" xyz="0 0 0"/>
      <geometry>
        <mesh filename="package://linorobot2_description/mecanum_wheel_left/meshes/roller9.STL"/>
      </geometry>
    </collision>
  </link>
  <joint name="rear_right_base_link_to_rear_right_roller9" type="continuous">
    <origin rpy="-0.81448 -0.69826 -3.0973" xyz="0.059473 -0.01515 -0.032819"/>
    <parent link="rear_right_base_link"/>
    <child link="rear_right_roller9"/>
    <axis xyz="0 0 1"/>
  </joint>
  <link name="rear_right_roller10">
    <inertial>
      <origin rpy="0 0 0" xyz="5.96744875736022E-16 -6.51952450358984E-15 -0.0215899999999933"/>
      <mass value="0.00499543658848228"/>
      <inertia ixx="8.99919949250464E-07" ixy="-1.43929426584227E-22" ixz="8.58613475830043E-22" iyy="8.99919949250483E-07" iyz="-8.01756389245598E-19" izz="3.31951561018128E-07"/>
    </inertial>
    <visual>
      <origin rpy="0 0 0" xyz="0 0 0"/>
      <geometry>
        <mesh filename="package://linorobot2_description/mecanum_wheel_left/meshes/roller10.STL"/>
      </geometry>
      <material name="">
        <color rgba="0.752941176470588 0.752941176470588 0.752941176470588 1"/>
      </material>
    </visual>
    <collision>
      <origin rpy="0 0 0" xyz="0 0 0"/>
      <geometry>
        <mesh filename="package://linorobot2_description/mecanum_wheel_left/meshes/roller10.STL"/>
      </geometry>
    </collision>
  </link>
  <joint name="rear_right_base_link_to_rear_right_roller10" type="continuous">
    <origin rpy="-0.85554 -1.1164 -3.0642" xyz="0.040982 -0.01515 -0.054171"/>
    <parent link="rear_right_base_link"/>
    <child link="rear_right_roller10"/>
    <axis xyz="0 0 1"/>
  </joint>
  <link name="rear_right_roller11">
    <inertial>
      <origin rpy="0 0 0" xyz="5.68989300120393E-16 -3.40699690681845E-15 -0.0215899999999933"/>
      <mass value="0.00499543658848228"/>
      <inertia ixx="8.99919949249114E-07" ixy="-6.61744490042422E-24" ixz="8.13118542139626E-22" iyy="8.99919949249044E-07" iyz="-8.00419665375712E-19" izz="3.31951561015731E-07"/>
    </inertial>
    <visual>
      <origin rpy="0 0 0" xyz="0 0 0"/>
      <geometry>
        <mesh filename="package://linorobot2_description/mecanum_wheel_left/meshes/roller11.STL"/>
      </geometry>
      <material name="">
        <color rgba="0.752941176470588 0.752941176470588 0.752941176470588 1"/>
      </material>
    </visual>
    <collision>
      <origin rpy="0 0 0" xyz="0 0 0"/>
      <geometry>
        <mesh filename="package://linorobot2_description/mecanum_wheel_left/meshes/roller11.STL"/>
      </geometry>
    </collision>
  </link>
  <joint name="rear_right_base_link_to_rear_right_roller11" type="continuous">
    <origin rpy="-1.5658 -1.5225 -2.3612" xyz="0.015406 -0.01515 -0.066157"/>
    <parent link="rear_right_base_link"/>
    <child link="rear_right_roller11"/>
    <axis xyz="0 0 1"/>
  </joint>
  <link name="rear_right_roller12">
    <inertial>
      <origin rpy="0 0 0" xyz="5.96744875736022E-16 -9.87751547221194E-15 -0.0215899999999933"/>
      <mass value="0.00499543658848222"/>
      <inertia ixx="8.99919949247458E-07" ixy="8.27180612553028E-24" ixz="7.10548146183051E-22" iyy="8.99919949247364E-07" iyz="-8.01716684576195E-19" izz="3.31951561012396E-07"/>
    </inertial>
    <visual>
      <origin rpy="0 0 0" xyz="0 0 0"/>
      <geometry>
        <mesh filename="package://linorobot2_description/mecanum_wheel_left/meshes/roller12.STL"/>
      </geometry>
      <material name="">
        <color rgba="0.752941176470588 0.752941176470588 0.752941176470588 1"/>
      </material>
    </visual>
    <collision>
      <origin rpy="0 0 0" xyz="0 0 0"/>
      <geometry>
        <mesh filename="package://linorobot2_description/mecanum_wheel_left/meshes/roller12.STL"/>
      </geometry>
    </collision>
  </link>
  <joint name="rear_right_base_link_to_rear_right_roller12" type="continuous">
    <origin rpy="2.4393 -1.1848 -0.090248" xyz="-0.012835 -0.01515 -0.066704"/>
    <parent link="rear_right_base_link"/>
    <child link="rear_right_roller12"/>
    <axis xyz="0 0 1"/>
  </joint>
  <link name="rear_right_roller13">
    <inertial>
      <origin rpy="0 0 0" xyz="6.10622663543836E-16 -6.50608039665102E-15 -0.0215899999999933"/>
      <mass value="0.0049954365884824"/>
      <inertia ixx="8.99919949251263E-07" ixy="3.30872245021211E-24" ixz="8.75984268693656E-22" iyy="8.9991994925119E-07" iyz="-8.01491691449581E-19" izz="3.31951561019653E-07"/>
    </inertial>
    <visual>
      <origin rpy="0 0 0" xyz="0 0 0"/>
      <geometry>
        <mesh filename="package://linorobot2_description/mecanum_wheel_left/meshes/roller13.STL"/>
      </geometry>
      <material name="">
        <color rgba="0.752941176470588 0.752941176470588 0.752941176470588 1"/>
      </material>
    </visual>
    <collision>
      <origin rpy="0 0 0" xyz="0 0 0"/>
      <geometry>
        <mesh filename="package://linorobot2_description/mecanum_wheel_left/meshes/roller13.STL"/>
      </geometry>
    </collision>
  </link>
  <joint name="rear_right_base_link_to_rear_right_roller13" type="continuous">
    <origin rpy="2.3883 -0.76678 -0.047134" xyz="-0.038856 -0.01515 -0.055716"/>
    <parent link="rear_right_base_link"/>
    <child link="rear_right_roller13"/>
    <axis xyz="0 0 1"/>
  </joint>
  <link name="rear_right_roller14">
    <inertial>
      <origin rpy="0 0 0" xyz="5.96744875736022E-16 -3.365797224264E-15 -0.0215899999999933"/>
      <mass value="0.00499543658848228"/>
      <inertia ixx="8.99919949249125E-07" ixy="2.81241408268029E-23" ixz="6.46855239016468E-22" iyy="8.99919949249103E-07" iyz="-8.01888738143606E-19" izz="3.31951561015801E-07"/>
    </inertial>
    <visual>
      <origin rpy="0 0 0" xyz="0 0 0"/>
      <geometry>
        <mesh filename="package://linorobot2_description/mecanum_wheel_left/meshes/roller14.STL"/>
      </geometry>
      <material name="">
        <color rgba="0.752941176470588 0.752941176470588 0.752941176470588 1"/>
      </material>
    </visual>
    <collision>
      <origin rpy="0 0 0" xyz="0 0 0"/>
      <geometry>
        <mesh filename="package://linorobot2_description/mecanum_wheel_left/meshes/roller14.STL"/>
      </geometry>
    </collision>
  </link>
  <joint name="rear_right_base_link_to_rear_right_roller14" type="continuous">
    <origin rpy="2.3679 -0.34825 -0.036106" xyz="-0.058159 -0.01515 -0.035095"/>
    <parent link="rear_right_base_link"/>
    <child link="rear_right_roller14"/>
    <axis xyz="0 0 1"/>
  </joint>
  <link name="rear_right_roller15">
    <inertial>
      <origin rpy="0 0 0" xyz="5.82867087928207E-16 -3.35452152167015E-15 -0.0215899999999933"/>
      <mass value="0.00499543658848229"/>
      <inertia ixx="8.99919949249126E-07" ixy="-1.15805285757424E-23" ixz="8.54477572767278E-22" iyy="8.99919949249124E-07" iyz="-8.01796093915E-19" izz="3.31951561015821E-07"/>
    </inertial>
    <visual>
      <origin rpy="0 0 0" xyz="0 0 0"/>
      <geometry>
        <mesh filename="package://linorobot2_description/mecanum_wheel_left/meshes/roller15.STL"/>
      </geometry>
      <material name="">
        <color rgba="0.752941176470588 0.752941176470588 0.752941176470588 1"/>
      </material>
    </visual>
    <collision>
      <origin rpy="0 0 0" xyz="0 0 0"/>
      <geometry>
        <mesh filename="package://linorobot2_description/mecanum_wheel_left/meshes/roller15.STL"/>
      </geometry>
    </collision>
  </link>
  <joint name="rear_right_base_link_to_rear_right_roller15" type="continuous">
    <origin rpy="2.35322166168045 0.070379538766794 -0.0340216727613588" xyz="-0.0674050504299177 -0.0151497403158722 -0.00840608812639412"/>
    <parent link="rear_right_base_link"/>
    <child link="rear_right_roller15"/>
    <axis xyz="0 0 1"/>
  </joint>
</robot>
